Workbook
Name ANA_Anni_Adeguamento: Parametri!$M$4:$M$23
Name ANA_Attenzione_Supervisore: Parametri!$N$4:$N$23
Name ANA_Driver: Parametri!$K$4:$K$23
Name ANA_Event_Type: Parametri!$J$4:$J$23
Name ANA_ID: Parametri!$H$4:$H$23
Name ANA_Nome: Parametri!$I$4:$I$23
Name ANA_Owner: Parametri!$L$4:$L$23
Name ANA_Presidio_Controlli: Parametri!$O$4:$O$23
Name anagrafica: Parametri!$H$4:$O$23
Name anniProssimita: Parametri!$B$51:$B$55
Name AZ_Ciclo: Azioni!$A$6:$A$20015
Name AZ_Data_Decisione: Azioni!$J$6:$J$20015
Name AZ_Decisa_Da: Azioni!$K$6:$K$20015
Name AZ_Descrizione: Azioni!$D$6:$D$20015
Name AZ_ID_Azione: Azioni!$C$6:$C$20015
Name AZ_ID_Rischio: Azioni!$B$6:$B$20015
Name AZ_Mesi_Orizzonte: Azioni!$G$6:$G$20015
Name AZ_Orizzonte: Azioni!$F$6:$F$20015
Name AZ_Owner: Azioni!$E$6:$E$20015
Name AZ_Razionale: Azioni!$H$6:$H$20015
Name AZ_Stato: Azioni!$I$6:$I$20015
Name AZ_Validazione: Azioni!$L$6:$L$20015
Name capienzaElencoKRI: 150
Name capienzaKRICorrenti: 60
Name capienzaPianoAzioni: 150
Name cicliTrend: Parametri!$B$20:$B$27
Name cicloCorrente: Parametri!$B$15
Name cicloMeno2: Parametri!$B$17
Name cicloPrecedente: Parametri!$B$16
Name classificaAgire: OFFSET(Classifica!$V$5,0,0,MAX(1,COUNT(Classifica!$D$5:$D$24)),1)
Name classificaEntro: OFFSET(Classifica!$W$5,0,0,MAX(1,COUNT(Classifica!$D$5:$D$24)),1)
Name classificaEtichette: OFFSET(Classifica!$K$5,0,0,MAX(1,COUNT(Classifica!$D$5:$D$24)),1)
Name classificaID: OFFSET(Classifica!$B$5,0,0,MAX(1,COUNT(Classifica!$D$5:$D$24)),1)
Name classificaMargine: OFFSET(Classifica!$X$5,0,0,MAX(1,COUNT(Classifica!$D$5:$D$24)),1)
Name codiciL1: Parametri!$E$4:$E$10
Name coperturaAnagrafica: Registro!$D$5
Name coperturaValutati: Registro!$G$5
Name decisioniDaPrendere: Registro!$D$4
Name deltaEtichette: OFFSET(Delta!$AL$5,0,0,MAX(1,COUNT(Delta!$AI$5:$AI$24)),1)
Name deltaGiu: OFFSET(Delta!$AN$5,0,0,MAX(1,COUNT(Delta!$AI$5:$AI$24)),1)
Name deltaMotivi: Delta!$K$6:$Q$25
Name deltaSu: OFFSET(Delta!$AM$5,0,0,MAX(1,COUNT(Delta!$AI$5:$AI$24)),1)
Name deltaZero: OFFSET(Delta!$AO$5,0,0,MAX(1,COUNT(Delta!$AI$5:$AI$24)),1)
Name elencoKRI: OFFSET(Indicatori!$AB$12,0,0,MAX(1,COUNTIF(Indicatori!$AB$12:$AB$161,"?*")),1)
Name etichettaCiclo: Parametri!$B$57
Name inizioFinestra4: Parametri!$B$31
Name KRI_Chiave: KRI!$S$6:$S$20025
Name KRI_Ciclo: KRI!$A$6:$A$20025
Name KRI_Ciclo_Aggiornamento: KRI!$Q$6:$Q$20025
Name KRI_Ciclo_Definizione: KRI!$P$6:$P$20025
Name KRI_Data_Rilevazione: KRI!$K$6:$K$20025
Name KRI_Fonte_Dati: KRI!$G$6:$G$20025
Name KRI_Fonte_Rilevazione: KRI!$L$6:$L$20025
Name KRI_ID_Rischio: KRI!$C$6:$C$20025
Name KRI_In_Vigore: KRI!$O$6:$O$20025
Name KRI_KRI_ID: KRI!$B$6:$B$20025
Name KRI_Nome: KRI!$D$6:$D$20025
Name KRI_Nota_Rilevazione: KRI!$M$6:$M$20025
Name KRI_Razionale: KRI!$R$6:$R$20025
Name KRI_Soglia_Allerta: KRI!$I$6:$I$20025

Sheet Guida
A1: ="Horizon Scan NFR — Guida: come si usa questo workbook · "&etichettaCiclo -> Horizon Scan NFR — Guida: come si usa questo workbook · Ciclo 2026Q3 · dati al 30/09/2026 · da validare · Uso interno
A3: A COSA SERVE
A4: Horizon Scan NFR: registro dei rischi non finanziari emergenti della Banca. Ogni trimestre gli agenti valutano i rischi, lo script controlla e scrive qui, il validatore decide; i fogli da Quadro a Metodologia sono il report al comitato, le schede dei rischi un file a parte. Ogni foglio ha in testa (riga 2) chi lo aggiorna, cosa contiene e come si legge; il foglio Dizionario spiega ogni dato.
A6: CHI AGGIORNA COSA E QUANDO
A7: Foglio | B7: Settimanale · lunedi', A3 | C7: Trimestrale · A1, poi A5 | D7: Validatore · dopo il trimestre | E7: A che cosa serve
A8: REPORT AL COMITATO
A9: Quadro | C9: commento di A1, sintesi di A5, segnalazioni da motivare, numeri | D9: stato della validazione; avviso rettifiche | E9: prima pagina: il quadro e il perche'
A10: Classifica | C10: score e urgenza | D10: valori validati | E10: rischi per score; lente di Mosca
A11: Radar_Mosca | B11: segnali netti (livello) | C11: score, azioni (Y), KRI | D11: anni di adeguamento, presidio, attenzione del supervisore | E11: quanto presto agire, quanto e' grande, livello di allerta
A12: Matrice | C12: Probabilita e Impatto | D12: valori validati | E12: gravita' dei rischi
A13: Delta | C13: confronto con il ciclo prima | E13: che cosa e' cambiato e perche'
A14: Metodologia | D14: pesi e parametri (Parametri) | E14: come si leggono i numeri
A15: LAVORO
A16: Registro | B16: segnali netti (colonna Q) | C16: dimensioni, score, urgenza, KRI, rilievi | D16: righe 4-5; presidio (anagrafica) | E16: il ciclo corrente, un rischio per riga
A17: Storico, Indicatori | C17: si aggiornano | E17: score negli ultimi cicli; KRI del ciclo e storia di uno
A18: Notizie | B18: si aggiorna; sintesi e flag di A3 | E18: pressione delle notizie, aree non presidiate, sintesi della settimana
A19: Piano_azioni | C19: azioni proposte da A1 | D19: decisione; Stato In corso/Completata (foglio Azioni) | E19: tutte le azioni e la loro scadenza
A20: Validazione | B20: righe delle notizie | C20: righe di rischi, KRI, azioni | D20: valori gialli, Motivazione, Respingi (a mano) | E20: unico foglio da compilare: una riga per oggetto
A21: Parametri | B21: settimana corrente | C21: ciclo corrente; anagrafica H-K | D21: celle gialle | E21: pesi, soglie, urgenza, anagrafica
A22: Dizionario | E22: ogni dato: chi lo scrive, come si calcola
A23: DATI (solo lo script)
A24: RiskRegister | C24: valutazioni di A1 | D24: valori validati | E24: una riga per rischio per ciclo
A25: Azioni | C25: azioni proposte da A1 | D25: delibera; Stato In corso/Completata a mano | E25: una riga per azione
A26: KRI | C26: KRI e valori riletti da A1 | D26: rettifiche, KRI respinti | E26: storico, una riga per KRI per ciclo
A27: NewsLog | B27: notizie valutate da A3 | D27: rettifiche (facoltative) | E27: una riga per notizia
A28: Sintesi_Cicli | C28: commento di A1 e di A5 | E28: una riga per ciclo
A29: Sintesi_Settimane | B29: sintesi di A3 e flag proposti | E29: una riga per settimana
A30: Storico_Validazioni | B30: proposte delle notizie | C30: proposte di rischi, KRI, azioni | D30: decisioni (comando valida) | E30: una riga per oggetto e campo: proposta, valore deciso, motivo
A31: FILE A PARTE
A32: Schede_<ciclo>.xlsx | C32: testi di A6 dopo la validazione | D32: dati validati | E32: una scheda per rischio (comando schede)
A33: Giornaliero: la raccolta delle notizie riempie la cartella News_Inbox, non questo file. A4 (pareri su richiesta, in qualsiasi momento) non scrive qui: se un parere suggerisce di rivedere un rischio, la via e' il ciclo trimestrale successivo.
A35: QUANDO SI LANCIANO A5 E A6
A36: A5 (challenger), facoltativo (D-71): se lo si usa, dopo A1 e prima del comando trimestrale, allegando SOLO l'output di A1 e Baseline_corrente.json, e di nuovo ogni volta che A1 viene rifatto (vale solo per l'output esaminato). I suoi rilievi non fermano il ciclo: vanno nella colonna Segnalazioni del foglio Validazione, e un suo Bloccante rende obbligatoria la Motivazione del rischio. Lo script ferma solo i difetti di integrita' del registro. Non si lancia per le settimane, per A4 ne' dopo la validazione.
A37: A6 (schede): dopo la validazione del trimestre. Il comando schede-input prepara i dati validati; A6 scrive i testi; il comando schede li controlla e produce Schede_<ciclo>.xlsx. Senza A6 il comando schede produce comunque le schede con i testi del registro.
A39: DOVE SI SCRIVE A MANO (solo qui)
A40: Validazione: una riga per rischio, KRI, azione e notizia; si cambiano solo le celle gialle, la Motivazione e Respingi (istruzioni e criteri in testa al foglio), poi il comando valida.
A41: Parametri, celle gialle: pesi, soglie, urgenza (decisione della funzione di rischio); nell'anagrafica Owner, anni di adeguamento, attenzione del supervisore e presidio dei controlli (decisi dal validatore, restano da un ciclo all'altro).
A42: Azioni, colonna Stato: avanzamento di un'azione approvata (In corso, Completata); il Piano_azioni si aggiorna da solo.
A43: Indicatori, cella N4: il KRI di cui guardare la storia.
A44: Tutto il resto lo scrive lo script o e' una formula: non modificarlo.
...

Sheet Quadro
A1: ="Horizon Scan NFR — Quadro d'insieme · "&etichettaCiclo -> Horizon Scan NFR — Quadro d'insieme · Ciclo 2026Q3 · dati al 30/09/2026 · da validare · Uso interno
A2: CICLO TRIMESTRALE — A1 valuta i rischi, lo script la controlla (e A5, se usato), il validatore la conferma o la rettifica. Come si legge: i cinque riquadri in alto dicono se il ciclo e' completo e validato; poi le priorita' per score, la gravita' (matrice) e l'urgenza (radar). A pagina 2 il commento di A1 (scritto prima della validazione: se dopo ci sono state rettifiche lo dice la riga "Dopo il commento" e valgono i numeri validati), le segnalazioni portate in validazione e i rischi segnalati, con il perche' calcolato dal foglio. Metodo e scale: Metodologia; ogni dato: Dizionario. Note dell'analista (cella gialla in prima pagina): testo libero scritto a mano, per esempio la sintesi delle spiegazioni chieste ad A7; a un ciclo nuovo passa nel foglio Sintesi_Cicli.
BH3: Appoggio del grafico: non modificare | BY3: Attivazione | BZ3: Attivazione | CA3: Attivazione | CB3: Attivazione | CC3: Attivazione | CD3: Attivazione | CE3: Attivazione | CF3: Attivazione | CG3: Attivazione | CH3: Attivazione | CI3: Attivazione | CJ3: Attivazione | CK3: Attivazione | CL3: Attivazione | CM3: Attenzione | CN3: Attenzione | CO3: Attenzione | CP3: Attenzione | CQ3: Attenzione | CR3: Attenzione | CS3: Attenzione | CT3: Attenzione | CU3: Attenzione | CV3: Attenzione | CW3: Attenzione | CX3: Attenzione | CY3: Attenzione | CZ3: Attenzione | DA3: Monitoraggio | DB3: Monitoraggio | DC3: Monitoraggio | DD3: Monitoraggio | DE3: Monitoraggio | DF3: Monitoraggio | DG3: Monitoraggio | DH3: Monitoraggio | DI3: Monitoraggio | DJ3: Monitoraggio | DK3: Monitoraggio | DL3: Monitoraggio | DM3: Monitoraggio | DN3: Monitoraggio
A4: Rischi valutati | D4: Livello di allerta: attivazione · attenzione | G4: Variati · nuovi | J4: KRI in rosso | M4: Validazione | T4: =COUNTIF(Radar_Mosca!$AA$5:$AA$24,"Attivazione") -> 1 | BY4: 1 | BZ4: 2 | CA4: 3 | CB4: 4 | CC4: 5 | CD4: 6 | CE4: 8 | CF4: 9 | CG4: 10 | CH4: 12 | CI4: 15 | CJ4: 16 | CK4: 20 | CL4: 25 | CM4: 1 | CN4: 2 | CO4: 3 | CP4: 4 | CQ4: 5 | CR4: 6 | CS4: 8 | CT4: 9 | CU4: 10 | CV4: 12 | CW4: 15 | CX4: 16 | CY4: 20 | CZ4: 25 | DA4: 1 | DB4: 2 | DC4: 3 | DD4: 4 | DE4: 5 | DF4: 6 | DG4: 8 | DH4: 9 | DI4: 10 | DJ4: 12 | DK4: 15 | DL4: 16 | DM4: 20 | DN4: 25
A5: =coperturaValutati -> 12 | D5: =$T$4&" · "&COUNTIF(Radar_Mosca!$AA$5:$AA$24,"Attenzione") -> 1 · 7 | G5: =COUNTIFS(RR_Ciclo,cicloCorrente,RR_Esito,"Variato")&" · "&COUNTIFS(RR_Ciclo,cicloCorrente,RR_Esito,"Nuovo") -> 1 · 0 | J5: =COUNTIFS(KRI_Ciclo,cicloCorrente,KRI_In_Vigore,"Sì",KRI_Stato,"Rosso") -> 0 | M5: =IF(decisioniDaPrendere>0,decisioniDaPrendere,"✓") -> 52 | T5: =IF(Radar_Mosca!$AA$5="Attivazione",Radar_Mosca!$A$5,"") -> NFR-01 | BH5: =2*PI()*0/72 -> 0 | BI5: =2*SIN($BH5) -> 0 | BJ5: =2*COS($BH5) -> 2 | BK5: =3*SIN($BH5) -> 0 | BL5: =3*COS($BH5) -> 3 | BM5: =4*SIN($BH5) -> 0 | BN5: =4*COS($BH5) -> 4 | BO5: =5*SIN($BH5) -> 0 | BP5: =5*COS($BH5) -> 5 | BR5: 0 | BS5: 0 | BU5: L1-01 Frode interna | BV5: =6.95*SIN(2*PI()*(0+0.5)/ROWS(codiciL1)) -> 3.015492 | BW5: =6.95*COS(2*PI()*(0+0.5)/ROWS(codiciL1)) -> 6.2617336 | BY5: =IF(AND(ISNUMBER(Radar_Mosca!$F5),ISNUMBER(Radar_Mosca!$S5)),IF(AND(Radar_Mosca!$F5=BY$4,Radar_Mosca!$AA5=BY$3),Radar_Mosca!$S5,NA()),NA()) -> #N/A | BZ5: =IF(AND(ISNUMBER(Radar_Mosca!$F5),ISNUMBER(Radar_Mosca!$S5)),IF(AND(Radar_Mosca!$F5=BZ$4,Radar_Mosca!$AA5=BZ$3),Radar_Mosca!$S5,NA()),NA()) -> #N/A | CA5: =IF(AND(ISNUMBER(Radar_Mosca!$F5),ISNUMBER(Radar_Mosca!$S5)),IF(AND(Radar_Mosca!$F5=CA$4,Radar_Mosca!$AA5=CA$3),Radar_Mosca!$S5,NA()),NA()) -> #N/A | CB5: =IF(AND(ISNUMBER(Radar_Mosca!$F5),ISNUMBER(Radar_Mosca!$S5)),IF(AND(Radar_Mosca!$F5=CB$4,Radar_Mosca!$AA5=CB$3),Radar_Mosca!$S5,NA()),NA()) -> #N/A | CC5: =IF(AND(ISNUMBER(Radar_Mosca!$F5),ISNUMBER(Radar_Mosca!$S5)),IF(AND(Radar_Mosca!$F5=CC$4,Radar_Mosca!$AA5=CC$3),Radar_Mosca!$S5,NA()),NA()) -> #N/A | CD5: =IF(AND(ISNUMBER(Radar_Mosca!$F5),ISNUMBER(Radar_Mosca!$S5)),IF(AND(Radar_Mosca!$F5=CD$4,Radar_Mosca!$AA5=CD$3),Radar_Mosca!$S5,NA()),NA()) -> #N/A | CE5: =IF(AND(ISNUMBER(Radar_Mosca!$F5),ISNUMBER(Radar_Mosca!$S5)),IF(AND(Radar_Mosca!$F5=CE$4,Radar_Mosca!$AA5=CE$3),Radar_Mosca!$S5,NA()),NA()) -> #N/A | CF5: =IF(AND(ISNUMBER(Radar_Mosca!$F5),ISNUMBER(Radar_Mosca!$S5)),IF(AND(Radar_Mosca!$F5=CF$4,Radar_Mosca!$AA5=CF$3),Radar_Mosca!$S5,NA()),NA()) -> #N/A | ... DN5: =IF(AND(ISNUMBER(Radar_Mosca!$F5),ISNUMBER(Radar_Mosca!$S5)),IF(AND(Radar_Mosca!$F5=DN$4,Radar_Mosca!$AA5=DN$3),Radar_Mosca!$S5,NA()),NA()) -> #N/A | DO5: =IF(ISNUMBER(Radar_Mosca!$R5),Radar_Mosca!$R5,NA()) -> 1.7061238 | DP5: =IF(Radar_Mosca!$A5="","",MID(Radar_Mosca!$A5,5,3)&IF(Radar_Mosca!$T5="Sì"," ◆","")) -> 01 ◆ | DQ5: =IF(ISNUMBER(Radar_Mosca!$S5),Radar_Mosca!$S5,NA()) -> 0.38941163 | DR5: Attivazione | DS5: -6.9 | DT5: -5.05
A6: ="su "&coperturaAnagrafica&" in anagrafica · "&IF(coperturaValutati=coperturaAnagrafica,"completo","INCOMPLETO") -> su 12 in anagrafica · completo | D6: =IF($T$4=0,"nessun rischio in attivazione","in attivazione: "&_xlfn.TEXTJOIN(", ",TRUE,$T$5:$T$24))&" · in monitoraggio "&COUNTIF(Radar_Mosca!$AA$5:$AA$24,"Monitoraggio") -> in attivazione: NFR-01 · in monitoraggio 4 | G6: ="rispetto al "&cicloPrecedente -> rispetto al 2026Q2 | J6: ="su "&COUNTIFS(KRI_Ciclo,cicloCorrente,KRI_In_Vigore,"Sì")&" in vigore" -> su 24 in vigore | M6: =IF(decisioniDaPrendere>0,"righe da validare: ciclo non validato","ciclo validato") -> righe da validare: ciclo non validato | T6: =IF(Radar_Mosca!$AA$6="Attivazione",Radar_Mosca!$A$6,"") | BH6: =2*PI()*1/72 -> 0.087266463 | BI6: =2*SIN($BH6) -> 0.17431149 | BJ6: =2*COS($BH6) -> 1.9923894 | BK6: =3*SIN($BH6) -> 0.26146723 | BL6: =3*COS($BH6) -> 2.9885841 | BM6: =4*SIN($BH6) -> 0.34862297 | BN6: =4*COS($BH6) -> 3.9847788 | BO6: =5*SIN($BH6) -> 0.43577871 | BP6: =5*COS($BH6) -> 4.9809735 | BR6: =6.3*SIN(2*PI()*0/ROWS(codiciL1)) -> 0 | BS6: =6.3*COS(2*PI()*0/ROWS(codiciL1)) -> 6.3 | BU6: L1-02 Frode esterna | BV6: =6.95*SIN(2*PI()*(1+0.5)/ROWS(codiciL1)) -> 6.775749 | BW6: =6.95*COS(2*PI()*(1+0.5)/ROWS(codiciL1)) -> 1.5465205 | BY6: =IF(AND(ISNUMBER(Radar_Mosca!$F6),ISNUMBER(Radar_Mosca!$S6)),IF(AND(Radar_Mosca!$F6=BY$4,Radar_Mosca!$AA6=BY$3),Radar_Mosca!$S6,NA()),NA()) -> #N/A | BZ6: =IF(AND(ISNUMBER(Radar_Mosca!$F6),ISNUMBER(Radar_Mosca!$S6)),IF(AND(Radar_Mosca!$F6=BZ$4,Radar_Mosca!$AA6=BZ$3),Radar_Mosca!$S6,NA()),NA()) -> #N/A | CA6: =IF(AND(ISNUMBER(Radar_Mosca!$F6),ISNUMBER(Radar_Mosca!$S6)),IF(AND(Radar_Mosca!$F6=CA$4,Radar_Mosca!$AA6=CA$3),Radar_Mosca!$S6,NA()),NA()) -> #N/A | CB6: =IF(AND(ISNUMBER(Radar_Mosca!$F6),ISNUMBER(Radar_Mosca!$S6)),IF(AND(Radar_Mosca!$F6=CB$4,Radar_Mosca!$AA6=CB$3),Radar_Mosca!$S6,NA()),NA()) -> #N/A | CC6: =IF(AND(ISNUMBER(Radar_Mosca!$F6),ISNUMBER(Radar_Mosca!$S6)),IF(AND(Radar_Mosca!$F6=CC$4,Radar_Mosca!$AA6=CC$3),Radar_Mosca!$S6,NA()),NA()) -> #N/A | CD6: =IF(AND(ISNUMBER(Radar_Mosca!$F6),ISNUMBER(Radar_Mosca!$S6)),IF(AND(Radar_Mosca!$F6=CD$4,Radar_Mosca!$AA6=CD$3),Radar_Mosca!$S6,NA()),NA()) -> #N/A | CE6: =IF(AND(ISNUMBER(Radar_Mosca!$F6),ISNUMBER(Radar_Mosca!$S6)),IF(AND(Radar_Mosca!$F6=CE$4,Radar_Mosca!$AA6=CE$3),Radar_Mosca!$S6,NA()),NA()) -> #N/A | CF6: =IF(AND(ISNUMBER(Radar_Mosca!$F6),ISNUMBER(Radar_Mosca!$S6)),IF(AND(Radar_Mosca!$F6=CF$4,Radar_Mosca!$AA6=CF$3),Radar_Mosca!$S6,NA()),NA()) -> #N/A | ... DN6: =IF(AND(ISNUMBER(Radar_Mosca!$F6),ISNUMBER(Radar_Mosca!$S6)),IF(AND(Radar_Mosca!$F6=DN$4,Radar_Mosca!$AA6=DN$3),Radar_Mosca!$S6,NA()),NA()) -> #N/A | DO6: =IF(ISNUMBER(Radar_Mosca!$R6),Radar_Mosca!$R6,NA()) -> -2.2437085 | DP6: =IF(Radar_Mosca!$A6="","",MID(Radar_Mosca!$A6,5,3)&IF(Radar_Mosca!$T6="Sì"," ◆","")) -> 02 ◆ | DQ6: =IF(ISNUMBER(Radar_Mosca!$S6),Radar_Mosca!$S6,NA()) -> -0.16814271 | DR6: Attenzione | DS6: -6.9 | DT6: -5.7
T7: =IF(Radar_Mosca!$AA$7="Attivazione",Radar_Mosca!$A$7,"") | BH7: =2*PI()*2/72 -> 0.17453293 | BI7: =2*SIN($BH7) -> 0.34729636 | BJ7: =2*COS($BH7) -> 1.9696155 | BK7: =3*SIN($BH7) -> 0.52094453 | BL7: =3*COS($BH7) -> 2.9544233 | BM7: =4*SIN($BH7) -> 0.69459271 | BN7: =4*COS($BH7) -> 3.939231 | BO7: =5*SIN($BH7) -> 0.86824089 | BP7: =5*COS($BH7) -> 4.9240388 | BR7: 0 | BS7: 0 | BU7: L1-03 Impiego e sicurezza | BV7: =6.95*SIN(2*PI()*(2+0.5)/ROWS(codiciL1)) -> 5.4337288 | BW7: =6.95*COS(2*PI()*(2+0.5)/ROWS(codiciL1)) -> -4.3332541 | BY7: =IF(AND(ISNUMBER(Radar_Mosca!$F7),ISNUMBER(Radar_Mosca!$S7)),IF(AND(Radar_Mosca!$F7=BY$4,Radar_Mosca!$AA7=BY$3),Radar_Mosca!$S7,NA()),NA()) -> #N/A | BZ7: =IF(AND(ISNUMBER(Radar_Mosca!$F7),ISNUMBER(Radar_Mosca!$S7)),IF(AND(Radar_Mosca!$F7=BZ$4,Radar_Mosca!$AA7=BZ$3),Radar_Mosca!$S7,NA()),NA()) -> #N/A | CA7: =IF(AND(ISNUMBER(Radar_Mosca!$F7),ISNUMBER(Radar_Mosca!$S7)),IF(AND(Radar_Mosca!$F7=CA$4,Radar_Mosca!$AA7=CA$3),Radar_Mosca!$S7,NA()),NA()) -> #N/A | CB7: =IF(AND(ISNUMBER(Radar_Mosca!$F7),ISNUMBER(Radar_Mosca!$S7)),IF(AND(Radar_Mosca!$F7=CB$4,Radar_Mosca!$AA7=CB$3),Radar_Mosca!$S7,NA()),NA()) -> #N/A | CC7: =IF(AND(ISNUMBER(Radar_Mosca!$F7),ISNUMBER(Radar_Mosca!$S7)),IF(AND(Radar_Mosca!$F7=CC$4,Radar_Mosca!$AA7=CC$3),Radar_Mosca!$S7,NA()),NA()) -> #N/A | CD7: =IF(AND(ISNUMBER(Radar_Mosca!$F7),ISNUMBER(Radar_Mosca!$S7)),IF(AND(Radar_Mosca!$F7=CD$4,Radar_Mosca!$AA7=CD$3),Radar_Mosca!$S7,NA()),NA()) -> #N/A | CE7: =IF(AND(ISNUMBER(Radar_Mosca!$F7),ISNUMBER(Radar_Mosca!$S7)),IF(AND(Radar_Mosca!$F7=CE$4,Radar_Mosca!$AA7=CE$3),Radar_Mosca!$S7,NA()),NA()) -> #N/A | CF7: =IF(AND(ISNUMBER(Radar_Mosca!$F7),ISNUMBER(Radar_Mosca!$S7)),IF(AND(Radar_Mosca!$F7=CF$4,Radar_Mosca!$AA7=CF$3),Radar_Mosca!$S7,NA()),NA()) -> #N/A | ... DN7: =IF(AND(ISNUMBER(Radar_Mosca!$F7),ISNUMBER(Radar_Mosca!$S7)),IF(AND(Radar_Mosca!$F7=DN$4,Radar_Mosca!$AA7=DN$3),Radar_Mosca!$S7,NA()),NA()) -> #N/A | DO7: =IF(ISNUMBER(Radar_Mosca!$R7),Radar_Mosca!$R7,NA()) -> 0.58951035 | DP7: =IF(Radar_Mosca!$A7="","",MID(Radar_Mosca!$A7,5,3)&IF(Radar_Mosca!$T7="Sì"," ◆","")) -> 03 | DQ7: =IF(ISNUMBER(Radar_Mosca!$S7),Radar_Mosca!$S7,NA()) -> -1.9111456 | DR7: Monitoraggio | DS7: -6.9 | DT7: -6.35
A8: Priorita' — primi cinque per score composito | J8: Gravita': Probabilita x Impatto | T8: =IF(Radar_Mosca!$AA$8="Attivazione",Radar_Mosca!$A$8,"") | BH8: =2*PI()*3/72 -> 0.26179939 | BI8: =2*SIN($BH8) -> 0.51763809 | BJ8: =2*COS($BH8) -> 1.9318517 | BK8: =3*SIN($BH8) -> 0.77645714 | BL8: =3*COS($BH8) -> 2.8977775 | BM8: =4*SIN($BH8) -> 1.0352762 | BN8: =4*COS($BH8) -> 3.8637033 | BO8: =5*SIN($BH8) -> 1.2940952 | BP8: =5*COS($BH8) -> 4.8296291 | BR8: =6.3*SIN(2*PI()*1/ROWS(codiciL1)) -> 4.9255383 | BS8: =6.3*COS(2*PI()*1/ROWS(codiciL1)) -> 3.9279858 | BU8: L1-04 Clientela e prodotti | BV8: =6.95*SIN(2*PI()*(3+0.5)/ROWS(codiciL1)) -> 8.5147818e-16 | BW8: =6.95*COS(2*PI()*(3+0.5)/ROWS(codiciL1)) -> -6.95 | BY8: =IF(AND(ISNUMBER(Radar_Mosca!$F8),ISNUMBER(Radar_Mosca!$S8)),IF(AND(Radar_Mosca!$F8=BY$4,Radar_Mosca!$AA8=BY$3),Radar_Mosca!$S8,NA()),NA()) -> #N/A | BZ8: =IF(AND(ISNUMBER(Radar_Mosca!$F8),ISNUMBER(Radar_Mosca!$S8)),IF(AND(Radar_Mosca!$F8=BZ$4,Radar_Mosca!$AA8=BZ$3),Radar_Mosca!$S8,NA()),NA()) -> #N/A | CA8: =IF(AND(ISNUMBER(Radar_Mosca!$F8),ISNUMBER(Radar_Mosca!$S8)),IF(AND(Radar_Mosca!$F8=CA$4,Radar_Mosca!$AA8=CA$3),Radar_Mosca!$S8,NA()),NA()) -> #N/A | CB8: =IF(AND(ISNUMBER(Radar_Mosca!$F8),ISNUMBER(Radar_Mosca!$S8)),IF(AND(Radar_Mosca!$F8=CB$4,Radar_Mosca!$AA8=CB$3),Radar_Mosca!$S8,NA()),NA()) -> #N/A | CC8: =IF(AND(ISNUMBER(Radar_Mosca!$F8),ISNUMBER(Radar_Mosca!$S8)),IF(AND(Radar_Mosca!$F8=CC$4,Radar_Mosca!$AA8=CC$3),Radar_Mosca!$S8,NA()),NA()) -> #N/A | CD8: =IF(AND(ISNUMBER(Radar_Mosca!$F8),ISNUMBER(Radar_Mosca!$S8)),IF(AND(Radar_Mosca!$F8=CD$4,Radar_Mosca!$AA8=CD$3),Radar_Mosca!$S8,NA()),NA()) -> #N/A | CE8: =IF(AND(ISNUMBER(Radar_Mosca!$F8),ISNUMBER(Radar_Mosca!$S8)),IF(AND(Radar_Mosca!$F8=CE$4,Radar_Mosca!$AA8=CE$3),Radar_Mosca!$S8,NA()),NA()) -> #N/A | CF8: =IF(AND(ISNUMBER(Radar_Mosca!$F8),ISNUMBER(Radar_Mosca!$S8)),IF(AND(Radar_Mosca!$F8=CF$4,Radar_Mosca!$AA8=CF$3),Radar_Mosca!$S8,NA()),NA()) -> #N/A | ... DN8: =IF(AND(ISNUMBER(Radar_Mosca!$F8),ISNUMBER(Radar_Mosca!$S8)),IF(AND(Radar_Mosca!$F8=DN$4,Radar_Mosca!$AA8=DN$3),Radar_Mosca!$S8,NA()),NA()) -> #N/A | DO8: =IF(ISNUMBER(Radar_Mosca!$R8),Radar_Mosca!$R8,NA()) -> -2.1500366 | DP8: =IF(Radar_Mosca!$A8="","",MID(Radar_Mosca!$A8,5,3)&IF(Radar_Mosca!$T8="Sì"," ◆","")) -> 04 | DQ8: =IF(ISNUMBER(Radar_Mosca!$S8),Radar_Mosca!$S8,NA()) -> -1.714597 | DR8: AGIRE ORA: X + Y > Z | DS8: -7.35 | DT8: -7.35
A9: # | B9: Rischio | F9: Score | G9: Variazione | H9: Urgenza | J9: P \ S | K9: 1 | L9: 2 | M9: 3 | N9: 4 | O9: 5 | T9: =IF(Radar_Mosca!$AA$9="Attivazione",Radar_Mosca!$A$9,"") | BH9: =2*PI()*4/72 -> 0.34906585 | BI9: =2*SIN($BH9) -> 0.68404029 | BJ9: =2*COS($BH9) -> 1.8793852 | BK9: =3*SIN($BH9) -> 1.0260604 | BL9: =3*COS($BH9) -> 2.8190779 | BM9: =4*SIN($BH9) -> 1.3680806 | BN9: =4*COS($BH9) -> 3.7587705 | BO9: =5*SIN($BH9) -> 1.7101007 | BP9: =5*COS($BH9) -> 4.6984631 | BR9: 0 | BS9: 0 | BU9: L1-05 Danni a beni materiali | BV9: =6.95*SIN(2*PI()*(4+0.5)/ROWS(codiciL1)) -> -5.4337288 | BW9: =6.95*COS(2*PI()*(4+0.5)/ROWS(codiciL1)) -> -4.3332541 | BY9: =IF(AND(ISNUMBER(Radar_Mosca!$F9),ISNUMBER(Radar_Mosca!$S9)),IF(AND(Radar_Mosca!$F9=BY$4,Radar_Mosca!$AA9=BY$3),Radar_Mosca!$S9,NA()),NA()) -> #N/A | BZ9: =IF(AND(ISNUMBER(Radar_Mosca!$F9),ISNUMBER(Radar_Mosca!$S9)),IF(AND(Radar_Mosca!$F9=BZ$4,Radar_Mosca!$AA9=BZ$3),Radar_Mosca!$S9,NA()),NA()) -> #N/A | CA9: =IF(AND(ISNUMBER(Radar_Mosca!$F9),ISNUMBER(Radar_Mosca!$S9)),IF(AND(Radar_Mosca!$F9=CA$4,Radar_Mosca!$AA9=CA$3),Radar_Mosca!$S9,NA()),NA()) -> #N/A | CB9: =IF(AND(ISNUMBER(Radar_Mosca!$F9),ISNUMBER(Radar_Mosca!$S9)),IF(AND(Radar_Mosca!$F9=CB$4,Radar_Mosca!$AA9=CB$3),Radar_Mosca!$S9,NA()),NA()) -> #N/A | CC9: =IF(AND(ISNUMBER(Radar_Mosca!$F9),ISNUMBER(Radar_Mosca!$S9)),IF(AND(Radar_Mosca!$F9=CC$4,Radar_Mosca!$AA9=CC$3),Radar_Mosca!$S9,NA()),NA()) -> #N/A | CD9: =IF(AND(ISNUMBER(Radar_Mosca!$F9),ISNUMBER(Radar_Mosca!$S9)),IF(AND(Radar_Mosca!$F9=CD$4,Radar_Mosca!$AA9=CD$3),Radar_Mosca!$S9,NA()),NA()) -> #N/A | CE9: =IF(AND(ISNUMBER(Radar_Mosca!$F9),ISNUMBER(Radar_Mosca!$S9)),IF(AND(Radar_Mosca!$F9=CE$4,Radar_Mosca!$AA9=CE$3),Radar_Mosca!$S9,NA()),NA()) -> #N/A | CF9: =IF(AND(ISNUMBER(Radar_Mosca!$F9),ISNUMBER(Radar_Mosca!$S9)),IF(AND(Radar_Mosca!$F9=CF$4,Radar_Mosca!$AA9=CF$3),Radar_Mosca!$S9,NA()),NA()) -> #N/A | ... DN9: =IF(AND(ISNUMBER(Radar_Mosca!$F9),ISNUMBER(Radar_Mosca!$S9)),IF(AND(Radar_Mosca!$F9=DN$4,Radar_Mosca!$AA9=DN$3),Radar_Mosca!$S9,NA()),NA()) -> #N/A | DO9: =IF(ISNUMBER(Radar_Mosca!$R9),Radar_Mosca!$R9,NA()) -> -1.8704694 | DP9: =IF(Radar_Mosca!$A9="","",MID(Radar_Mosca!$A9,5,3)&IF(Radar_Mosca!$T9="Sì"," ◆","")) -> 05 | DQ9: =IF(ISNUMBER(Radar_Mosca!$S9),Radar_Mosca!$S9,NA()) -> 2.3454944 | DS9: -6.45 | DT9: -7.35
A10: =Classifica!$A$5 -> 1 | B10: =IF(Classifica!$B$5="","",Classifica!$B$5&" "&Classifica!$C$5&IFERROR(IF(INDEX(ANA_Attenzione_Supervisore,Classifica!$U$5)="Sì"," ◆",""),"")) -> NFR-01 Frodi su pagamenti istantanei abilitate da AI generativa ◆ | F10: =IF(Classifica!$B$5="","",Classifica!$D$5) -> 4.2 | G10: =IF(Classifica!$B$5="","",IF(ISNUMBER(Classifica!$F$5),Classifica!$F$5,"nuovo")) -> 0 | H10: =IF(Classifica!$B$5="","",IF(LEFT(Classifica!$H$5,9)="AGIRE ORA","AGIRE ORA",IF(LEFT(Classifica!$H$5,11)="Agire entro","Entro l'anno",Classifica!$H$5))) -> AGIRE ORA | J10: 5 | K10: =SUBSTITUTE(SUBSTITUTE(Matrice!C5," ◆",""),"NFR-","") | L10: =SUBSTITUTE(SUBSTITUTE(Matrice!D5," ◆",""),"NFR-","") | M10: =SUBSTITUTE(SUBSTITUTE(Matrice!E5," ◆",""),"NFR-","") | N10: =SUBSTITUTE(SUBSTITUTE(Matrice!F5," ◆",""),"NFR-","") | O10: =SUBSTITUTE(SUBSTITUTE(Matrice!G5," ◆",""),"NFR-","") | T10: =IF(Radar_Mosca!$AA$10="Attivazione",Radar_Mosca!$A$10,"") | BH10: =2*PI()*5/72 -> 0.43633231 | BI10: =2*SIN($BH10) -> 0.84523652 | BJ10: =2*COS($BH10) -> 1.8126156 | BK10: =3*SIN($BH10) -> 1.2678548 | BL10: =3*COS($BH10) -> 2.7189234 | BM10: =4*SIN($BH10) -> 1.690473 | BN10: =4*COS($BH10) -> 3.6252311 | BO10: =5*SIN($BH10) -> 2.1130913 | BP10: =5*COS($BH10) -> 4.5315389 | BR10: =6.3*SIN(2*PI()*2/ROWS(codiciL1)) -> 6.1420458 | BS10: =6.3*COS(2*PI()*2/ROWS(codiciL1)) -> -1.4018819 | BU10: L1-06 Interruzione e sistemi | BV10: =6.95*SIN(2*PI()*(5+0.5)/ROWS(codiciL1)) -> -6.775749 | BW10: =6.95*COS(2*PI()*(5+0.5)/ROWS(codiciL1)) -> 1.5465205 | BY10: =IF(AND(ISNUMBER(Radar_Mosca!$F10),ISNUMBER(Radar_Mosca!$S10)),IF(AND(Radar_Mosca!$F10=BY$4,Radar_Mosca!$AA10=BY$3),Radar_Mosca!$S10,NA()),NA()) -> #N/A | BZ10: =IF(AND(ISNUMBER(Radar_Mosca!$F10),ISNUMBER(Radar_Mosca!$S10)),IF(AND(Radar_Mosca!$F10=BZ$4,Radar_Mosca!$AA10=BZ$3),Radar_Mosca!$S10,NA()),NA()) -> #N/A | CA10: =IF(AND(ISNUMBER(Radar_Mosca!$F10),ISNUMBER(Radar_Mosca!$S10)),IF(AND(Radar_Mosca!$F10=CA$4,Radar_Mosca!$AA10=CA$3),Radar_Mosca!$S10,NA()),NA()) -> #N/A | CB10: =IF(AND(ISNUMBER(Radar_Mosca!$F10),ISNUMBER(Radar_Mosca!$S10)),IF(AND(Radar_Mosca!$F10=CB$4,Radar_Mosca!$AA10=CB$3),Radar_Mosca!$S10,NA()),NA()) -> #N/A | CC10: =IF(AND(ISNUMBER(Radar_Mosca!$F10),ISNUMBER(Radar_Mosca!$S10)),IF(AND(Radar_Mosca!$F10=CC$4,Radar_Mosca!$AA10=CC$3),Radar_Mosca!$S10,NA()),NA()) -> #N/A | CD10: =IF(AND(ISNUMBER(Radar_Mosca!$F10),ISNUMBER(Radar_Mosca!$S10)),IF(AND(Radar_Mosca!$F10=CD$4,Radar_Mosca!$AA10=CD$3),Radar_Mosca!$S10,NA()),NA()) -> #N/A | CE10: =IF(AND(ISNUMBER(Radar_Mosca!$F10),ISNUMBER(Radar_Mosca!$S10)),IF(AND(Radar_Mosca!$F10=CE$4,Radar_Mosca!$AA10=CE$3),Radar_Mosca!$S10,NA()),NA()) -> #N/A | CF10: =IF(AND(ISNUMBER(Radar_Mosca!$F10),ISNUMBER(Radar_Mosca!$S10)),IF(AND(Radar_Mosca!$F10=CF$4,Radar_Mosca!$AA10=CF$3),Radar_Mosca!$S10,NA()),NA()) -> #N/A | ... DN10: =IF(AND(ISNUMBER(Radar_Mosca!$F10),ISNUMBER(Radar_Mosca!$S10)),IF(AND(Radar_Mosca!$F10=DN$4,Radar_Mosca!$AA10=DN$3),Radar_Mosca!$S10,NA()),NA()) -> #N/A | DO10: =IF(ISNUMBER(Radar_Mosca!$R10),Radar_Mosca!$R10,NA()) -> 0.61193257 | DP10: =IF(Radar_Mosca!$A10="","",MID(Radar_Mosca!$A10,5,3)&IF(Radar_Mosca!$T10="Sì"," ◆","")) -> 06 | DQ10: =IF(ISNUMBER(Radar_Mosca!$S10),Radar_Mosca!$S10,NA()) -> 2.6810518 | DR10: Area del cerchio = P x I | DS10: 4.4 | DT10: -5.6
A11: =Classifica!$A$6 -> 2 | B11: =IF(Classifica!$B$6="","",Classifica!$B$6&" "&Classifica!$C$6&IFERROR(IF(INDEX(ANA_Attenzione_Supervisore,Classifica!$U$6)="Sì"," ◆",""),"")) -> NFR-07 Ransomware presso un fornitore di servizi di pagamento ◆ | F11: =IF(Classifica!$B$6="","",Classifica!$D$6) -> 3.75 | G11: =IF(Classifica!$B$6="","",IF(ISNUMBER(Classifica!$F$6),Classifica!$F$6,"nuovo")) -> 0 | H11: =IF(Classifica!$B$6="","",IF(LEFT(Classifica!$H$6,9)="AGIRE ORA","AGIRE ORA",IF(LEFT(Classifica!$H$6,11)="Agire entro","Entro l'anno",Classifica!$H$6))) -> Entro l'anno | J11: 4 | K11: =SUBSTITUTE(SUBSTITUTE(Matrice!C6," ◆",""),"NFR-","") | L11: =SUBSTITUTE(SUBSTITUTE(Matrice!D6," ◆",""),"NFR-","") | M11: =SUBSTITUTE(SUBSTITUTE(Matrice!E6," ◆",""),"NFR-","") -> 12 | N11: =SUBSTITUTE(SUBSTITUTE(Matrice!F6," ◆",""),"NFR-","") -> 01 | O11: =SUBSTITUTE(SUBSTITUTE(Matrice!G6," ◆",""),"NFR-","") | T11: =IF(Radar_Mosca!$AA$11="Attivazione",Radar_Mosca!$A$11,"") | BH11: =2*PI()*6/72 -> 0.52359878 | BI11: =2*SIN($BH11) -> 1 | BJ11: =2*COS($BH11) -> 1.7320508 | BK11: =3*SIN($BH11) -> 1.5 | BL11: =3*COS($BH11) -> 2.5980762 | BM11: =4*SIN($BH11) -> 2 | BN11: =4*COS($BH11) -> 3.4641016 | BO11: =5*SIN($BH11) -> 2.5 | BP11: =5*COS($BH11) -> 4.330127 | BR11: 0 | BS11: 0 | BU11: L1-07 Processi | BV11: =6.95*SIN(2*PI()*(6+0.5)/ROWS(codiciL1)) -> -3.015492 | BW11: =6.95*COS(2*PI()*(6+0.5)/ROWS(codiciL1)) -> 6.2617336 | BY11: =IF(AND(ISNUMBER(Radar_Mosca!$F11),ISNUMBER(Radar_Mosca!$S11)),IF(AND(Radar_Mosca!$F11=BY$4,Radar_Mosca!$AA11=BY$3),Radar_Mosca!$S11,NA()),NA()) -> #N/A | BZ11: =IF(AND(ISNUMBER(Radar_Mosca!$F11),ISNUMBER(Radar_Mosca!$S11)),IF(AND(Radar_Mosca!$F11=BZ$4,Radar_Mosca!$AA11=BZ$3),Radar_Mosca!$S11,NA()),NA()) -> #N/A | CA11: =IF(AND(ISNUMBER(Radar_Mosca!$F11),ISNUMBER(Radar_Mosca!$S11)),IF(AND(Radar_Mosca!$F11=CA$4,Radar_Mosca!$AA11=CA$3),Radar_Mosca!$S11,NA()),NA()) -> #N/A | CB11: =IF(AND(ISNUMBER(Radar_Mosca!$F11),ISNUMBER(Radar_Mosca!$S11)),IF(AND(Radar_Mosca!$F11=CB$4,Radar_Mosca!$AA11=CB$3),Radar_Mosca!$S11,NA()),NA()) -> #N/A | CC11: =IF(AND(ISNUMBER(Radar_Mosca!$F11),ISNUMBER(Radar_Mosca!$S11)),IF(AND(Radar_Mosca!$F11=CC$4,Radar_Mosca!$AA11=CC$3),Radar_Mosca!$S11,NA()),NA()) -> #N/A | CD11: =IF(AND(ISNUMBER(Radar_Mosca!$F11),ISNUMBER(Radar_Mosca!$S11)),IF(AND(Radar_Mosca!$F11=CD$4,Radar_Mosca!$AA11=CD$3),Radar_Mosca!$S11,NA()),NA()) -> #N/A | CE11: =IF(AND(ISNUMBER(Radar_Mosca!$F11),ISNUMBER(Radar_Mosca!$S11)),IF(AND(Radar_Mosca!$F11=CE$4,Radar_Mosca!$AA11=CE$3),Radar_Mosca!$S11,NA()),NA()) -> #N/A | CF11: =IF(AND(ISNUMBER(Radar_Mosca!$F11),ISNUMBER(Radar_Mosca!$S11)),IF(AND(Radar_Mosca!$F11=CF$4,Radar_Mosca!$AA11=CF$3),Radar_Mosca!$S11,NA()),NA()) -> #N/A | ... DN11: =IF(AND(ISNUMBER(Radar_Mosca!$F11),ISNUMBER(Radar_Mosca!$S11)),IF(AND(Radar_Mosca!$F11=DN$4,Radar_Mosca!$AA11=DN$3),Radar_Mosca!$S11,NA()),NA()) -> #N/A | DO11: =IF(ISNUMBER(Radar_Mosca!$R11),Radar_Mosca!$R11,NA()) -> -2.6810518 | DP11: =IF(Radar_Mosca!$A11="","",MID(Radar_Mosca!$A11,5,3)&IF(Radar_Mosca!$T11="Sì"," ◆","")) -> 07 ◆ | DQ11: =IF(ISNUMBER(Radar_Mosca!$S11),Radar_Mosca!$S11,NA()) -> 0.61193257 | DR11: 4 | DS11: 3.5 | DT11: -6.6
A12: =Classifica!$A$7 -> 3 | B12: =IF(Classifica!$B$7="","",Classifica!$B$7&" "&Classifica!$C$7&IFERROR(IF(INDEX(ANA_Attenzione_Supervisore,Classifica!$U$7)="Sì"," ◆",""),"")) -> NFR-12 Errori operativi nei pagamenti istantanei obbligatori | F12: =IF(Classifica!$B$7="","",Classifica!$D$7) -> 3.65 | G12: =IF(Classifica!$B$7="","",IF(ISNUMBER(Classifica!$F$7),Classifica!$F$7,"nuovo")) -> 0 | H12: =IF(Classifica!$B$7="","",IF(LEFT(Classifica!$H$7,9)="AGIRE ORA","AGIRE ORA",IF(LEFT(Classifica!$H$7,11)="Agire entro","Entro l'anno",Classifica!$H$7))) -> Entro l'anno | J12: 3 | K12: =SUBSTITUTE(SUBSTITUTE(Matrice!C7," ◆",""),"NFR-","") | L12: =SUBSTITUTE(SUBSTITUTE(Matrice!D7," ◆",""),"NFR-","") | M12: =SUBSTITUTE(SUBSTITUTE(Matrice!E7," ◆",""),"NFR-","") -> 03 04 05 06 10 11 | N12: =SUBSTITUTE(SUBSTITUTE(Matrice!F7," ◆",""),"NFR-","") -> 07 | O12: =SUBSTITUTE(SUBSTITUTE(Matrice!G7," ◆",""),"NFR-","") | T12: =IF(Radar_Mosca!$AA$12="Attivazione",Radar_Mosca!$A$12,"") | BH12: =2*PI()*7/72 -> 0.61086524 | BI12: =2*SIN($BH12) -> 1.1471529 | BJ12: =2*COS($BH12) -> 1.6383041 | BK12: =3*SIN($BH12) -> 1.7207293 | BL12: =3*COS($BH12) -> 2.4574561 | BM12: =4*SIN($BH12) -> 2.2943057 | BN12: =4*COS($BH12) -> 3.2766082 | BO12: =5*SIN($BH12) -> 2.8678822 | BP12: =5*COS($BH12) -> 4.0957602 | BR12: =6.3*SIN(2*PI()*3/ROWS(codiciL1)) -> 2.7334676 | BS12: =6.3*COS(2*PI()*3/ROWS(codiciL1)) -> -5.6761039 | BY12: =IF(AND(ISNUMBER(Radar_Mosca!$F12),ISNUMBER(Radar_Mosca!$S12)),IF(AND(Radar_Mosca!$F12=BY$4,Radar_Mosca!$AA12=BY$3),Radar_Mosca!$S12,NA()),NA()) -> #N/A | BZ12: =IF(AND(ISNUMBER(Radar_Mosca!$F12),ISNUMBER(Radar_Mosca!$S12)),IF(AND(Radar_Mosca!$F12=BZ$4,Radar_Mosca!$AA12=BZ$3),Radar_Mosca!$S12,NA()),NA()) -> #N/A | CA12: =IF(AND(ISNUMBER(Radar_Mosca!$F12),ISNUMBER(Radar_Mosca!$S12)),IF(AND(Radar_Mosca!$F12=CA$4,Radar_Mosca!$AA12=CA$3),Radar_Mosca!$S12,NA()),NA()) -> #N/A | CB12: =IF(AND(ISNUMBER(Radar_Mosca!$F12),ISNUMBER(Radar_Mosca!$S12)),IF(AND(Radar_Mosca!$F12=CB$4,Radar_Mosca!$AA12=CB$3),Radar_Mosca!$S12,NA()),NA()) -> #N/A | CC12: =IF(AND(ISNUMBER(Radar_Mosca!$F12),ISNUMBER(Radar_Mosca!$S12)),IF(AND(Radar_Mosca!$F12=CC$4,Radar_Mosca!$AA12=CC$3),Radar_Mosca!$S12,NA()),NA()) -> #N/A | CD12: =IF(AND(ISNUMBER(Radar_Mosca!$F12),ISNUMBER(Radar_Mosca!$S12)),IF(AND(Radar_Mosca!$F12=CD$4,Radar_Mosca!$AA12=CD$3),Radar_Mosca!$S12,NA()),NA()) -> #N/A | CE12: =IF(AND(ISNUMBER(Radar_Mosca!$F12),ISNUMBER(Radar_Mosca!$S12)),IF(AND(Radar_Mosca!$F12=CE$4,Radar_Mosca!$AA12=CE$3),Radar_Mosca!$S12,NA()),NA()) -> #N/A | CF12: =IF(AND(ISNUMBER(Radar_Mosca!$F12),ISNUMBER(Radar_Mosca!$S12)),IF(AND(Radar_Mosca!$F12=CF$4,Radar_Mosca!$AA12=CF$3),Radar_Mosca!$S12,NA()),NA()) -> #N/A | ... DN12: =IF(AND(ISNUMBER(Radar_Mosca!$F12),ISNUMBER(Radar_Mosca!$S12)),IF(AND(Radar_Mosca!$F12=DN$4,Radar_Mosca!$AA12=DN$3),Radar_Mosca!$S12,NA()),NA()) -> #N/A | DO12: =IF(ISNUMBER(Radar_Mosca!$R12),Radar_Mosca!$R12,NA()) -> 1.8704694 | DP12: =IF(Radar_Mosca!$A12="","",MID(Radar_Mosca!$A12,5,3)&IF(Radar_Mosca!$T12="Sì"," ◆","")) -> 08 | DQ12: =IF(ISNUMBER(Radar_Mosca!$S12),Radar_Mosca!$S12,NA()) -> 2.3454944 | DR12: 12 | DS12: 4.8 | DT12: -6.6
A13: =Classifica!$A$8 -> 4 | B13: =IF(Classifica!$B$8="","",Classifica!$B$8&" "&Classifica!$C$8&IFERROR(IF(INDEX(ANA_Attenzione_Supervisore,Classifica!$U$8)="Sì"," ◆",""),"")) -> NFR-02 Concentrazione su un fornitore cloud critico ◆ | F13: =IF(Classifica!$B$8="","",Classifica!$D$8) -> 3.3 | G13: =IF(Classifica!$B$8="","",IF(ISNUMBER(Classifica!$F$8),Classifica!$F$8,"nuovo")) -> 0 | H13: =IF(Classifica!$B$8="","",IF(LEFT(Classifica!$H$8,9)="AGIRE ORA","AGIRE ORA",IF(LEFT(Classifica!$H$8,11)="Agire entro","Entro l'anno",Classifica!$H$8))) -> Entro l'anno | J13: 2 | K13: =SUBSTITUTE(SUBSTITUTE(Matrice!C8," ◆",""),"NFR-","") | L13: =SUBSTITUTE(SUBSTITUTE(Matrice!D8," ◆",""),"NFR-","") | M13: =SUBSTITUTE(SUBSTITUTE(Matrice!E8," ◆",""),"NFR-","") -> 08 | N13: =SUBSTITUTE(SUBSTITUTE(Matrice!F8," ◆",""),"NFR-","") -> 02 09 | O13: =SUBSTITUTE(SUBSTITUTE(Matrice!G8," ◆",""),"NFR-","") | T13: =IF(Radar_Mosca!$AA$13="Attivazione",Radar_Mosca!$A$13,"") | BH13: =2*PI()*8/72 -> 0.6981317 | BI13: =2*SIN($BH13) -> 1.2855752 | BJ13: =2*COS($BH13) -> 1.5320889 | BK13: =3*SIN($BH13) -> 1.9283628 | BL13: =3*COS($BH13) -> 2.2981333 | BM13: =4*SIN($BH13) -> 2.5711504 | BN13: =4*COS($BH13) -> 3.0641778 | BO13: =5*SIN($BH13) -> 3.213938 | BP13: =5*COS($BH13) -> 3.8302222 | BR13: 0 | BS13: 0 | BY13: =IF(AND(ISNUMBER(Radar_Mosca!$F13),ISNUMBER(Radar_Mosca!$S13)),IF(AND(Radar_Mosca!$F13=BY$4,Radar_Mosca!$AA13=BY$3),Radar_Mosca!$S13,NA()),NA()) -> #N/A | BZ13: =IF(AND(ISNUMBER(Radar_Mosca!$F13),ISNUMBER(Radar_Mosca!$S13)),IF(AND(Radar_Mosca!$F13=BZ$4,Radar_Mosca!$AA13=BZ$3),Radar_Mosca!$S13,NA()),NA()) -> #N/A | CA13: =IF(AND(ISNUMBER(Radar_Mosca!$F13),ISNUMBER(Radar_Mosca!$S13)),IF(AND(Radar_Mosca!$F13=CA$4,Radar_Mosca!$AA13=CA$3),Radar_Mosca!$S13,NA()),NA()) -> #N/A | CB13: =IF(AND(ISNUMBER(Radar_Mosca!$F13),ISNUMBER(Radar_Mosca!$S13)),IF(AND(Radar_Mosca!$F13=CB$4,Radar_Mosca!$AA13=CB$3),Radar_Mosca!$S13,NA()),NA()) -> #N/A | CC13: =IF(AND(ISNUMBER(Radar_Mosca!$F13),ISNUMBER(Radar_Mosca!$S13)),IF(AND(Radar_Mosca!$F13=CC$4,Radar_Mosca!$AA13=CC$3),Radar_Mosca!$S13,NA()),NA()) -> #N/A | CD13: =IF(AND(ISNUMBER(Radar_Mosca!$F13),ISNUMBER(Radar_Mosca!$S13)),IF(AND(Radar_Mosca!$F13=CD$4,Radar_Mosca!$AA13=CD$3),Radar_Mosca!$S13,NA()),NA()) -> #N/A | CE13: =IF(AND(ISNUMBER(Radar_Mosca!$F13),ISNUMBER(Radar_Mosca!$S13)),IF(AND(Radar_Mosca!$F13=CE$4,Radar_Mosca!$AA13=CE$3),Radar_Mosca!$S13,NA()),NA()) -> #N/A | CF13: =IF(AND(ISNUMBER(Radar_Mosca!$F13),ISNUMBER(Radar_Mosca!$S13)),IF(AND(Radar_Mosca!$F13=CF$4,Radar_Mosca!$AA13=CF$3),Radar_Mosca!$S13,NA()),NA()) -> #N/A | ... DN13: =IF(AND(ISNUMBER(Radar_Mosca!$F13),ISNUMBER(Radar_Mosca!$S13)),IF(AND(Radar_Mosca!$F13=DN$4,Radar_Mosca!$AA13=DN$3),Radar_Mosca!$S13,NA()),NA()) -> #N/A | DO13: =IF(ISNUMBER(Radar_Mosca!$R13),Radar_Mosca!$R13,NA()) -> 3.9817325e-16 | DP13: =IF(Radar_Mosca!$A13="","",MID(Radar_Mosca!$A13,5,3)&IF(Radar_Mosca!$T13="Sì"," ◆","")) -> 09 ◆ | DQ13: =IF(ISNUMBER(Radar_Mosca!$S13),Radar_Mosca!$S13,NA()) -> -3.25 | DR13: 25 | DS13: 6.5 | DT13: -6.6
A14: =Classifica!$A$9 -> 5 | B14: =IF(Classifica!$B$9="","",Classifica!$B$9&" "&Classifica!$C$9&IFERROR(IF(INDEX(ANA_Attenzione_Supervisore,Classifica!$U$9)="Sì"," ◆",""),"")) -> NFR-03 Greenwashing nella commercializzazione di prodotti ESG | F14: =IF(Classifica!$B$9="","",Classifica!$D$9) -> 3 | G14: =IF(Classifica!$B$9="","",IF(ISNUMBER(Classifica!$F$9),Classifica!$F$9,"nuovo")) -> 0.2 | H14: =IF(Classifica!$B$9="","",IF(LEFT(Classifica!$H$9,9)="AGIRE ORA","AGIRE ORA",IF(LEFT(Classifica!$H$9,11)="Agire entro","Entro l'anno",Classifica!$H$9))) -> Entro l'anno | J14: 1 | K14: =SUBSTITUTE(SUBSTITUTE(Matrice!C9," ◆",""),"NFR-","") | L14: =SUBSTITUTE(SUBSTITUTE(Matrice!D9," ◆",""),"NFR-","") | M14: =SUBSTITUTE(SUBSTITUTE(Matrice!E9," ◆",""),"NFR-","") | N14: =SUBSTITUTE(SUBSTITUTE(Matrice!F9," ◆",""),"NFR-","") | O14: =SUBSTITUTE(SUBSTITUTE(Matrice!G9," ◆",""),"NFR-","") | T14: =IF(Radar_Mosca!$AA$14="Attivazione",Radar_Mosca!$A$14,"") | BH14: =2*PI()*9/72 -> 0.78539816 | BI14: =2*SIN($BH14) -> 1.4142136 | BJ14: =2*COS($BH14) -> 1.4142136 | BK14: =3*SIN($BH14) -> 2.1213203 | BL14: =3*COS($BH14) -> 2.1213203 | BM14: =4*SIN($BH14) -> 2.8284271 | BN14: =4*COS($BH14) -> 2.8284271 | BO14: =5*SIN($BH14) -> 3.5355339 | BP14: =5*COS($BH14) -> 3.5355339 | BR14: =6.3*SIN(2*PI()*4/ROWS(codiciL1)) -> -2.7334676 | BS14: =6.3*COS(2*PI()*4/ROWS(codiciL1)) -> -5.6761039 | BY14: =IF(AND(ISNUMBER(Radar_Mosca!$F14),ISNUMBER(Radar_Mosca!$S14)),IF(AND(Radar_Mosca!$F14=BY$4,Radar_Mosca!$AA14=BY$3),Radar_Mosca!$S14,NA()),NA()) -> #N/A | BZ14: =IF(AND(ISNUMBER(Radar_Mosca!$F14),ISNUMBER(Radar_Mosca!$S14)),IF(AND(Radar_Mosca!$F14=BZ$4,Radar_Mosca!$AA14=BZ$3),Radar_Mosca!$S14,NA()),NA()) -> #N/A | CA14: =IF(AND(ISNUMBER(Radar_Mosca!$F14),ISNUMBER(Radar_Mosca!$S14)),IF(AND(Radar_Mosca!$F14=CA$4,Radar_Mosca!$AA14=CA$3),Radar_Mosca!$S14,NA()),NA()) -> #N/A | CB14: =IF(AND(ISNUMBER(Radar_Mosca!$F14),ISNUMBER(Radar_Mosca!$S14)),IF(AND(Radar_Mosca!$F14=CB$4,Radar_Mosca!$AA14=CB$3),Radar_Mosca!$S14,NA()),NA()) -> #N/A | CC14: =IF(AND(ISNUMBER(Radar_Mosca!$F14),ISNUMBER(Radar_Mosca!$S14)),IF(AND(Radar_Mosca!$F14=CC$4,Radar_Mosca!$AA14=CC$3),Radar_Mosca!$S14,NA()),NA()) -> #N/A | CD14: =IF(AND(ISNUMBER(Radar_Mosca!$F14),ISNUMBER(Radar_Mosca!$S14)),IF(AND(Radar_Mosca!$F14=CD$4,Radar_Mosca!$AA14=CD$3),Radar_Mosca!$S14,NA()),NA()) -> #N/A | CE14: =IF(AND(ISNUMBER(Radar_Mosca!$F14),ISNUMBER(Radar_Mosca!$S14)),IF(AND(Radar_Mosca!$F14=CE$4,Radar_Mosca!$AA14=CE$3),Radar_Mosca!$S14,NA()),NA()) -> #N/A | CF14: =IF(AND(ISNUMBER(Radar_Mosca!$F14),ISNUMBER(Radar_Mosca!$S14)),IF(AND(Radar_Mosca!$F14=CF$4,Radar_Mosca!$AA14=CF$3),Radar_Mosca!$S14,NA()),NA()) -> #N/A | ... DN14: =IF(AND(ISNUMBER(Radar_Mosca!$F14),ISNUMBER(Radar_Mosca!$S14)),IF(AND(Radar_Mosca!$F14=DN$4,Radar_Mosca!$AA14=DN$3),Radar_Mosca!$S14,NA()),NA()) -> #N/A | DO14: =IF(ISNUMBER(Radar_Mosca!$R14),Radar_Mosca!$R14,NA()) -> -0.88426552 | DP14: =IF(Radar_Mosca!$A14="","",MID(Radar_Mosca!$A14,5,3)&IF(Radar_Mosca!$T14="Sì"," ◆","")) -> 10 | DQ14: =IF(ISNUMBER(Radar_Mosca!$S14),Radar_Mosca!$S14,NA()) -> -2.8667184
A15: Score 1-5, 5 = peggiore; barra su scala fissa 0-5. Variazione sul ciclo precedente. | J15: Numeri = NFR-nn. Verde P x I fino a 6, ambra 8-12, rosso da 15. | T15: =IF(Radar_Mosca!$AA$15="Attivazione",Radar_Mosca!$A$15,"") | BH15: =2*PI()*10/72 -> 0.87266463 | BI15: =2*SIN($BH15) -> 1.5320889 | BJ15: =2*COS($BH15) -> 1.2855752 | BK15: =3*SIN($BH15) -> 2.2981333 | BL15: =3*COS($BH15) -> 1.9283628 | BM15: =4*SIN($BH15) -> 3.0641778 | BN15: =4*COS($BH15) -> 2.5711504 | BO15: =5*SIN($BH15) -> 3.8302222 | BP15: =5*COS($BH15) -> 3.213938 | BR15: 0 | BS15: 0 | BY15: =IF(AND(ISNUMBER(Radar_Mosca!$F15),ISNUMBER(Radar_Mosca!$S15)),IF(AND(Radar_Mosca!$F15=BY$4,Radar_Mosca!$AA15=BY$3),Radar_Mosca!$S15,NA()),NA()) -> #N/A | BZ15: =IF(AND(ISNUMBER(Radar_Mosca!$F15),ISNUMBER(Radar_Mosca!$S15)),IF(AND(Radar_Mosca!$F15=BZ$4,Radar_Mosca!$AA15=BZ$3),Radar_Mosca!$S15,NA()),NA()) -> #N/A | CA15: =IF(AND(ISNUMBER(Radar_Mosca!$F15),ISNUMBER(Radar_Mosca!$S15)),IF(AND(Radar_Mosca!$F15=CA$4,Radar_Mosca!$AA15=CA$3),Radar_Mosca!$S15,NA()),NA()) -> #N/A | CB15: =IF(AND(ISNUMBER(Radar_Mosca!$F15),ISNUMBER(Radar_Mosca!$S15)),IF(AND(Radar_Mosca!$F15=CB$4,Radar_Mosca!$AA15=CB$3),Radar_Mosca!$S15,NA()),NA()) -> #N/A | CC15: =IF(AND(ISNUMBER(Radar_Mosca!$F15),ISNUMBER(Radar_Mosca!$S15)),IF(AND(Radar_Mosca!$F15=CC$4,Radar_Mosca!$AA15=CC$3),Radar_Mosca!$S15,NA()),NA()) -> #N/A | CD15: =IF(AND(ISNUMBER(Radar_Mosca!$F15),ISNUMBER(Radar_Mosca!$S15)),IF(AND(Radar_Mosca!$F15=CD$4,Radar_Mosca!$AA15=CD$3),Radar_Mosca!$S15,NA()),NA()) -> #N/A | CE15: =IF(AND(ISNUMBER(Radar_Mosca!$F15),ISNUMBER(Radar_Mosca!$S15)),IF(AND(Radar_Mosca!$F15=CE$4,Radar_Mosca!$AA15=CE$3),Radar_Mosca!$S15,NA()),NA()) -> #N/A | CF15: =IF(AND(ISNUMBER(Radar_Mosca!$F15),ISNUMBER(Radar_Mosca!$S15)),IF(AND(Radar_Mosca!$F15=CF$4,Radar_Mosca!$AA15=CF$3),Radar_Mosca!$S15,NA()),NA()) -> #N/A | ... DN15: =IF(AND(ISNUMBER(Radar_Mosca!$F15),ISNUMBER(Radar_Mosca!$S15)),IF(AND(Radar_Mosca!$F15=DN$4,Radar_Mosca!$AA15=DN$3),Radar_Mosca!$S15,NA()),NA()) -> #N/A | DO15: =IF(ISNUMBER(Radar_Mosca!$R15),Radar_Mosca!$R15,NA()) -> -0.51961524 | DP15: =IF(Radar_Mosca!$A15="","",MID(Radar_Mosca!$A15,5,3)&IF(Radar_Mosca!$T15="Sì"," ◆","")) -> 11 | DQ15: =IF(ISNUMBER(Radar_Mosca!$S15),Radar_Mosca!$S15,NA()) -> 0.3
A16: Note dell'analista | T16: =IF(Radar_Mosca!$AA$16="Attivazione",Radar_Mosca!$A$16,"") | BH16: =2*PI()*11/72 -> 0.95993109 | BI16: =2*SIN($BH16) -> 1.6383041 | BJ16: =2*COS($BH16) -> 1.1471529 | BK16: =3*SIN($BH16) -> 2.4574561 | BL16: =3*COS($BH16) -> 1.7207293 | BM16: =4*SIN($BH16) -> 3.2766082 | BN16: =4*COS($BH16) -> 2.2943057 | BO16: =5*SIN($BH16) -> 4.0957602 | BP16: =5*COS($BH16) -> 2.8678822 | BR16: =6.3*SIN(2*PI()*5/ROWS(codiciL1)) -> -6.1420458 | BS16: =6.3*COS(2*PI()*5/ROWS(codiciL1)) -> -1.4018819 | BY16: =IF(AND(ISNUMBER(Radar_Mosca!$F16),ISNUMBER(Radar_Mosca!$S16)),IF(AND(Radar_Mosca!$F16=BY$4,Radar_Mosca!$AA16=BY$3),Radar_Mosca!$S16,NA()),NA()) -> #N/A | BZ16: =IF(AND(ISNUMBER(Radar_Mosca!$F16),ISNUMBER(Radar_Mosca!$S16)),IF(AND(Radar_Mosca!$F16=BZ$4,Radar_Mosca!$AA16=BZ$3),Radar_Mosca!$S16,NA()),NA()) -> #N/A | CA16: =IF(AND(ISNUMBER(Radar_Mosca!$F16),ISNUMBER(Radar_Mosca!$S16)),IF(AND(Radar_Mosca!$F16=CA$4,Radar_Mosca!$AA16=CA$3),Radar_Mosca!$S16,NA()),NA()) -> #N/A | CB16: =IF(AND(ISNUMBER(Radar_Mosca!$F16),ISNUMBER(Radar_Mosca!$S16)),IF(AND(Radar_Mosca!$F16=CB$4,Radar_Mosca!$AA16=CB$3),Radar_Mosca!$S16,NA()),NA()) -> #N/A | CC16: =IF(AND(ISNUMBER(Radar_Mosca!$F16),ISNUMBER(Radar_Mosca!$S16)),IF(AND(Radar_Mosca!$F16=CC$4,Radar_Mosca!$AA16=CC$3),Radar_Mosca!$S16,NA()),NA()) -> #N/A | CD16: =IF(AND(ISNUMBER(Radar_Mosca!$F16),ISNUMBER(Radar_Mosca!$S16)),IF(AND(Radar_Mosca!$F16=CD$4,Radar_Mosca!$AA16=CD$3),Radar_Mosca!$S16,NA()),NA()) -> #N/A | CE16: =IF(AND(ISNUMBER(Radar_Mosca!$F16),ISNUMBER(Radar_Mosca!$S16)),IF(AND(Radar_Mosca!$F16=CE$4,Radar_Mosca!$AA16=CE$3),Radar_Mosca!$S16,NA()),NA()) -> #N/A | CF16: =IF(AND(ISNUMBER(Radar_Mosca!$F16),ISNUMBER(Radar_Mosca!$S16)),IF(AND(Radar_Mosca!$F16=CF$4,Radar_Mosca!$AA16=CF$3),Radar_Mosca!$S16,NA()),NA()) -> #N/A | ... DN16: =IF(AND(ISNUMBER(Radar_Mosca!$F16),ISNUMBER(Radar_Mosca!$S16)),IF(AND(Radar_Mosca!$F16=DN$4,Radar_Mosca!$AA16=DN$3),Radar_Mosca!$S16,NA()),NA()) -> #N/A | DO16: =IF(ISNUMBER(Radar_Mosca!$R16),Radar_Mosca!$R16,NA()) -> -0.44504187 | DP16: =IF(Radar_Mosca!$A16="","",MID(Radar_Mosca!$A16,5,3)&IF(Radar_Mosca!$T16="Sì"," ◆","")) -> 12 | DQ16: =IF(ISNUMBER(Radar_Mosca!$S16),Radar_Mosca!$S16,NA()) -> 1.9498558
A17: Urgenza: radar di Mosca | J17: I rischi del ciclo | T17: =IF(Radar_Mosca!$AA$17="Attivazione",Radar_Mosca!$A$17,"") | BH17: =2*PI()*12/72 -> 1.0471976 | BI17: =2*SIN($BH17) -> 1.7320508 | BJ17: =2*COS($BH17) -> 1 | BK17: =3*SIN($BH17) -> 2.5980762 | BL17: =3*COS($BH17) -> 1.5 | BM17: =4*SIN($BH17) -> 3.4641016 | BN17: =4*COS($BH17) -> 2 | BO17: =5*SIN($BH17) -> 4.330127 | BP17: =5*COS($BH17) -> 2.5 | BR17: 0 | BS17: 0 | BY17: =IF(AND(ISNUMBER(Radar_Mosca!$F17),ISNUMBER(Radar_Mosca!$S17)),IF(AND(Radar_Mosca!$F17=BY$4,Radar_Mosca!$AA17=BY$3),Radar_Mosca!$S17,NA()),NA()) -> #N/A | BZ17: =IF(AND(ISNUMBER(Radar_Mosca!$F17),ISNUMBER(Radar_Mosca!$S17)),IF(AND(Radar_Mosca!$F17=BZ$4,Radar_Mosca!$AA17=BZ$3),Radar_Mosca!$S17,NA()),NA()) -> #N/A | CA17: =IF(AND(ISNUMBER(Radar_Mosca!$F17),ISNUMBER(Radar_Mosca!$S17)),IF(AND(Radar_Mosca!$F17=CA$4,Radar_Mosca!$AA17=CA$3),Radar_Mosca!$S17,NA()),NA()) -> #N/A | CB17: =IF(AND(ISNUMBER(Radar_Mosca!$F17),ISNUMBER(Radar_Mosca!$S17)),IF(AND(Radar_Mosca!$F17=CB$4,Radar_Mosca!$AA17=CB$3),Radar_Mosca!$S17,NA()),NA()) -> #N/A | CC17: =IF(AND(ISNUMBER(Radar_Mosca!$F17),ISNUMBER(Radar_Mosca!$S17)),IF(AND(Radar_Mosca!$F17=CC$4,Radar_Mosca!$AA17=CC$3),Radar_Mosca!$S17,NA()),NA()) -> #N/A | CD17: =IF(AND(ISNUMBER(Radar_Mosca!$F17),ISNUMBER(Radar_Mosca!$S17)),IF(AND(Radar_Mosca!$F17=CD$4,Radar_Mosca!$AA17=CD$3),Radar_Mosca!$S17,NA()),NA()) -> #N/A | CE17: =IF(AND(ISNUMBER(Radar_Mosca!$F17),ISNUMBER(Radar_Mosca!$S17)),IF(AND(Radar_Mosca!$F17=CE$4,Radar_Mosca!$AA17=CE$3),Radar_Mosca!$S17,NA()),NA()) -> #N/A | CF17: =IF(AND(ISNUMBER(Radar_Mosca!$F17),ISNUMBER(Radar_Mosca!$S17)),IF(AND(Radar_Mosca!$F17=CF$4,Radar_Mosca!$AA17=CF$3),Radar_Mosca!$S17,NA()),NA()) -> #N/A | ... DN17: =IF(AND(ISNUMBER(Radar_Mosca!$F17),ISNUMBER(Radar_Mosca!$S17)),IF(AND(Radar_Mosca!$F17=DN$4,Radar_Mosca!$AA17=DN$3),Radar_Mosca!$S17,NA()),NA()) -> #N/A | DO17: =IF(ISNUMBER(Radar_Mosca!$R17),Radar_Mosca!$R17,NA()) -> #N/A | DP17: =IF(Radar_Mosca!$A17="","",MID(Radar_Mosca!$A17,5,3)&IF(Radar_Mosca!$T17="Sì"," ◆","")) | DQ17: =IF(ISNUMBER(Radar_Mosca!$S17),Radar_Mosca!$S17,NA()) -> #N/A
J18: =INDEX(posID,1)&"" -> NFR-01 | K18: =IF(J18="","",INDEX(posNome,1)&IF(INDEX(ANA_Attenzione_Supervisore,1)="Sì"," ◆","")) -> Frodi su pagamenti istantanei abilitate da AI generativa ◆ | T18: =IF(Radar_Mosca!$AA$18="Attivazione",Radar_Mosca!$A$18,"") | BH18: =2*PI()*13/72 -> 1.134464 | BI18: =2*SIN($BH18) -> 1.8126156 | BJ18: =2*COS($BH18) -> 0.84523652 | BK18: =3*SIN($BH18) -> 2.7189234 | BL18: =3*COS($BH18) -> 1.2678548 | BM18: =4*SIN($BH18) -> 3.6252311 | BN18: =4*COS($BH18) -> 1.690473 | BO18: =5*SIN($BH18) -> 4.5315389 | BP18: =5*COS($BH18) -> 2.1130913 | BR18: =6.3*SIN(2*PI()*6/ROWS(codiciL1)) -> -4.9255383 | BS18: =6.3*COS(2*PI()*6/ROWS(codiciL1)) -> 3.9279858 | BY18: =IF(AND(ISNUMBER(Radar_Mosca!$F18),ISNUMBER(Radar_Mosca!$S18)),IF(AND(Radar_Mosca!$F18=BY$4,Radar_Mosca!$AA18=BY$3),Radar_Mosca!$S18,NA()),NA()) -> #N/A | BZ18: =IF(AND(ISNUMBER(Radar_Mosca!$F18),ISNUMBER(Radar_Mosca!$S18)),IF(AND(Radar_Mosca!$F18=BZ$4,Radar_Mosca!$AA18=BZ$3),Radar_Mosca!$S18,NA()),NA()) -> #N/A | CA18: =IF(AND(ISNUMBER(Radar_Mosca!$F18),ISNUMBER(Radar_Mosca!$S18)),IF(AND(Radar_Mosca!$F18=CA$4,Radar_Mosca!$AA18=CA$3),Radar_Mosca!$S18,NA()),NA()) -> #N/A | CB18: =IF(AND(ISNUMBER(Radar_Mosca!$F18),ISNUMBER(Radar_Mosca!$S18)),IF(AND(Radar_Mosca!$F18=CB$4,Radar_Mosca!$AA18=CB$3),Radar_Mosca!$S18,NA()),NA()) -> #N/A | CC18: =IF(AND(ISNUMBER(Radar_Mosca!$F18),ISNUMBER(Radar_Mosca!$S18)),IF(AND(Radar_Mosca!$F18=CC$4,Radar_Mosca!$AA18=CC$3),Radar_Mosca!$S18,NA()),NA()) -> #N/A | CD18: =IF(AND(ISNUMBER(Radar_Mosca!$F18),ISNUMBER(Radar_Mosca!$S18)),IF(AND(Radar_Mosca!$F18=CD$4,Radar_Mosca!$AA18=CD$3),Radar_Mosca!$S18,NA()),NA()) -> #N/A | CE18: =IF(AND(ISNUMBER(Radar_Mosca!$F18),ISNUMBER(Radar_Mosca!$S18)),IF(AND(Radar_Mosca!$F18=CE$4,Radar_Mosca!$AA18=CE$3),Radar_Mosca!$S18,NA()),NA()) -> #N/A | CF18: =IF(AND(ISNUMBER(Radar_Mosca!$F18),ISNUMBER(Radar_Mosca!$S18)),IF(AND(Radar_Mosca!$F18=CF$4,Radar_Mosca!$AA18=CF$3),Radar_Mosca!$S18,NA()),NA()) -> #N/A | ... DN18: =IF(AND(ISNUMBER(Radar_Mosca!$F18),ISNUMBER(Radar_Mosca!$S18)),IF(AND(Radar_Mosca!$F18=DN$4,Radar_Mosca!$AA18=DN$3),Radar_Mosca!$S18,NA()),NA()) -> #N/A | DO18: =IF(ISNUMBER(Radar_Mosca!$R18),Radar_Mosca!$R18,NA()) -> #N/A | DP18: =IF(Radar_Mosca!$A18="","",MID(Radar_Mosca!$A18,5,3)&IF(Radar_Mosca!$T18="Sì"," ◆","")) | DQ18: =IF(ISNUMBER(Radar_Mosca!$S18),Radar_Mosca!$S18,NA()) -> #N/A
J19: =INDEX(posID,2)&"" -> NFR-02 | K19: =IF(J19="","",INDEX(posNome,2)&IF(INDEX(ANA_Attenzione_Supervisore,2)="Sì"," ◆","")) -> Concentrazione su un fornitore cloud critico ◆ | T19: =IF(Radar_Mosca!$AA$19="Attivazione",Radar_Mosca!$A$19,"") | BH19: =2*PI()*14/72 -> 1.2217305 | BI19: =2*SIN($BH19) -> 1.8793852 | BJ19: =2*COS($BH19) -> 0.68404029 | BK19: =3*SIN($BH19) -> 2.8190779 | BL19: =3*COS($BH19) -> 1.0260604 | BM19: =4*SIN($BH19) -> 3.7587705 | BN19: =4*COS($BH19) -> 1.3680806 | BO19: =5*SIN($BH19) -> 4.6984631 | BP19: =5*COS($BH19) -> 1.7101007 | BY19: =IF(AND(ISNUMBER(Radar_Mosca!$F19),ISNUMBER(Radar_Mosca!$S19)),IF(AND(Radar_Mosca!$F19=BY$4,Radar_Mosca!$AA19=BY$3),Radar_Mosca!$S19,NA()),NA()) -> #N/A | BZ19: =IF(AND(ISNUMBER(Radar_Mosca!$F19),ISNUMBER(Radar_Mosca!$S19)),IF(AND(Radar_Mosca!$F19=BZ$4,Radar_Mosca!$AA19=BZ$3),Radar_Mosca!$S19,NA()),NA()) -> #N/A | CA19: =IF(AND(ISNUMBER(Radar_Mosca!$F19),ISNUMBER(Radar_Mosca!$S19)),IF(AND(Radar_Mosca!$F19=CA$4,Radar_Mosca!$AA19=CA$3),Radar_Mosca!$S19,NA()),NA()) -> #N/A | CB19: =IF(AND(ISNUMBER(Radar_Mosca!$F19),ISNUMBER(Radar_Mosca!$S19)),IF(AND(Radar_Mosca!$F19=CB$4,Radar_Mosca!$AA19=CB$3),Radar_Mosca!$S19,NA()),NA()) -> #N/A | CC19: =IF(AND(ISNUMBER(Radar_Mosca!$F19),ISNUMBER(Radar_Mosca!$S19)),IF(AND(Radar_Mosca!$F19=CC$4,Radar_Mosca!$AA19=CC$3),Radar_Mosca!$S19,NA()),NA()) -> #N/A | CD19: =IF(AND(ISNUMBER(Radar_Mosca!$F19),ISNUMBER(Radar_Mosca!$S19)),IF(AND(Radar_Mosca!$F19=CD$4,Radar_Mosca!$AA19=CD$3),Radar_Mosca!$S19,NA()),NA()) -> #N/A | CE19: =IF(AND(ISNUMBER(Radar_Mosca!$F19),ISNUMBER(Radar_Mosca!$S19)),IF(AND(Radar_Mosca!$F19=CE$4,Radar_Mosca!$AA19=CE$3),Radar_Mosca!$S19,NA()),NA()) -> #N/A | CF19: =IF(AND(ISNUMBER(Radar_Mosca!$F19),ISNUMBER(Radar_Mosca!$S19)),IF(AND(Radar_Mosca!$F19=CF$4,Radar_Mosca!$AA19=CF$3),Radar_Mosca!$S19,NA()),NA()) -> #N/A | ... DN19: =IF(AND(ISNUMBER(Radar_Mosca!$F19),ISNUMBER(Radar_Mosca!$S19)),IF(AND(Radar_Mosca!$F19=DN$4,Radar_Mosca!$AA19=DN$3),Radar_Mosca!$S19,NA()),NA()) -> #N/A | DO19: =IF(ISNUMBER(Radar_Mosca!$R19),Radar_Mosca!$R19,NA()) -> #N/A | DP19: =IF(Radar_Mosca!$A19="","",MID(Radar_Mosca!$A19,5,3)&IF(Radar_Mosca!$T19="Sì"," ◆","")) | DQ19: =IF(ISNUMBER(Radar_Mosca!$S19),Radar_Mosca!$S19,NA()) -> #N/A
J20: =INDEX(posID,3)&"" -> NFR-03 | K20: =IF(J20="","",INDEX(posNome,3)&IF(INDEX(ANA_Attenzione_Supervisore,3)="Sì"," ◆","")) -> Greenwashing nella commercializzazione di prodotti ESG | T20: =IF(Radar_Mosca!$AA$20="Attivazione",Radar_Mosca!$A$20,"") | BH20: =2*PI()*15/72 -> 1.3089969 | BI20: =2*SIN($BH20) -> 1.9318517 | BJ20: =2*COS($BH20) -> 0.51763809 | BK20: =3*SIN($BH20) -> 2.8977775 | BL20: =3*COS($BH20) -> 0.77645714 | BM20: =4*SIN($BH20) -> 3.8637033 | BN20: =4*COS($BH20) -> 1.0352762 | BO20: =5*SIN($BH20) -> 4.8296291 | BP20: =5*COS($BH20) -> 1.2940952 | BY20: =IF(AND(ISNUMBER(Radar_Mosca!$F20),ISNUMBER(Radar_Mosca!$S20)),IF(AND(Radar_Mosca!$F20=BY$4,Radar_Mosca!$AA20=BY$3),Radar_Mosca!$S20,NA()),NA()) -> #N/A | BZ20: =IF(AND(ISNUMBER(Radar_Mosca!$F20),ISNUMBER(Radar_Mosca!$S20)),IF(AND(Radar_Mosca!$F20=BZ$4,Radar_Mosca!$AA20=BZ$3),Radar_Mosca!$S20,NA()),NA()) -> #N/A | CA20: =IF(AND(ISNUMBER(Radar_Mosca!$F20),ISNUMBER(Radar_Mosca!$S20)),IF(AND(Radar_Mosca!$F20=CA$4,Radar_Mosca!$AA20=CA$3),Radar_Mosca!$S20,NA()),NA()) -> #N/A | CB20: =IF(AND(ISNUMBER(Radar_Mosca!$F20),ISNUMBER(Radar_Mosca!$S20)),IF(AND(Radar_Mosca!$F20=CB$4,Radar_Mosca!$AA20=CB$3),Radar_Mosca!$S20,NA()),NA()) -> #N/A | CC20: =IF(AND(ISNUMBER(Radar_Mosca!$F20),ISNUMBER(Radar_Mosca!$S20)),IF(AND(Radar_Mosca!$F20=CC$4,Radar_Mosca!$AA20=CC$3),Radar_Mosca!$S20,NA()),NA()) -> #N/A | CD20: =IF(AND(ISNUMBER(Radar_Mosca!$F20),ISNUMBER(Radar_Mosca!$S20)),IF(AND(Radar_Mosca!$F20=CD$4,Radar_Mosca!$AA20=CD$3),Radar_Mosca!$S20,NA()),NA()) -> #N/A | CE20: =IF(AND(ISNUMBER(Radar_Mosca!$F20),ISNUMBER(Radar_Mosca!$S20)),IF(AND(Radar_Mosca!$F20=CE$4,Radar_Mosca!$AA20=CE$3),Radar_Mosca!$S20,NA()),NA()) -> #N/A | CF20: =IF(AND(ISNUMBER(Radar_Mosca!$F20),ISNUMBER(Radar_Mosca!$S20)),IF(AND(Radar_Mosca!$F20=CF$4,Radar_Mosca!$AA20=CF$3),Radar_Mosca!$S20,NA()),NA()) -> #N/A | ... DN20: =IF(AND(ISNUMBER(Radar_Mosca!$F20),ISNUMBER(Radar_Mosca!$S20)),IF(AND(Radar_Mosca!$F20=DN$4,Radar_Mosca!$AA20=DN$3),Radar_Mosca!$S20,NA()),NA()) -> #N/A | DO20: =IF(ISNUMBER(Radar_Mosca!$R20),Radar_Mosca!$R20,NA()) -> #N/A | DP20: =IF(Radar_Mosca!$A20="","",MID(Radar_Mosca!$A20,5,3)&IF(Radar_Mosca!$T20="Sì"," ◆","")) | DQ20: =IF(ISNUMBER(Radar_Mosca!$S20),Radar_Mosca!$S20,NA()) -> #N/A
J21: =INDEX(posID,4)&"" -> NFR-04 | K21: =IF(J21="","",INDEX(posNome,4)&IF(INDEX(ANA_Attenzione_Supervisore,4)="Sì"," ◆","")) -> Eventi climatici estremi su sedi e data center | T21: =IF(Radar_Mosca!$AA$21="Attivazione",Radar_Mosca!$A$21,"") | BH21: =2*PI()*16/72 -> 1.3962634 | BI21: =2*SIN($BH21) -> 1.9696155 | BJ21: =2*COS($BH21) -> 0.34729636 | BK21: =3*SIN($BH21) -> 2.9544233 | BL21: =3*COS($BH21) -> 0.52094453 | BM21: =4*SIN($BH21) -> 3.939231 | BN21: =4*COS($BH21) -> 0.69459271 | BO21: =5*SIN($BH21) -> 4.9240388 | BP21: =5*COS($BH21) -> 0.86824089 | BY21: =IF(AND(ISNUMBER(Radar_Mosca!$F21),ISNUMBER(Radar_Mosca!$S21)),IF(AND(Radar_Mosca!$F21=BY$4,Radar_Mosca!$AA21=BY$3),Radar_Mosca!$S21,NA()),NA()) -> #N/A | BZ21: =IF(AND(ISNUMBER(Radar_Mosca!$F21),ISNUMBER(Radar_Mosca!$S21)),IF(AND(Radar_Mosca!$F21=BZ$4,Radar_Mosca!$AA21=BZ$3),Radar_Mosca!$S21,NA()),NA()) -> #N/A | CA21: =IF(AND(ISNUMBER(Radar_Mosca!$F21),ISNUMBER(Radar_Mosca!$S21)),IF(AND(Radar_Mosca!$F21=CA$4,Radar_Mosca!$AA21=CA$3),Radar_Mosca!$S21,NA()),NA()) -> #N/A | CB21: =IF(AND(ISNUMBER(Radar_Mosca!$F21),ISNUMBER(Radar_Mosca!$S21)),IF(AND(Radar_Mosca!$F21=CB$4,Radar_Mosca!$AA21=CB$3),Radar_Mosca!$S21,NA()),NA()) -> #N/A | CC21: =IF(AND(ISNUMBER(Radar_Mosca!$F21),ISNUMBER(Radar_Mosca!$S21)),IF(AND(Radar_Mosca!$F21=CC$4,Radar_Mosca!$AA21=CC$3),Radar_Mosca!$S21,NA()),NA()) -> #N/A | CD21: =IF(AND(ISNUMBER(Radar_Mosca!$F21),ISNUMBER(Radar_Mosca!$S21)),IF(AND(Radar_Mosca!$F21=CD$4,Radar_Mosca!$AA21=CD$3),Radar_Mosca!$S21,NA()),NA()) -> #N/A | CE21: =IF(AND(ISNUMBER(Radar_Mosca!$F21),ISNUMBER(Radar_Mosca!$S21)),IF(AND(Radar_Mosca!$F21=CE$4,Radar_Mosca!$AA21=CE$3),Radar_Mosca!$S21,NA()),NA()) -> #N/A | CF21: =IF(AND(ISNUMBER(Radar_Mosca!$F21),ISNUMBER(Radar_Mosca!$S21)),IF(AND(Radar_Mosca!$F21=CF$4,Radar_Mosca!$AA21=CF$3),Radar_Mosca!$S21,NA()),NA()) -> #N/A | ... DN21: =IF(AND(ISNUMBER(Radar_Mosca!$F21),ISNUMBER(Radar_Mosca!$S21)),IF(AND(Radar_Mosca!$F21=DN$4,Radar_Mosca!$AA21=DN$3),Radar_Mosca!$S21,NA()),NA()) -> #N/A | DO21: =IF(ISNUMBER(Radar_Mosca!$R21),Radar_Mosca!$R21,NA()) -> #N/A | DP21: =IF(Radar_Mosca!$A21="","",MID(Radar_Mosca!$A21,5,3)&IF(Radar_Mosca!$T21="Sì"," ◆","")) | DQ21: =IF(ISNUMBER(Radar_Mosca!$S21),Radar_Mosca!$S21,NA()) -> #N/A
J22: =INDEX(posID,5)&"" -> NFR-05 | K22: =IF(J22="","",INDEX(posNome,5)&IF(INDEX(ANA_Attenzione_Supervisore,5)="Sì"," ◆","")) -> Errori di processo nella migrazione del core banking | T22: =IF(Radar_Mosca!$AA$22="Attivazione",Radar_Mosca!$A$22,"") | BH22: =2*PI()*17/72 -> 1.4835299 | BI22: =2*SIN($BH22) -> 1.9923894 | BJ22: =2*COS($BH22) -> 0.17431149 | BK22: =3*SIN($BH22) -> 2.9885841 | BL22: =3*COS($BH22) -> 0.26146723 | BM22: =4*SIN($BH22) -> 3.9847788 | BN22: =4*COS($BH22) -> 0.34862297 | BO22: =5*SIN($BH22) -> 4.9809735 | BP22: =5*COS($BH22) -> 0.43577871 | BY22: =IF(AND(ISNUMBER(Radar_Mosca!$F22),ISNUMBER(Radar_Mosca!$S22)),IF(AND(Radar_Mosca!$F22=BY$4,Radar_Mosca!$AA22=BY$3),Radar_Mosca!$S22,NA()),NA()) -> #N/A | BZ22: =IF(AND(ISNUMBER(Radar_Mosca!$F22),ISNUMBER(Radar_Mosca!$S22)),IF(AND(Radar_Mosca!$F22=BZ$4,Radar_Mosca!$AA22=BZ$3),Radar_Mosca!$S22,NA()),NA()) -> #N/A | CA22: =IF(AND(ISNUMBER(Radar_Mosca!$F22),ISNUMBER(Radar_Mosca!$S22)),IF(AND(Radar_Mosca!$F22=CA$4,Radar_Mosca!$AA22=CA$3),Radar_Mosca!$S22,NA()),NA()) -> #N/A | CB22: =IF(AND(ISNUMBER(Radar_Mosca!$F22),ISNUMBER(Radar_Mosca!$S22)),IF(AND(Radar_Mosca!$F22=CB$4,Radar_Mosca!$AA22=CB$3),Radar_Mosca!$S22,NA()),NA()) -> #N/A | CC22: =IF(AND(ISNUMBER(Radar_Mosca!$F22),ISNUMBER(Radar_Mosca!$S22)),IF(AND(Radar_Mosca!$F22=CC$4,Radar_Mosca!$AA22=CC$3),Radar_Mosca!$S22,NA()),NA()) -> #N/A | CD22: =IF(AND(ISNUMBER(Radar_Mosca!$F22),ISNUMBER(Radar_Mosca!$S22)),IF(AND(Radar_Mosca!$F22=CD$4,Radar_Mosca!$AA22=CD$3),Radar_Mosca!$S22,NA()),NA()) -> #N/A | CE22: =IF(AND(ISNUMBER(Radar_Mosca!$F22),ISNUMBER(Radar_Mosca!$S22)),IF(AND(Radar_Mosca!$F22=CE$4,Radar_Mosca!$AA22=CE$3),Radar_Mosca!$S22,NA()),NA()) -> #N/A | CF22: =IF(AND(ISNUMBER(Radar_Mosca!$F22),ISNUMBER(Radar_Mosca!$S22)),IF(AND(Radar_Mosca!$F22=CF$4,Radar_Mosca!$AA22=CF$3),Radar_Mosca!$S22,NA()),NA()) -> #N/A | ... DN22: =IF(AND(ISNUMBER(Radar_Mosca!$F22),ISNUMBER(Radar_Mosca!$S22)),IF(AND(Radar_Mosca!$F22=DN$4,Radar_Mosca!$AA22=DN$3),Radar_Mosca!$S22,NA()),NA()) -> #N/A | DO22: =IF(ISNUMBER(Radar_Mosca!$R22),Radar_Mosca!$R22,NA()) -> #N/A | DP22: =IF(Radar_Mosca!$A22="","",MID(Radar_Mosca!$A22,5,3)&IF(Radar_Mosca!$T22="Sì"," ◆","")) | DQ22: =IF(ISNUMBER(Radar_Mosca!$S22),Radar_Mosca!$S22,NA()) -> #N/A
J23: =INDEX(posID,6)&"" -> NFR-06 | K23: =IF(J23="","",INDEX(posNome,6)&IF(INDEX(ANA_Attenzione_Supervisore,6)="Sì"," ◆","")) -> Esfiltrazione di dati tramite strumenti di AI non autorizzati | T23: =IF(Radar_Mosca!$AA$23="Attivazione",Radar_Mosca!$A$23,"") | BH23: =2*PI()*18/72 -> 1.5707963 | BI23: =2*SIN($BH23) -> 2 | BJ23: =2*COS($BH23) -> 1.2251485e-16 | BK23: =3*SIN($BH23) -> 3 | BL23: =3*COS($BH23) -> 1.8377227e-16 | BM23: =4*SIN($BH23) -> 4 | BN23: =4*COS($BH23) -> 2.4502969e-16 | BO23: =5*SIN($BH23) -> 5 | BP23: =5*COS($BH23) -> 3.0628711e-16 | BY23: =IF(AND(ISNUMBER(Radar_Mosca!$F23),ISNUMBER(Radar_Mosca!$S23)),IF(AND(Radar_Mosca!$F23=BY$4,Radar_Mosca!$AA23=BY$3),Radar_Mosca!$S23,NA()),NA()) -> #N/A | BZ23: =IF(AND(ISNUMBER(Radar_Mosca!$F23),ISNUMBER(Radar_Mosca!$S23)),IF(AND(Radar_Mosca!$F23=BZ$4,Radar_Mosca!$AA23=BZ$3),Radar_Mosca!$S23,NA()),NA()) -> #N/A | CA23: =IF(AND(ISNUMBER(Radar_Mosca!$F23),ISNUMBER(Radar_Mosca!$S23)),IF(AND(Radar_Mosca!$F23=CA$4,Radar_Mosca!$AA23=CA$3),Radar_Mosca!$S23,NA()),NA()) -> #N/A | CB23: =IF(AND(ISNUMBER(Radar_Mosca!$F23),ISNUMBER(Radar_Mosca!$S23)),IF(AND(Radar_Mosca!$F23=CB$4,Radar_Mosca!$AA23=CB$3),Radar_Mosca!$S23,NA()),NA()) -> #N/A | CC23: =IF(AND(ISNUMBER(Radar_Mosca!$F23),ISNUMBER(Radar_Mosca!$S23)),IF(AND(Radar_Mosca!$F23=CC$4,Radar_Mosca!$AA23=CC$3),Radar_Mosca!$S23,NA()),NA()) -> #N/A | CD23: =IF(AND(ISNUMBER(Radar_Mosca!$F23),ISNUMBER(Radar_Mosca!$S23)),IF(AND(Radar_Mosca!$F23=CD$4,Radar_Mosca!$AA23=CD$3),Radar_Mosca!$S23,NA()),NA()) -> #N/A | CE23: =IF(AND(ISNUMBER(Radar_Mosca!$F23),ISNUMBER(Radar_Mosca!$S23)),IF(AND(Radar_Mosca!$F23=CE$4,Radar_Mosca!$AA23=CE$3),Radar_Mosca!$S23,NA()),NA()) -> #N/A | CF23: =IF(AND(ISNUMBER(Radar_Mosca!$F23),ISNUMBER(Radar_Mosca!$S23)),IF(AND(Radar_Mosca!$F23=CF$4,Radar_Mosca!$AA23=CF$3),Radar_Mosca!$S23,NA()),NA()) -> #N/A | ... DN23: =IF(AND(ISNUMBER(Radar_Mosca!$F23),ISNUMBER(Radar_Mosca!$S23)),IF(AND(Radar_Mosca!$F23=DN$4,Radar_Mosca!$AA23=DN$3),Radar_Mosca!$S23,NA()),NA()) -> #N/A | DO23: =IF(ISNUMBER(Radar_Mosca!$R23),Radar_Mosca!$R23,NA()) -> #N/A | DP23: =IF(Radar_Mosca!$A23="","",MID(Radar_Mosca!$A23,5,3)&IF(Radar_Mosca!$T23="Sì"," ◆","")) | DQ23: =IF(ISNUMBER(Radar_Mosca!$S23),Radar_Mosca!$S23,NA()) -> #N/A
