Workbook
Name ANA_Driver: Parametri!$K$4:$K$18
Name ANA_Event_Type: Parametri!$J$4:$J$18
Name ANA_ID: Parametri!$H$4:$H$18
Name ANA_Nome: Parametri!$I$4:$I$18
Name ANA_Owner: Parametri!$L$4:$L$18
Name anagrafica: Parametri!$H$4:$L$18
Name anniProssimita: Parametri!$B$51:$B$55
Name AZ_Ciclo: Azioni!$A$2:$A$20003
Name AZ_Data_Decisione: Azioni!$K$2:$K$20003
Name AZ_Decisa_Da: Azioni!$L$2:$L$20003
Name AZ_Descrizione: Azioni!$D$2:$D$20003
Name AZ_Dimensione: Azioni!$F$2:$F$20003
Name AZ_ID_Azione: Azioni!$C$2:$C$20003
Name AZ_ID_Rischio: Azioni!$B$2:$B$20003
Name AZ_Mesi_Orizzonte: Azioni!$H$2:$H$20003
Name AZ_Orizzonte: Azioni!$G$2:$G$20003
Name AZ_Owner: Azioni!$E$2:$E$20003
Name AZ_Razionale: Azioni!$I$2:$I$20003
Name AZ_Stato: Azioni!$J$2:$J$20003
Name AZ_Validazione: Azioni!$M$2:$M$20003
Name capienzaElencoKRI: 150
Name capienzaKRICorrenti: 60
Name cicliTrend: Parametri!$B$20:$B$27
Name cicloCorrente: Parametri!$B$15
Name cicloMeno2: Parametri!$B$17
Name cicloPrecedente: Parametri!$B$16
Name codiciL1: Parametri!$E$4:$E$10
Name elencoKRI: OFFSET(Andamento_KRI!$L$12,0,0,MAX(1,COUNTIF(Andamento_KRI!$L$12:$L$161,"?*")),1)
Name inizioFinestra4: Parametri!$B$31
Name KRI_Chiave: KRI!$R$2:$R$19937
Name KRI_Ciclo: KRI!$A$2:$A$19937
Name KRI_Ciclo_Aggiornamento: KRI!$P$2:$P$19937
Name KRI_Ciclo_Definizione: KRI!$O$2:$O$19937
Name KRI_Data_Rilevazione: KRI!$J$2:$J$19937
Name KRI_Fonte_Dati: KRI!$F$2:$F$19937
Name KRI_Fonte_Rilevazione: KRI!$K$2:$K$19937
Name KRI_ID_Rischio: KRI!$C$2:$C$19937
Name KRI_In_Vigore: KRI!$N$2:$N$19937
Name KRI_KRI_ID: KRI!$B$2:$B$19937
Name KRI_Nome: KRI!$D$2:$D$19937
Name KRI_Nota_Rilevazione: KRI!$L$2:$L$19937
Name KRI_Razionale: KRI!$Q$2:$Q$19937
Name KRI_Soglia_Allerta: KRI!$H$2:$H$19937
Name KRI_Soglia_Attenzione: KRI!$G$2:$G$19937
Name KRI_Stato: KRI!$M$2:$M$19937
Name KRI_Unita: KRI!$E$2:$E$19937
Name KRI_Validazione: KRI!$S$2:$S$19937
Name KRI_Valore_Corrente: KRI!$I$2:$I$19937
Name moscaX: Parametri!$B$48
Name moscaYDefault: Parametri!$B$49
Name NW_Codice_Fonte: NewsLog!$F$2:$F$19995
Name NW_Data: NewsLog!$A$2:$A$19995
Name NW_Fonte: NewsLog!$E$2:$E$19995
Name NW_ID_Notizia: NewsLog!$C$2:$C$19995
Name NW_Imp_L1_01: NewsLog!$I$2:$I$19995
Name NW_Imp_L1_02: NewsLog!$J$2:$J$19995
Name NW_Imp_L1_03: NewsLog!$K$2:$K$19995
Name NW_Imp_L1_04: NewsLog!$L$2:$L$19995
Name NW_Imp_L1_05: NewsLog!$M$2:$M$19995
Name NW_Imp_L1_06: NewsLog!$N$2:$N$19995

Sheet Leggimi
A1: Registro NFR emergenti — come si usa questo workbook
A4: CHE COSA TROVI E DOVE
A5: Dashboard: situazione del ciclo (radar, badge settimanali, controllo di copertura riga 10, stato della validazione riga 8).
A6: Radar_Mosca: quanto presto bisogna agire su ogni rischio (vicino al centro = subito) e quanto e' grande (area del cerchio).
A7: Validazione: le proposte degli agenti da accettare, correggere o respingere. E' L'UNICO FOGLIO IN CUI SI SCRIVE A MANO.
A8: Trend, Delta, Approfondimento, KRI_Correnti, Andamento_KRI, Analisi_News: viste di sola lettura, si aggiornano da sole.
A9: RiskRegister, Azioni, KRI, NewsLog: i dati. Li scrive solo lo script: NON modificarli a mano.
A10: Parametri: pesi, soglie, parametri dell'urgenza (celle gialle, da cambiare solo se deciso dalla funzione di rischio).
A12: COSA FARE, IN BREVE (la guida completa e' 00_GUIDA_PASSO_PASSO.md nel pacchetto)
A13: Ogni lunedi': lo script raccoglie le notizie, l'agente A3 le valuta, lo script le scrive qui (comando settimanale).
A14: Ogni trimestre: lo script esporta la baseline, A1 valuta i rischi, A5 li controlla, lo script scrive qui (comando trimestrale).
A15: Dopo ogni trimestre: il validatore apre il foglio Validazione, decide, salva e CHIUDE il file, poi lancia il comando valida.
... A34: Generato da 03_Excel/genera_dashboard.py. Per rifarlo a mano: 03_Excel/costruzione_manuale_template.md.

Sheet Dashboard
A1: Dashboard — registro NFR emergenti
A2: Livello VISTA: solo formule. Si aggiorna da solo quando la scrittura aggiunge righe ai dati.
A3: Ciclo corrente | B3: =cicloCorrente -> 2026Q3 | C3: Precedente | D3: =cicloPrecedente -> 2026Q2 | E3: Due cicli prima | F3: =cicloMeno2 -> 2026Q1
A5: Score composito 1-5 (5 = peggiore), calcolato dal foglio con i pesi di Parametri. #N/A = non valutato.
A6: Badge: segnali netti delle ultime 4 settimane rispetto alla soglia di direzione. Non modifica score.
A8: VALIDAZIONE DEL CICLO | B8: Decisioni da prendere | C8: =COUNTIFS(VAL_Periodo,cicloCorrente,VAL_Stato,"Da decidere") -> 0 | D8: Rettifiche applicate | E8: =COUNTIFS(VAL_Periodo,cicloCorrente,VAL_Decisione,"Rettificato",VAL_Stato,"Applicata") -> 2 | F8: =IF(C8>0,"CICLO NON ANCORA VALIDATO — vedi foglio Validazione","Ciclo validato") -> Ciclo validato
A10: CONTROLLO DI COPERTURA | B10: Rischi in anagrafica | C10: =COUNTIF(ANA_ID,"NFR-*") -> 12 | D10: Valutati nel ciclo | E10: =SUMPRODUCT((ANA_ID<>"")*(COUNTIFS(RR_ID_Rischio,ANA_ID,RR_Ciclo,cicloCorrente)>0)) -> 12 | F10: =IF(C10=E10,"Ciclo completo","CICLO INCOMPLETO — i rischi mancanti non sono valutazioni") -> Ciclo completo
A12: ID | B12: Nome | C12: Severity | D12: Velocity | E12: Prossimita' | F12: Gap_Controlli | G12: Score corrente | H12: Score precedente | I12: Score 2 cicli fa | J12: Confidence | K12: Segnali netti 4 sett. | L12: Badge
A13: =IF(Parametri!$H4="","",Parametri!$H4) -> NFR-01 | B13: =IF($A13="","",Parametri!$I4) -> Frodi su pagamenti istantanei abilitate da AI generativa | C13: =IF($A13="",NA(),IF(COUNTIFS(RR_ID_Rischio,$A13,RR_Ciclo,cicloCorrente)=0,NA(),SUMIFS(RR_Severity,RR_ID_Rischio,$A13,RR_Ciclo,cicloCorrente))) -> 4 | D13: =IF($A13="",NA(),IF(COUNTIFS(RR_ID_Rischio,$A13,RR_Ciclo,cicloCorrente)=0,NA(),SUMIFS(RR_Velocity,RR_ID_Rischio,$A13,RR_Ciclo,cicloCorrente))) -> 4 | E13: =IF($A13="",NA(),IF(COUNTIFS(RR_ID_Rischio,$A13,RR_Ciclo,cicloCorrente)=0,NA(),SUMIFS(RR_Prossimita,RR_ID_Rischio,$A13,RR_Ciclo,cicloCorrente))) -> 4 | F13: =IF($A13="",NA(),IF(COUNTIFS(RR_ID_Rischio,$A13,RR_Ciclo,cicloCorrente)=0,NA(),SUMIFS(RR_Gap_Controlli,RR_ID_Rischio,$A13,RR_Ciclo,cicloCorrente))) -> 3 | G13: =IF($A13="",NA(),IF(COUNTIFS(RR_ID_Rischio,$A13,RR_Ciclo,cicloCorrente)=0,NA(),SUMIFS(RR_Score_Composito,RR_ID_Rischio,$A13,RR_Ciclo,cicloCorrente))) -> 3.8 | H13: =IF($A13="",NA(),IF(COUNTIFS(RR_ID_Rischio,$A13,RR_Ciclo,cicloPrecedente)=0,NA(),SUMIFS(RR_Score_Composito,RR_ID_Rischio,$A13,RR_Ciclo,cicloPrecedente))) -> #N/A | I13: =IF($A13="",NA(),IF(COUNTIFS(RR_ID_Rischio,$A13,RR_Ciclo,cicloMeno2)=0,NA(),SUMIFS(RR_Score_Composito,RR_ID_Rischio,$A13,RR_Ciclo,cicloMeno2))) -> #N/A | J13: =IF($A13="",NA(),IF(COUNTIFS(RR_ID_Rischio,$A13,RR_Ciclo,cicloCorrente)=0,NA(),SUMIFS(RR_Confidence,RR_ID_Rischio,$A13,RR_Ciclo,cicloCorrente))) -> 4 | K13: =IF($A13="","",COUNTIFS(NW_Rischio_ID,$A13,NW_Segnale,"Peggiorativo",NW_Settimana,">="&inizioFinestra4,NW_Settimana,"<="&settimanaCorrente)-COUNTIFS(NW_Rischio_ID,$A13,NW_Segnale,"Migliorativo",NW_Settimana,">="&inizioFinestra4,NW_Settimana,"<="&settimanaCorrente)) -> 0 | L13: =IF($A13="","",IF(K13>=sogliaDirezione,"▲ In peggioramento",IF(K13<=-sogliaDirezione,"▼ In miglioramento","● Stabile"))) -> ● Stabile
A14: =IF(Parametri!$H5="","",Parametri!$H5) -> NFR-02 | B14: =IF($A14="","",Parametri!$I5) -> Concentrazione su un fornitore cloud critico | C14: =IF($A14="",NA(),IF(COUNTIFS(RR_ID_Rischio,$A14,RR_Ciclo,cicloCorrente)=0,NA(),SUMIFS(RR_Severity,RR_ID_Rischio,$A14,RR_Ciclo,cicloCorrente))) -> 4 | D14: =IF($A14="",NA(),IF(COUNTIFS(RR_ID_Rischio,$A14,RR_Ciclo,cicloCorrente)=0,NA(),SUMIFS(RR_Velocity,RR_ID_Rischio,$A14,RR_Ciclo,cicloCorrente))) -> 4 | E14: =IF($A14="",NA(),IF(COUNTIFS(RR_ID_Rischio,$A14,RR_Ciclo,cicloCorrente)=0,NA(),SUMIFS(RR_Prossimita,RR_ID_Rischio,$A14,RR_Ciclo,cicloCorrente))) -> 3 | F14: =IF($A14="",NA(),IF(COUNTIFS(RR_ID_Rischio,$A14,RR_Ciclo,cicloCorrente)=0,NA(),SUMIFS(RR_Gap_Controlli,RR_ID_Rischio,$A14,RR_Ciclo,cicloCorrente))) -> 3 | G14: =IF($A14="",NA(),IF(COUNTIFS(RR_ID_Rischio,$A14,RR_Ciclo,cicloCorrente)=0,NA(),SUMIFS(RR_Score_Composito,RR_ID_Rischio,$A14,RR_Ciclo,cicloCorrente))) -> 3.6 | H14: =IF($A14="",NA(),IF(COUNTIFS(RR_ID_Rischio,$A14,RR_Ciclo,cicloPrecedente)=0,NA(),SUMIFS(RR_Score_Composito,RR_ID_Rischio,$A14,RR_Ciclo,cicloPrecedente))) -> #N/A | I14: =IF($A14="",NA(),IF(COUNTIFS(RR_ID_Rischio,$A14,RR_Ciclo,cicloMeno2)=0,NA(),SUMIFS(RR_Score_Composito,RR_ID_Rischio,$A14,RR_Ciclo,cicloMeno2))) -> #N/A | J14: =IF($A14="",NA(),IF(COUNTIFS(RR_ID_Rischio,$A14,RR_Ciclo,cicloCorrente)=0,NA(),SUMIFS(RR_Confidence,RR_ID_Rischio,$A14,RR_Ciclo,cicloCorrente))) -> 4 | K14: =IF($A14="","",COUNTIFS(NW_Rischio_ID,$A14,NW_Segnale,"Peggiorativo",NW_Settimana,">="&inizioFinestra4,NW_Settimana,"<="&settimanaCorrente)-COUNTIFS(NW_Rischio_ID,$A14,NW_Segnale,"Migliorativo",NW_Settimana,">="&inizioFinestra4,NW_Settimana,"<="&settimanaCorrente)) -> 0 | L14: =IF($A14="","",IF(K14>=sogliaDirezione,"▲ In peggioramento",IF(K14<=-sogliaDirezione,"▼ In miglioramento","● Stabile"))) -> ● Stabile
A15: =IF(Parametri!$H6="","",Parametri!$H6) -> NFR-03 | B15: =IF($A15="","",Parametri!$I6) -> Greenwashing nella commercializzazione di prodotti ESG | C15: =IF($A15="",NA(),IF(COUNTIFS(RR_ID_Rischio,$A15,RR_Ciclo,cicloCorrente)=0,NA(),SUMIFS(RR_Severity,RR_ID_Rischio,$A15,RR_Ciclo,cicloCorrente))) -> 3 | D15: =IF($A15="",NA(),IF(COUNTIFS(RR_ID_Rischio,$A15,RR_Ciclo,cicloCorrente)=0,NA(),SUMIFS(RR_Velocity,RR_ID_Rischio,$A15,RR_Ciclo,cicloCorrente))) -> 2 | E15: =IF($A15="",NA(),IF(COUNTIFS(RR_ID_Rischio,$A15,RR_Ciclo,cicloCorrente)=0,NA(),SUMIFS(RR_Prossimita,RR_ID_Rischio,$A15,RR_Ciclo,cicloCorrente))) -> 4 | F15: =IF($A15="",NA(),IF(COUNTIFS(RR_ID_Rischio,$A15,RR_Ciclo,cicloCorrente)=0,NA(),SUMIFS(RR_Gap_Controlli,RR_ID_Rischio,$A15,RR_Ciclo,cicloCorrente))) -> 3 | G15: =IF($A15="",NA(),IF(COUNTIFS(RR_ID_Rischio,$A15,RR_Ciclo,cicloCorrente)=0,NA(),SUMIFS(RR_Score_Composito,RR_ID_Rischio,$A15,RR_Ciclo,cicloCorrente))) -> 3 | H15: =IF($A15="",NA(),IF(COUNTIFS(RR_ID_Rischio,$A15,RR_Ciclo,cicloPrecedente)=0,NA(),SUMIFS(RR_Score_Composito,RR_ID_Rischio,$A15,RR_Ciclo,cicloPrecedente))) -> #N/A | I15: =IF($A15="",NA(),IF(COUNTIFS(RR_ID_Rischio,$A15,RR_Ciclo,cicloMeno2)=0,NA(),SUMIFS(RR_Score_Composito,RR_ID_Rischio,$A15,RR_Ciclo,cicloMeno2))) -> #N/A | J15: =IF($A15="",NA(),IF(COUNTIFS(RR_ID_Rischio,$A15,RR_Ciclo,cicloCorrente)=0,NA(),SUMIFS(RR_Confidence,RR_ID_Rischio,$A15,RR_Ciclo,cicloCorrente))) -> 3 | K15: =IF($A15="","",COUNTIFS(NW_Rischio_ID,$A15,NW_Segnale,"Peggiorativo",NW_Settimana,">="&inizioFinestra4,NW_Settimana,"<="&settimanaCorrente)-COUNTIFS(NW_Rischio_ID,$A15,NW_Segnale,"Migliorativo",NW_Settimana,">="&inizioFinestra4,NW_Settimana,"<="&settimanaCorrente)) -> 0 | L15: =IF($A15="","",IF(K15>=sogliaDirezione,"▲ In peggioramento",IF(K15<=-sogliaDirezione,"▼ In miglioramento","● Stabile"))) -> ● Stabile
A16: =IF(Parametri!$H7="","",Parametri!$H7) -> NFR-04 | B16: =IF($A16="","",Parametri!$I7) -> Eventi climatici estremi su sedi e data center | C16: =IF($A16="",NA(),IF(COUNTIFS(RR_ID_Rischio,$A16,RR_Ciclo,cicloCorrente)=0,NA(),SUMIFS(RR_Severity,RR_ID_Rischio,$A16,RR_Ciclo,cicloCorrente))) -> 3 | D16: =IF($A16="",NA(),IF(COUNTIFS(RR_ID_Rischio,$A16,RR_Ciclo,cicloCorrente)=0,NA(),SUMIFS(RR_Velocity,RR_ID_Rischio,$A16,RR_Ciclo,cicloCorrente))) -> 2 | E16: =IF($A16="",NA(),IF(COUNTIFS(RR_ID_Rischio,$A16,RR_Ciclo,cicloCorrente)=0,NA(),SUMIFS(RR_Prossimita,RR_ID_Rischio,$A16,RR_Ciclo,cicloCorrente))) -> 3 | F16: =IF($A16="",NA(),IF(COUNTIFS(RR_ID_Rischio,$A16,RR_Ciclo,cicloCorrente)=0,NA(),SUMIFS(RR_Gap_Controlli,RR_ID_Rischio,$A16,RR_Ciclo,cicloCorrente))) -> 3 | G16: =IF($A16="",NA(),IF(COUNTIFS(RR_ID_Rischio,$A16,RR_Ciclo,cicloCorrente)=0,NA(),SUMIFS(RR_Score_Composito,RR_ID_Rischio,$A16,RR_Ciclo,cicloCorrente))) -> 2.8 | H16: =IF($A16="",NA(),IF(COUNTIFS(RR_ID_Rischio,$A16,RR_Ciclo,cicloPrecedente)=0,NA(),SUMIFS(RR_Score_Composito,RR_ID_Rischio,$A16,RR_Ciclo,cicloPrecedente))) -> #N/A | I16: =IF($A16="",NA(),IF(COUNTIFS(RR_ID_Rischio,$A16,RR_Ciclo,cicloMeno2)=0,NA(),SUMIFS(RR_Score_Composito,RR_ID_Rischio,$A16,RR_Ciclo,cicloMeno2))) -> #N/A | J16: =IF($A16="",NA(),IF(COUNTIFS(RR_ID_Rischio,$A16,RR_Ciclo,cicloCorrente)=0,NA(),SUMIFS(RR_Confidence,RR_ID_Rischio,$A16,RR_Ciclo,cicloCorrente))) -> 3 | K16: =IF($A16="","",COUNTIFS(NW_Rischio_ID,$A16,NW_Segnale,"Peggiorativo",NW_Settimana,">="&inizioFinestra4,NW_Settimana,"<="&settimanaCorrente)-COUNTIFS(NW_Rischio_ID,$A16,NW_Segnale,"Migliorativo",NW_Settimana,">="&inizioFinestra4,NW_Settimana,"<="&settimanaCorrente)) -> 0 | L16: =IF($A16="","",IF(K16>=sogliaDirezione,"▲ In peggioramento",IF(K16<=-sogliaDirezione,"▼ In miglioramento","● Stabile"))) -> ● Stabile
A17: =IF(Parametri!$H8="","",Parametri!$H8) -> NFR-05 | B17: =IF($A17="","",Parametri!$I8) -> Errori di processo nella migrazione del core banking | C17: =IF($A17="",NA(),IF(COUNTIFS(RR_ID_Rischio,$A17,RR_Ciclo,cicloCorrente)=0,NA(),SUMIFS(RR_Severity,RR_ID_Rischio,$A17,RR_Ciclo,cicloCorrente))) -> 3 | D17: =IF($A17="",NA(),IF(COUNTIFS(RR_ID_Rischio,$A17,RR_Ciclo,cicloCorrente)=0,NA(),SUMIFS(RR_Velocity,RR_ID_Rischio,$A17,RR_Ciclo,cicloCorrente))) -> 3 | E17: =IF($A17="",NA(),IF(COUNTIFS(RR_ID_Rischio,$A17,RR_Ciclo,cicloCorrente)=0,NA(),SUMIFS(RR_Prossimita,RR_ID_Rischio,$A17,RR_Ciclo,cicloCorrente))) -> 3 | F17: =IF($A17="",NA(),IF(COUNTIFS(RR_ID_Rischio,$A17,RR_Ciclo,cicloCorrente)=0,NA(),SUMIFS(RR_Gap_Controlli,RR_ID_Rischio,$A17,RR_Ciclo,cicloCorrente))) -> 3 | G17: =IF($A17="",NA(),IF(COUNTIFS(RR_ID_Rischio,$A17,RR_Ciclo,cicloCorrente)=0,NA(),SUMIFS(RR_Score_Composito,RR_ID_Rischio,$A17,RR_Ciclo,cicloCorrente))) -> 3 | H17: =IF($A17="",NA(),IF(COUNTIFS(RR_ID_Rischio,$A17,RR_Ciclo,cicloPrecedente)=0,NA(),SUMIFS(RR_Score_Composito,RR_ID_Rischio,$A17,RR_Ciclo,cicloPrecedente))) -> #N/A | I17: =IF($A17="",NA(),IF(COUNTIFS(RR_ID_Rischio,$A17,RR_Ciclo,cicloMeno2)=0,NA(),SUMIFS(RR_Score_Composito,RR_ID_Rischio,$A17,RR_Ciclo,cicloMeno2))) -> #N/A | J17: =IF($A17="",NA(),IF(COUNTIFS(RR_ID_Rischio,$A17,RR_Ciclo,cicloCorrente)=0,NA(),SUMIFS(RR_Confidence,RR_ID_Rischio,$A17,RR_Ciclo,cicloCorrente))) -> 4 | K17: =IF($A17="","",COUNTIFS(NW_Rischio_ID,$A17,NW_Segnale,"Peggiorativo",NW_Settimana,">="&inizioFinestra4,NW_Settimana,"<="&settimanaCorrente)-COUNTIFS(NW_Rischio_ID,$A17,NW_Segnale,"Migliorativo",NW_Settimana,">="&inizioFinestra4,NW_Settimana,"<="&settimanaCorrente)) -> 0 | L17: =IF($A17="","",IF(K17>=sogliaDirezione,"▲ In peggioramento",IF(K17<=-sogliaDirezione,"▼ In miglioramento","● Stabile"))) -> ● Stabile
A18: =IF(Parametri!$H9="","",Parametri!$H9) -> NFR-06 | B18: =IF($A18="","",Parametri!$I9) -> Esfiltrazione di dati tramite strumenti di AI non autorizzati | C18: =IF($A18="",NA(),IF(COUNTIFS(RR_ID_Rischio,$A18,RR_Ciclo,cicloCorrente)=0,NA(),SUMIFS(RR_Severity,RR_ID_Rischio,$A18,RR_Ciclo,cicloCorrente))) -> 3 | D18: =IF($A18="",NA(),IF(COUNTIFS(RR_ID_Rischio,$A18,RR_Ciclo,cicloCorrente)=0,NA(),SUMIFS(RR_Velocity,RR_ID_Rischio,$A18,RR_Ciclo,cicloCorrente))) -> 3 | E18: =IF($A18="",NA(),IF(COUNTIFS(RR_ID_Rischio,$A18,RR_Ciclo,cicloCorrente)=0,NA(),SUMIFS(RR_Prossimita,RR_ID_Rischio,$A18,RR_Ciclo,cicloCorrente))) -> 3 | F18: =IF($A18="",NA(),IF(COUNTIFS(RR_ID_Rischio,$A18,RR_Ciclo,cicloCorrente)=0,NA(),SUMIFS(RR_Gap_Controlli,RR_ID_Rischio,$A18,RR_Ciclo,cicloCorrente))) -> 3 | G18: =IF($A18="",NA(),IF(COUNTIFS(RR_ID_Rischio,$A18,RR_Ciclo,cicloCorrente)=0,NA(),SUMIFS(RR_Score_Composito,RR_ID_Rischio,$A18,RR_Ciclo,cicloCorrente))) -> 3 | H18: =IF($A18="",NA(),IF(COUNTIFS(RR_ID_Rischio,$A18,RR_Ciclo,cicloPrecedente)=0,NA(),SUMIFS(RR_Score_Composito,RR_ID_Rischio,$A18,RR_Ciclo,cicloPrecedente))) -> #N/A | I18: =IF($A18="",NA(),IF(COUNTIFS(RR_ID_Rischio,$A18,RR_Ciclo,cicloMeno2)=0,NA(),SUMIFS(RR_Score_Composito,RR_ID_Rischio,$A18,RR_Ciclo,cicloMeno2))) -> #N/A | J18: =IF($A18="",NA(),IF(COUNTIFS(RR_ID_Rischio,$A18,RR_Ciclo,cicloCorrente)=0,NA(),SUMIFS(RR_Confidence,RR_ID_Rischio,$A18,RR_Ciclo,cicloCorrente))) -> 3 | K18: =IF($A18="","",COUNTIFS(NW_Rischio_ID,$A18,NW_Segnale,"Peggiorativo",NW_Settimana,">="&inizioFinestra4,NW_Settimana,"<="&settimanaCorrente)-COUNTIFS(NW_Rischio_ID,$A18,NW_Segnale,"Migliorativo",NW_Settimana,">="&inizioFinestra4,NW_Settimana,"<="&settimanaCorrente)) -> 0 | L18: =IF($A18="","",IF(K18>=sogliaDirezione,"▲ In peggioramento",IF(K18<=-sogliaDirezione,"▼ In miglioramento","● Stabile"))) -> ● Stabile
A19: =IF(Parametri!$H10="","",Parametri!$H10) -> NFR-07 | B19: =IF($A19="","",Parametri!$I10) -> Ransomware presso un fornitore di servizi di pagamento | C19: =IF($A19="",NA(),IF(COUNTIFS(RR_ID_Rischio,$A19,RR_Ciclo,cicloCorrente)=0,NA(),SUMIFS(RR_Severity,RR_ID_Rischio,$A19,RR_Ciclo,cicloCorrente))) -> 4 | D19: =IF($A19="",NA(),IF(COUNTIFS(RR_ID_Rischio,$A19,RR_Ciclo,cicloCorrente)=0,NA(),SUMIFS(RR_Velocity,RR_ID_Rischio,$A19,RR_Ciclo,cicloCorrente))) -> 5 | E19: =IF($A19="",NA(),IF(COUNTIFS(RR_ID_Rischio,$A19,RR_Ciclo,cicloCorrente)=0,NA(),SUMIFS(RR_Prossimita,RR_ID_Rischio,$A19,RR_Ciclo,cicloCorrente))) -> 3 | F19: =IF($A19="",NA(),IF(COUNTIFS(RR_ID_Rischio,$A19,RR_Ciclo,cicloCorrente)=0,NA(),SUMIFS(RR_Gap_Controlli,RR_ID_Rischio,$A19,RR_Ciclo,cicloCorrente))) -> 3 | G19: =IF($A19="",NA(),IF(COUNTIFS(RR_ID_Rischio,$A19,RR_Ciclo,cicloCorrente)=0,NA(),SUMIFS(RR_Score_Composito,RR_ID_Rischio,$A19,RR_Ciclo,cicloCorrente))) -> 3.8 | H19: =IF($A19="",NA(),IF(COUNTIFS(RR_ID_Rischio,$A19,RR_Ciclo,cicloPrecedente)=0,NA(),SUMIFS(RR_Score_Composito,RR_ID_Rischio,$A19,RR_Ciclo,cicloPrecedente))) -> #N/A | I19: =IF($A19="",NA(),IF(COUNTIFS(RR_ID_Rischio,$A19,RR_Ciclo,cicloMeno2)=0,NA(),SUMIFS(RR_Score_Composito,RR_ID_Rischio,$A19,RR_Ciclo,cicloMeno2))) -> #N/A | J19: =IF($A19="",NA(),IF(COUNTIFS(RR_ID_Rischio,$A19,RR_Ciclo,cicloCorrente)=0,NA(),SUMIFS(RR_Confidence,RR_ID_Rischio,$A19,RR_Ciclo,cicloCorrente))) -> 3 | K19: =IF($A19="","",COUNTIFS(NW_Rischio_ID,$A19,NW_Segnale,"Peggiorativo",NW_Settimana,">="&inizioFinestra4,NW_Settimana,"<="&settimanaCorrente)-COUNTIFS(NW_Rischio_ID,$A19,NW_Segnale,"Migliorativo",NW_Settimana,">="&inizioFinestra4,NW_Settimana,"<="&settimanaCorrente)) -> 0 | L19: =IF($A19="","",IF(K19>=sogliaDirezione,"▲ In peggioramento",IF(K19<=-sogliaDirezione,"▼ In miglioramento","● Stabile"))) -> ● Stabile
A20: =IF(Parametri!$H11="","",Parametri!$H11) -> NFR-08 | B20: =IF($A20="","",Parametri!$I11) -> Accessi impropri di dipendenti ai dati dei clienti | C20: =IF($A20="",NA(),IF(COUNTIFS(RR_ID_Rischio,$A20,RR_Ciclo,cicloCorrente)=0,NA(),SUMIFS(RR_Severity,RR_ID_Rischio,$A20,RR_Ciclo,cicloCorrente))) -> 3 | D20: =IF($A20="",NA(),IF(COUNTIFS(RR_ID_Rischio,$A20,RR_Ciclo,cicloCorrente)=0,NA(),SUMIFS(RR_Velocity,RR_ID_Rischio,$A20,RR_Ciclo,cicloCorrente))) -> 3 | E20: =IF($A20="",NA(),IF(COUNTIFS(RR_ID_Rischio,$A20,RR_Ciclo,cicloCorrente)=0,NA(),SUMIFS(RR_Prossimita,RR_ID_Rischio,$A20,RR_Ciclo,cicloCorrente))) -> 3 | F20: =IF($A20="",NA(),IF(COUNTIFS(RR_ID_Rischio,$A20,RR_Ciclo,cicloCorrente)=0,NA(),SUMIFS(RR_Gap_Controlli,RR_ID_Rischio,$A20,RR_Ciclo,cicloCorrente))) -> 3 | G20: =IF($A20="",NA(),IF(COUNTIFS(RR_ID_Rischio,$A20,RR_Ciclo,cicloCorrente)=0,NA(),SUMIFS(RR_Score_Composito,RR_ID_Rischio,$A20,RR_Ciclo,cicloCorrente))) -> 3 | H20: =IF($A20="",NA(),IF(COUNTIFS(RR_ID_Rischio,$A20,RR_Ciclo,cicloPrecedente)=0,NA(),SUMIFS(RR_Score_Composito,RR_ID_Rischio,$A20,RR_Ciclo,cicloPrecedente))) -> #N/A | I20: =IF($A20="",NA(),IF(COUNTIFS(RR_ID_Rischio,$A20,RR_Ciclo,cicloMeno2)=0,NA(),SUMIFS(RR_Score_Composito,RR_ID_Rischio,$A20,RR_Ciclo,cicloMeno2))) -> #N/A | J20: =IF($A20="",NA(),IF(COUNTIFS(RR_ID_Rischio,$A20,RR_Ciclo,cicloCorrente)=0,NA(),SUMIFS(RR_Confidence,RR_ID_Rischio,$A20,RR_Ciclo,cicloCorrente))) -> 3 | K20: =IF($A20="","",COUNTIFS(NW_Rischio_ID,$A20,NW_Segnale,"Peggiorativo",NW_Settimana,">="&inizioFinestra4,NW_Settimana,"<="&settimanaCorrente)-COUNTIFS(NW_Rischio_ID,$A20,NW_Segnale,"Migliorativo",NW_Settimana,">="&inizioFinestra4,NW_Settimana,"<="&settimanaCorrente)) -> 0 | L20: =IF($A20="","",IF(K20>=sogliaDirezione,"▲ In peggioramento",IF(K20<=-sogliaDirezione,"▼ In miglioramento","● Stabile"))) -> ● Stabile
A21: =IF(Parametri!$H12="","",Parametri!$H12) -> NFR-09 | B21: =IF($A21="","",Parametri!$I12) -> Violazione di sanzioni internazionali tramite triangolazioni | C21: =IF($A21="",NA(),IF(COUNTIFS(RR_ID_Rischio,$A21,RR_Ciclo,cicloCorrente)=0,NA(),SUMIFS(RR_Severity,RR_ID_Rischio,$A21,RR_Ciclo,cicloCorrente))) -> 4 | D21: =IF($A21="",NA(),IF(COUNTIFS(RR_ID_Rischio,$A21,RR_Ciclo,cicloCorrente)=0,NA(),SUMIFS(RR_Velocity,RR_ID_Rischio,$A21,RR_Ciclo,cicloCorrente))) -> 3 | E21: =IF($A21="",NA(),IF(COUNTIFS(RR_ID_Rischio,$A21,RR_Ciclo,cicloCorrente)=0,NA(),SUMIFS(RR_Prossimita,RR_ID_Rischio,$A21,RR_Ciclo,cicloCorrente))) -> 2 | F21: =IF($A21="",NA(),IF(COUNTIFS(RR_ID_Rischio,$A21,RR_Ciclo,cicloCorrente)=0,NA(),SUMIFS(RR_Gap_Controlli,RR_ID_Rischio,$A21,RR_Ciclo,cicloCorrente))) -> 3 | G21: =IF($A21="",NA(),IF(COUNTIFS(RR_ID_Rischio,$A21,RR_Ciclo,cicloCorrente)=0,NA(),SUMIFS(RR_Score_Composito,RR_ID_Rischio,$A21,RR_Ciclo,cicloCorrente))) -> 3.2 | H21: =IF($A21="",NA(),IF(COUNTIFS(RR_ID_Rischio,$A21,RR_Ciclo,cicloPrecedente)=0,NA(),SUMIFS(RR_Score_Composito,RR_ID_Rischio,$A21,RR_Ciclo,cicloPrecedente))) -> #N/A | I21: =IF($A21="",NA(),IF(COUNTIFS(RR_ID_Rischio,$A21,RR_Ciclo,cicloMeno2)=0,NA(),SUMIFS(RR_Score_Composito,RR_ID_Rischio,$A21,RR_Ciclo,cicloMeno2))) -> #N/A | J21: =IF($A21="",NA(),IF(COUNTIFS(RR_ID_Rischio,$A21,RR_Ciclo,cicloCorrente)=0,NA(),SUMIFS(RR_Confidence,RR_ID_Rischio,$A21,RR_Ciclo,cicloCorrente))) -> 2 | K21: =IF($A21="","",COUNTIFS(NW_Rischio_ID,$A21,NW_Segnale,"Peggiorativo",NW_Settimana,">="&inizioFinestra4,NW_Settimana,"<="&settimanaCorrente)-COUNTIFS(NW_Rischio_ID,$A21,NW_Segnale,"Migliorativo",NW_Settimana,">="&inizioFinestra4,NW_Settimana,"<="&settimanaCorrente)) -> 0 | L21: =IF($A21="","",IF(K21>=sogliaDirezione,"▲ In peggioramento",IF(K21<=-sogliaDirezione,"▼ In miglioramento","● Stabile"))) -> ● Stabile
A22: =IF(Parametri!$H13="","",Parametri!$H13) -> NFR-10 | B22: =IF($A22="","",Parametri!$I13) -> Informazioni errate ai clienti da assistenti di AI generativa | C22: =IF($A22="",NA(),IF(COUNTIFS(RR_ID_Rischio,$A22,RR_Ciclo,cicloCorrente)=0,NA(),SUMIFS(RR_Severity,RR_ID_Rischio,$A22,RR_Ciclo,cicloCorrente))) -> 3 | D22: =IF($A22="",NA(),IF(COUNTIFS(RR_ID_Rischio,$A22,RR_Ciclo,cicloCorrente)=0,NA(),SUMIFS(RR_Velocity,RR_ID_Rischio,$A22,RR_Ciclo,cicloCorrente))) -> 3 | E22: =IF($A22="",NA(),IF(COUNTIFS(RR_ID_Rischio,$A22,RR_Ciclo,cicloCorrente)=0,NA(),SUMIFS(RR_Prossimita,RR_ID_Rischio,$A22,RR_Ciclo,cicloCorrente))) -> 3 | F22: =IF($A22="",NA(),IF(COUNTIFS(RR_ID_Rischio,$A22,RR_Ciclo,cicloCorrente)=0,NA(),SUMIFS(RR_Gap_Controlli,RR_ID_Rischio,$A22,RR_Ciclo,cicloCorrente))) -> 4 | G22: =IF($A22="",NA(),IF(COUNTIFS(RR_ID_Rischio,$A22,RR_Ciclo,cicloCorrente)=0,NA(),SUMIFS(RR_Score_Composito,RR_ID_Rischio,$A22,RR_Ciclo,cicloCorrente))) -> 3.2 | H22: =IF($A22="",NA(),IF(COUNTIFS(RR_ID_Rischio,$A22,RR_Ciclo,cicloPrecedente)=0,NA(),SUMIFS(RR_Score_Composito,RR_ID_Rischio,$A22,RR_Ciclo,cicloPrecedente))) -> #N/A | I22: =IF($A22="",NA(),IF(COUNTIFS(RR_ID_Rischio,$A22,RR_Ciclo,cicloMeno2)=0,NA(),SUMIFS(RR_Score_Composito,RR_ID_Rischio,$A22,RR_Ciclo,cicloMeno2))) -> #N/A | J22: =IF($A22="",NA(),IF(COUNTIFS(RR_ID_Rischio,$A22,RR_Ciclo,cicloCorrente)=0,NA(),SUMIFS(RR_Confidence,RR_ID_Rischio,$A22,RR_Ciclo,cicloCorrente))) -> 2 | K22: =IF($A22="","",COUNTIFS(NW_Rischio_ID,$A22,NW_Segnale,"Peggiorativo",NW_Settimana,">="&inizioFinestra4,NW_Settimana,"<="&settimanaCorrente)-COUNTIFS(NW_Rischio_ID,$A22,NW_Segnale,"Migliorativo",NW_Settimana,">="&inizioFinestra4,NW_Settimana,"<="&settimanaCorrente)) -> 0 | L22: =IF($A22="","",IF(K22>=sogliaDirezione,"▲ In peggioramento",IF(K22<=-sogliaDirezione,"▼ In miglioramento","● Stabile"))) -> ● Stabile
A23: =IF(Parametri!$H14="","",Parametri!$H14) -> NFR-11 | B23: =IF($A23="","",Parametri!$I14) -> Fine del supporto dei sistemi di pagamento legacy | C23: =IF($A23="",NA(),IF(COUNTIFS(RR_ID_Rischio,$A23,RR_Ciclo,cicloCorrente)=0,NA(),SUMIFS(RR_Severity,RR_ID_Rischio,$A23,RR_Ciclo,cicloCorrente))) -> 3 | D23: =IF($A23="",NA(),IF(COUNTIFS(RR_ID_Rischio,$A23,RR_Ciclo,cicloCorrente)=0,NA(),SUMIFS(RR_Velocity,RR_ID_Rischio,$A23,RR_Ciclo,cicloCorrente))) -> 2 | E23: =IF($A23="",NA(),IF(COUNTIFS(RR_ID_Rischio,$A23,RR_Ciclo,cicloCorrente)=0,NA(),SUMIFS(RR_Prossimita,RR_ID_Rischio,$A23,RR_Ciclo,cicloCorrente))) -> 3 | F23: =IF($A23="",NA(),IF(COUNTIFS(RR_ID_Rischio,$A23,RR_Ciclo,cicloCorrente)=0,NA(),SUMIFS(RR_Gap_Controlli,RR_ID_Rischio,$A23,RR_Ciclo,cicloCorrente))) -> 4 | G23: =IF($A23="",NA(),IF(COUNTIFS(RR_ID_Rischio,$A23,RR_Ciclo,cicloCorrente)=0,NA(),SUMIFS(RR_Score_Composito,RR_ID_Rischio,$A23,RR_Ciclo,cicloCorrente))) -> 3 | H23: =IF($A23="",NA(),IF(COUNTIFS(RR_ID_Rischio,$A23,RR_Ciclo,cicloPrecedente)=0,NA(),SUMIFS(RR_Score_Composito,RR_ID_Rischio,$A23,RR_Ciclo,cicloPrecedente))) -> #N/A | I23: =IF($A23="",NA(),IF(COUNTIFS(RR_ID_Rischio,$A23,RR_Ciclo,cicloMeno2)=0,NA(),SUMIFS(RR_Score_Composito,RR_ID_Rischio,$A23,RR_Ciclo,cicloMeno2))) -> #N/A | J23: =IF($A23="",NA(),IF(COUNTIFS(RR_ID_Rischio,$A23,RR_Ciclo,cicloCorrente)=0,NA(),SUMIFS(RR_Confidence,RR_ID_Rischio,$A23,RR_Ciclo,cicloCorrente))) -> 3 | K23: =IF($A23="","",COUNTIFS(NW_Rischio_ID,$A23,NW_Segnale,"Peggiorativo",NW_Settimana,">="&inizioFinestra4,NW_Settimana,"<="&settimanaCorrente)-COUNTIFS(NW_Rischio_ID,$A23,NW_Segnale,"Migliorativo",NW_Settimana,">="&inizioFinestra4,NW_Settimana,"<="&settimanaCorrente)) -> 0 | L23: =IF($A23="","",IF(K23>=sogliaDirezione,"▲ In peggioramento",IF(K23<=-sogliaDirezione,"▼ In miglioramento","● Stabile"))) -> ● Stabile
A24: =IF(Parametri!$H15="","",Parametri!$H15) -> NFR-12 | B24: =IF($A24="","",Parametri!$I15) -> Errori operativi nei pagamenti istantanei obbligatori | C24: =IF($A24="",NA(),IF(COUNTIFS(RR_ID_Rischio,$A24,RR_Ciclo,cicloCorrente)=0,NA(),SUMIFS(RR_Severity,RR_ID_Rischio,$A24,RR_Ciclo,cicloCorrente))) -> 3 | D24: =IF($A24="",NA(),IF(COUNTIFS(RR_ID_Rischio,$A24,RR_Ciclo,cicloCorrente)=0,NA(),SUMIFS(RR_Velocity,RR_ID_Rischio,$A24,RR_Ciclo,cicloCorrente))) -> 4 | E24: =IF($A24="",NA(),IF(COUNTIFS(RR_ID_Rischio,$A24,RR_Ciclo,cicloCorrente)=0,NA(),SUMIFS(RR_Prossimita,RR_ID_Rischio,$A24,RR_Ciclo,cicloCorrente))) -> 4 | F24: =IF($A24="",NA(),IF(COUNTIFS(RR_ID_Rischio,$A24,RR_Ciclo,cicloCorrente)=0,NA(),SUMIFS(RR_Gap_Controlli,RR_ID_Rischio,$A24,RR_Ciclo,cicloCorrente))) -> 3 | G24: =IF($A24="",NA(),IF(COUNTIFS(RR_ID_Rischio,$A24,RR_Ciclo,cicloCorrente)=0,NA(),SUMIFS(RR_Score_Composito,RR_ID_Rischio,$A24,RR_Ciclo,cicloCorrente))) -> 3.4 | H24: =IF($A24="",NA(),IF(COUNTIFS(RR_ID_Rischio,$A24,RR_Ciclo,cicloPrecedente)=0,NA(),SUMIFS(RR_Score_Composito,RR_ID_Rischio,$A24,RR_Ciclo,cicloPrecedente))) -> #N/A | I24: =IF($A24="",NA(),IF(COUNTIFS(RR_ID_Rischio,$A24,RR_Ciclo,cicloMeno2)=0,NA(),SUMIFS(RR_Score_Composito,RR_ID_Rischio,$A24,RR_Ciclo,cicloMeno2))) -> #N/A | J24: =IF($A24="",NA(),IF(COUNTIFS(RR_ID_Rischio,$A24,RR_Ciclo,cicloCorrente)=0,NA(),SUMIFS(RR_Confidence,RR_ID_Rischio,$A24,RR_Ciclo,cicloCorrente))) -> 3 | K24: =IF($A24="","",COUNTIFS(NW_Rischio_ID,$A24,NW_Segnale,"Peggiorativo",NW_Settimana,">="&inizioFinestra4,NW_Settimana,"<="&settimanaCorrente)-COUNTIFS(NW_Rischio_ID,$A24,NW_Segnale,"Migliorativo",NW_Settimana,">="&inizioFinestra4,NW_Settimana,"<="&settimanaCorrente)) -> 0 | L24: =IF($A24="","",IF(K24>=sogliaDirezione,"▲ In peggioramento",IF(K24<=-sogliaDirezione,"▼ In miglioramento","● Stabile"))) -> ● Stabile
... A27: =IF(Parametri!$H18="","",Parametri!$H18) | B27: =IF($A27="","",Parametri!$I18) | C27: =IF($A27="",NA(),IF(COUNTIFS(RR_ID_Rischio,$A27,RR_Ciclo,cicloCorrente)=0,NA(),SUMIFS(RR_Severity,RR_ID_Rischio,$A27,RR_Ciclo,cicloCorrente))) -> #N/A | D27: =IF($A27="",NA(),IF(COUNTIFS(RR_ID_Rischio,$A27,RR_Ciclo,cicloCorrente)=0,NA(),SUMIFS(RR_Velocity,RR_ID_Rischio,$A27,RR_Ciclo,cicloCorrente))) -> #N/A | E27: =IF($A27="",NA(),IF(COUNTIFS(RR_ID_Rischio,$A27,RR_Ciclo,cicloCorrente)=0,NA(),SUMIFS(RR_Prossimita,RR_ID_Rischio,$A27,RR_Ciclo,cicloCorrente))) -> #N/A | F27: =IF($A27="",NA(),IF(COUNTIFS(RR_ID_Rischio,$A27,RR_Ciclo,cicloCorrente)=0,NA(),SUMIFS(RR_Gap_Controlli,RR_ID_Rischio,$A27,RR_Ciclo,cicloCorrente))) -> #N/A | G27: =IF($A27="",NA(),IF(COUNTIFS(RR_ID_Rischio,$A27,RR_Ciclo,cicloCorrente)=0,NA(),SUMIFS(RR_Score_Composito,RR_ID_Rischio,$A27,RR_Ciclo,cicloCorrente))) -> #N/A | H27: =IF($A27="",NA(),IF(COUNTIFS(RR_ID_Rischio,$A27,RR_Ciclo,cicloPrecedente)=0,NA(),SUMIFS(RR_Score_Composito,RR_ID_Rischio,$A27,RR_Ciclo,cicloPrecedente))) -> #N/A | I27: =IF($A27="",NA(),IF(COUNTIFS(RR_ID_Rischio,$A27,RR_Ciclo,cicloMeno2)=0,NA(),SUMIFS(RR_Score_Composito,RR_ID_Rischio,$A27,RR_Ciclo,cicloMeno2))) -> #N/A | J27: =IF($A27="",NA(),IF(COUNTIFS(RR_ID_Rischio,$A27,RR_Ciclo,cicloCorrente)=0,NA(),SUMIFS(RR_Confidence,RR_ID_Rischio,$A27,RR_Ciclo,cicloCorrente))) -> #N/A | K27: =IF($A27="","",COUNTIFS(NW_Rischio_ID,$A27,NW_Segnale,"Peggiorativo",NW_Settimana,">="&inizioFinestra4,NW_Settimana,"<="&settimanaCorrente)-COUNTIFS(NW_Rischio_ID,$A27,NW_Segnale,"Migliorativo",NW_Settimana,">="&inizioFinestra4,NW_Settimana,"<="&settimanaCorrente)) | L27: =IF($A27="","",IF(K27>=sogliaDirezione,"▲ In peggioramento",IF(K27<=-sogliaDirezione,"▼ In miglioramento","● Stabile")))

Sheet Radar_Mosca
A1: Radar di Mosca — quanto presto bisogna agire, e quanto e' grande ogni rischio
A2: Piu' vicino al centro = agire prima (dentro il cerchio rosso X + Y > Z: gia' in ritardo). Area del cerchio = Probabilita x Severity. Settore = event type. Tutto calcolato: parametri X, Y di riserva e Z in Parametri (righe 47-55).
U3: Appoggio del grafico: non modificare
A4: ID | B4: Nome | C4: Event type | D4: Impatto (Severity) | E4: Probabilita | F4: P x I | G4: Prossimita | H4: Z anni alla manifestazione | I4: X anni per decidere | J4: Y anni per mitigare | K4: Margine Z-(X+Y) | L4: Urgenza | M4: Settore | N4: Posizione nel settore | O4: Rischi nel settore | P4: Angolo | Q4: Raggio | R4: x | S4: y | V4: Mosca | X4: 1 anno | Z4: 2 anni | AB4: 3 anni | AL4: 1 | AM4: 2 | AN4: 3 | AO4: 4 | AP4: 5 | AQ4: 6 | AR4: 8 | AS4: 9 | AT4: 10 | AU4: 12 | AV4: 15 | AW4: 16 | AX4: 20 | AY4: 25
A5: =IF(Parametri!$H4="","",Parametri!$H4) -> NFR-01 | B5: =IF($A5="","",Parametri!$I4) -> Frodi su pagamenti istantanei abilitate da AI generativa | C5: =IF($A5="","",Parametri!$J4) -> L1-02 | D5: =IF($A5="",NA(),IF(COUNTIFS(RR_ID_Rischio,$A5,RR_Ciclo,cicloCorrente)=0,NA(),SUMIFS(RR_Severity,RR_ID_Rischio,$A5,RR_Ciclo,cicloCorrente))) -> 4 | E5: =IF($A5="",NA(),IF(COUNTIFS(RR_ID_Rischio,$A5,RR_Ciclo,cicloCorrente)=0,NA(),SUMIFS(RR_Probabilita,RR_ID_Rischio,$A5,RR_Ciclo,cicloCorrente))) -> 4 | F5: =IF(AND(ISNUMBER(D5),ISNUMBER(E5)),D5*E5,NA()) -> 16 | G5: =IF($A5="",NA(),IF(COUNTIFS(RR_ID_Rischio,$A5,RR_Ciclo,cicloCorrente)=0,NA(),SUMIFS(RR_Prossimita,RR_ID_Rischio,$A5,RR_Ciclo,cicloCorrente))) -> 4 | H5: =IF(ISNUMBER(G5),INDEX(anniProssimita,G5),NA()) -> 0.5 | I5: =IF($A5="",NA(),moscaX) -> 0.25 | J5: =IF($A5="",NA(),IF(COUNTIFS(AZ_ID_Rischio,$A5,AZ_Ciclo,cicloCorrente,AZ_Stato,"<>Respinta",AZ_Mesi_Orizzonte,">0")=0,moscaYDefault,_xlfn.MAXIFS(AZ_Mesi_Orizzonte,AZ_ID_Rischio,$A5,AZ_Ciclo,cicloCorrente,AZ_Stato,"<>Respinta")/12)) -> 0.5 | K5: =IF(AND(ISNUMBER(H5),ISNUMBER(J5)),H5-(I5+J5),NA()) -> -0.25 | L5: =IF(NOT(ISNUMBER(K5)),"",IF(K5<0,"AGIRE ORA: X+Y > Z",IF(K5<1,"Agire entro l'anno","Margine "&ROUND(K5,1)&IF(ROUND(K5,1)=1," anno"," anni")))) -> AGIRE ORA: X+Y > Z | M5: =IF($A5="",NA(),MATCH(C5,codiciL1,0)-1) -> 1 | N5: =IF($A5="",NA(),COUNTIF($C$4:C4,C5)) -> 0 | O5: =IF($A5="",NA(),COUNTIF(ANA_Event_Type,C5)) -> 1 | P5: =IF($A5="",NA(),2*PI()*(M5+(N5+0.5)/O5)/ROWS(codiciL1)) -> 1.3463969 | Q5: =IF(ISNUMBER(K5),MAX(0.6,MIN(6,K5+2)),NA()) -> 1.75 | R5: =IF(AND(ISNUMBER(Q5),ISNUMBER(P5)),Q5*SIN(P5),NA()) -> 1.7061238 | S5: =IF(AND(ISNUMBER(Q5),ISNUMBER(P5)),Q5*COS(P5),NA()) -> 0.38941163 | U5: =2*PI()*0/72 -> 0 | V5: =2*SIN($U5) -> 0 | W5: =2*COS($U5) -> 2 | X5: =3*SIN($U5) -> 0 | Y5: =3*COS($U5) -> 3 | Z5: =4*SIN($U5) -> 0 | AA5: =4*COS($U5) -> 4 | AB5: =5*SIN($U5) -> 0 | AC5: =5*COS($U5) -> 5 | AE5: 0 | AF5: 0 | AH5: L1-01 | AI5: =6.75*SIN(2*PI()*(0+0.5)/ROWS(codiciL1)) -> 2.9287152 | AJ5: =6.75*COS(2*PI()*(0+0.5)/ROWS(codiciL1)) -> 6.0815399 | AL5: =IF(AND(ISNUMBER($F5),ISNUMBER($S5)),IF($F5=AL$4,$S5,NA()),NA()) -> #N/A | AM5: =IF(AND(ISNUMBER($F5),ISNUMBER($S5)),IF($F5=AM$4,$S5,NA()),NA()) -> #N/A | AN5: =IF(AND(ISNUMBER($F5),ISNUMBER($S5)),IF($F5=AN$4,$S5,NA()),NA()) -> #N/A | AO5: =IF(AND(ISNUMBER($F5),ISNUMBER($S5)),IF($F5=AO$4,$S5,NA()),NA()) -> #N/A | AP5: =IF(AND(ISNUMBER($F5),ISNUMBER($S5)),IF($F5=AP$4,$S5,NA()),NA()) -> #N/A | AQ5: =IF(AND(ISNUMBER($F5),ISNUMBER($S5)),IF($F5=AQ$4,$S5,NA()),NA()) -> #N/A | AR5: =IF(AND(ISNUMBER($F5),ISNUMBER($S5)),IF($F5=AR$4,$S5,NA()),NA()) -> #N/A | AS5: =IF(AND(ISNUMBER($F5),ISNUMBER($S5)),IF($F5=AS$4,$S5,NA()),NA()) -> #N/A | ... AY5: =IF(AND(ISNUMBER($F5),ISNUMBER($S5)),IF($F5=AY$4,$S5,NA()),NA()) -> #N/A
A6: =IF(Parametri!$H5="","",Parametri!$H5) -> NFR-02 | B6: =IF($A6="","",Parametri!$I5) -> Concentrazione su un fornitore cloud critico | C6: =IF($A6="","",Parametri!$J5) -> L1-06 | D6: =IF($A6="",NA(),IF(COUNTIFS(RR_ID_Rischio,$A6,RR_Ciclo,cicloCorrente)=0,NA(),SUMIFS(RR_Severity,RR_ID_Rischio,$A6,RR_Ciclo,cicloCorrente))) -> 4 | E6: =IF($A6="",NA(),IF(COUNTIFS(RR_ID_Rischio,$A6,RR_Ciclo,cicloCorrente)=0,NA(),SUMIFS(RR_Probabilita,RR_ID_Rischio,$A6,RR_Ciclo,cicloCorrente))) -> 2 | F6: =IF(AND(ISNUMBER(D6),ISNUMBER(E6)),D6*E6,NA()) -> 8 | G6: =IF($A6="",NA(),IF(COUNTIFS(RR_ID_Rischio,$A6,RR_Ciclo,cicloCorrente)=0,NA(),SUMIFS(RR_Prossimita,RR_ID_Rischio,$A6,RR_Ciclo,cicloCorrente))) -> 3 | H6: =IF(ISNUMBER(G6),INDEX(anniProssimita,G6),NA()) -> 1.5 | I6: =IF($A6="",NA(),moscaX) -> 0.25 | J6: =IF($A6="",NA(),IF(COUNTIFS(AZ_ID_Rischio,$A6,AZ_Ciclo,cicloCorrente,AZ_Stato,"<>Respinta",AZ_Mesi_Orizzonte,">0")=0,moscaYDefault,_xlfn.MAXIFS(AZ_Mesi_Orizzonte,AZ_ID_Rischio,$A6,AZ_Ciclo,cicloCorrente,AZ_Stato,"<>Respinta")/12)) -> 1 | K6: =IF(AND(ISNUMBER(H6),ISNUMBER(J6)),H6-(I6+J6),NA()) -> 0.25 | L6: =IF(NOT(ISNUMBER(K6)),"",IF(K6<0,"AGIRE ORA: X+Y > Z",IF(K6<1,"Agire entro l'anno","Margine "&ROUND(K6,1)&IF(ROUND(K6,1)=1," anno"," anni")))) -> Agire entro l'anno | M6: =IF($A6="",NA(),MATCH(C6,codiciL1,0)-1) -> 5 | N6: =IF($A6="",NA(),COUNTIF($C$4:C5,C6)) -> 0 | O6: =IF($A6="",NA(),COUNTIF(ANA_Event_Type,C6)) -> 3 | P6: =IF($A6="",NA(),2*PI()*(M6+(N6+0.5)/O6)/ROWS(codiciL1)) -> 4.6375892 | Q6: =IF(ISNUMBER(K6),MAX(0.6,MIN(6,K6+2)),NA()) -> 2.25 | R6: =IF(AND(ISNUMBER(Q6),ISNUMBER(P6)),Q6*SIN(P6),NA()) -> -2.2437085 | S6: =IF(AND(ISNUMBER(Q6),ISNUMBER(P6)),Q6*COS(P6),NA()) -> -0.16814271 | U6: =2*PI()*1/72 -> 0.087266463 | V6: =2*SIN($U6) -> 0.17431149 | W6: =2*COS($U6) -> 1.9923894 | X6: =3*SIN($U6) -> 0.26146723 | Y6: =3*COS($U6) -> 2.9885841 | Z6: =4*SIN($U6) -> 0.34862297 | AA6: =4*COS($U6) -> 3.9847788 | AB6: =5*SIN($U6) -> 0.43577871 | AC6: =5*COS($U6) -> 4.9809735 | AE6: =6.3*SIN(2*PI()*0/ROWS(codiciL1)) -> 0 | AF6: =6.3*COS(2*PI()*0/ROWS(codiciL1)) -> 6.3 | AH6: L1-02 | AI6: =6.75*SIN(2*PI()*(1+0.5)/ROWS(codiciL1)) -> 6.5807634 | AJ6: =6.75*COS(2*PI()*(1+0.5)/ROWS(codiciL1)) -> 1.5020163 | AL6: =IF(AND(ISNUMBER($F6),ISNUMBER($S6)),IF($F6=AL$4,$S6,NA()),NA()) -> #N/A | AM6: =IF(AND(ISNUMBER($F6),ISNUMBER($S6)),IF($F6=AM$4,$S6,NA()),NA()) -> #N/A | AN6: =IF(AND(ISNUMBER($F6),ISNUMBER($S6)),IF($F6=AN$4,$S6,NA()),NA()) -> #N/A | AO6: =IF(AND(ISNUMBER($F6),ISNUMBER($S6)),IF($F6=AO$4,$S6,NA()),NA()) -> #N/A | AP6: =IF(AND(ISNUMBER($F6),ISNUMBER($S6)),IF($F6=AP$4,$S6,NA()),NA()) -> #N/A | AQ6: =IF(AND(ISNUMBER($F6),ISNUMBER($S6)),IF($F6=AQ$4,$S6,NA()),NA()) -> #N/A | AR6: =IF(AND(ISNUMBER($F6),ISNUMBER($S6)),IF($F6=AR$4,$S6,NA()),NA()) -> -0.16814271 | AS6: =IF(AND(ISNUMBER($F6),ISNUMBER($S6)),IF($F6=AS$4,$S6,NA()),NA()) -> #N/A | ... AY6: =IF(AND(ISNUMBER($F6),ISNUMBER($S6)),IF($F6=AY$4,$S6,NA()),NA()) -> #N/A
A7: =IF(Parametri!$H6="","",Parametri!$H6) -> NFR-03 | B7: =IF($A7="","",Parametri!$I6) -> Greenwashing nella commercializzazione di prodotti ESG | C7: =IF($A7="","",Parametri!$J6) -> L1-04 | D7: =IF($A7="",NA(),IF(COUNTIFS(RR_ID_Rischio,$A7,RR_Ciclo,cicloCorrente)=0,NA(),SUMIFS(RR_Severity,RR_ID_Rischio,$A7,RR_Ciclo,cicloCorrente))) -> 3 | E7: =IF($A7="",NA(),IF(COUNTIFS(RR_ID_Rischio,$A7,RR_Ciclo,cicloCorrente)=0,NA(),SUMIFS(RR_Probabilita,RR_ID_Rischio,$A7,RR_Ciclo,cicloCorrente))) -> 2 | F7: =IF(AND(ISNUMBER(D7),ISNUMBER(E7)),D7*E7,NA()) -> 6 | G7: =IF($A7="",NA(),IF(COUNTIFS(RR_ID_Rischio,$A7,RR_Ciclo,cicloCorrente)=0,NA(),SUMIFS(RR_Prossimita,RR_ID_Rischio,$A7,RR_Ciclo,cicloCorrente))) -> 4 | H7: =IF(ISNUMBER(G7),INDEX(anniProssimita,G7),NA()) -> 0.5 | I7: =IF($A7="",NA(),moscaX) -> 0.25 | J7: =IF($A7="",NA(),IF(COUNTIFS(AZ_ID_Rischio,$A7,AZ_Ciclo,cicloCorrente,AZ_Stato,"<>Respinta",AZ_Mesi_Orizzonte,">0")=0,moscaYDefault,_xlfn.MAXIFS(AZ_Mesi_Orizzonte,AZ_ID_Rischio,$A7,AZ_Ciclo,cicloCorrente,AZ_Stato,"<>Respinta")/12)) -> 0.25 | K7: =IF(AND(ISNUMBER(H7),ISNUMBER(J7)),H7-(I7+J7),NA()) -> 0 | L7: =IF(NOT(ISNUMBER(K7)),"",IF(K7<0,"AGIRE ORA: X+Y > Z",IF(K7<1,"Agire entro l'anno","Margine "&ROUND(K7,1)&IF(ROUND(K7,1)=1," anno"," anni")))) -> Agire entro l'anno | M7: =IF($A7="",NA(),MATCH(C7,codiciL1,0)-1) -> 3 | N7: =IF($A7="",NA(),COUNTIF($C$4:C6,C7)) -> 0 | O7: =IF($A7="",NA(),COUNTIF(ANA_Event_Type,C7)) -> 3 | P7: =IF($A7="",NA(),2*PI()*(M7+(N7+0.5)/O7)/ROWS(codiciL1)) -> 2.8423934 | Q7: =IF(ISNUMBER(K7),MAX(0.6,MIN(6,K7+2)),NA()) -> 2 | R7: =IF(AND(ISNUMBER(Q7),ISNUMBER(P7)),Q7*SIN(P7),NA()) -> 0.58951035 | S7: =IF(AND(ISNUMBER(Q7),ISNUMBER(P7)),Q7*COS(P7),NA()) -> -1.9111456 | U7: =2*PI()*2/72 -> 0.17453293 | V7: =2*SIN($U7) -> 0.34729636 | W7: =2*COS($U7) -> 1.9696155 | X7: =3*SIN($U7) -> 0.52094453 | Y7: =3*COS($U7) -> 2.9544233 | Z7: =4*SIN($U7) -> 0.69459271 | AA7: =4*COS($U7) -> 3.939231 | AB7: =5*SIN($U7) -> 0.86824089 | AC7: =5*COS($U7) -> 4.9240388 | AE7: 0 | AF7: 0 | AH7: L1-03 | AI7: =6.75*SIN(2*PI()*(2+0.5)/ROWS(codiciL1)) -> 5.2773625 | AJ7: =6.75*COS(2*PI()*(2+0.5)/ROWS(codiciL1)) -> -4.2085562 | AL7: =IF(AND(ISNUMBER($F7),ISNUMBER($S7)),IF($F7=AL$4,$S7,NA()),NA()) -> #N/A | AM7: =IF(AND(ISNUMBER($F7),ISNUMBER($S7)),IF($F7=AM$4,$S7,NA()),NA()) -> #N/A | AN7: =IF(AND(ISNUMBER($F7),ISNUMBER($S7)),IF($F7=AN$4,$S7,NA()),NA()) -> #N/A | AO7: =IF(AND(ISNUMBER($F7),ISNUMBER($S7)),IF($F7=AO$4,$S7,NA()),NA()) -> #N/A | AP7: =IF(AND(ISNUMBER($F7),ISNUMBER($S7)),IF($F7=AP$4,$S7,NA()),NA()) -> #N/A | AQ7: =IF(AND(ISNUMBER($F7),ISNUMBER($S7)),IF($F7=AQ$4,$S7,NA()),NA()) -> -1.9111456 | AR7: =IF(AND(ISNUMBER($F7),ISNUMBER($S7)),IF($F7=AR$4,$S7,NA()),NA()) -> #N/A | AS7: =IF(AND(ISNUMBER($F7),ISNUMBER($S7)),IF($F7=AS$4,$S7,NA()),NA()) -> #N/A | ... AY7: =IF(AND(ISNUMBER($F7),ISNUMBER($S7)),IF($F7=AY$4,$S7,NA()),NA()) -> #N/A
A8: =IF(Parametri!$H7="","",Parametri!$H7) -> NFR-04 | B8: =IF($A8="","",Parametri!$I7) -> Eventi climatici estremi su sedi e data center | C8: =IF($A8="","",Parametri!$J7) -> L1-05 | D8: =IF($A8="",NA(),IF(COUNTIFS(RR_ID_Rischio,$A8,RR_Ciclo,cicloCorrente)=0,NA(),SUMIFS(RR_Severity,RR_ID_Rischio,$A8,RR_Ciclo,cicloCorrente))) -> 3 | E8: =IF($A8="",NA(),IF(COUNTIFS(RR_ID_Rischio,$A8,RR_Ciclo,cicloCorrente)=0,NA(),SUMIFS(RR_Probabilita,RR_ID_Rischio,$A8,RR_Ciclo,cicloCorrente))) -> 3 | F8: =IF(AND(ISNUMBER(D8),ISNUMBER(E8)),D8*E8,NA()) -> 9 | G8: =IF($A8="",NA(),IF(COUNTIFS(RR_ID_Rischio,$A8,RR_Ciclo,cicloCorrente)=0,NA(),SUMIFS(RR_Prossimita,RR_ID_Rischio,$A8,RR_Ciclo,cicloCorrente))) -> 3 | H8: =IF(ISNUMBER(G8),INDEX(anniProssimita,G8),NA()) -> 1.5 | I8: =IF($A8="",NA(),moscaX) -> 0.25 | J8: =IF($A8="",NA(),IF(COUNTIFS(AZ_ID_Rischio,$A8,AZ_Ciclo,cicloCorrente,AZ_Stato,"<>Respinta",AZ_Mesi_Orizzonte,">0")=0,moscaYDefault,_xlfn.MAXIFS(AZ_Mesi_Orizzonte,AZ_ID_Rischio,$A8,AZ_Ciclo,cicloCorrente,AZ_Stato,"<>Respinta")/12)) -> 0.5 | K8: =IF(AND(ISNUMBER(H8),ISNUMBER(J8)),H8-(I8+J8),NA()) -> 0.75 | L8: =IF(NOT(ISNUMBER(K8)),"",IF(K8<0,"AGIRE ORA: X+Y > Z",IF(K8<1,"Agire entro l'anno","Margine "&ROUND(K8,1)&IF(ROUND(K8,1)=1," anno"," anni")))) -> Agire entro l'anno | M8: =IF($A8="",NA(),MATCH(C8,codiciL1,0)-1) -> 4 | N8: =IF($A8="",NA(),COUNTIF($C$4:C7,C8)) -> 0 | O8: =IF($A8="",NA(),COUNTIF(ANA_Event_Type,C8)) -> 1 | P8: =IF($A8="",NA(),2*PI()*(M8+(N8+0.5)/O8)/ROWS(codiciL1)) -> 4.0391906 | Q8: =IF(ISNUMBER(K8),MAX(0.6,MIN(6,K8+2)),NA()) -> 2.75 | R8: =IF(AND(ISNUMBER(Q8),ISNUMBER(P8)),Q8*SIN(P8),NA()) -> -2.1500366 | S8: =IF(AND(ISNUMBER(Q8),ISNUMBER(P8)),Q8*COS(P8),NA()) -> -1.714597 | U8: =2*PI()*3/72 -> 0.26179939 | V8: =2*SIN($U8) -> 0.51763809 | W8: =2*COS($U8) -> 1.9318517 | X8: =3*SIN($U8) -> 0.77645714 | Y8: =3*COS($U8) -> 2.8977775 | Z8: =4*SIN($U8) -> 1.0352762 | AA8: =4*COS($U8) -> 3.8637033 | AB8: =5*SIN($U8) -> 1.2940952 | AC8: =5*COS($U8) -> 4.8296291 | AE8: =6.3*SIN(2*PI()*1/ROWS(codiciL1)) -> 4.9255383 | AF8: =6.3*COS(2*PI()*1/ROWS(codiciL1)) -> 3.9279858 | AH8: L1-04 | AI8: =6.75*SIN(2*PI()*(3+0.5)/ROWS(codiciL1)) -> 8.2697521e-16 | AJ8: =6.75*COS(2*PI()*(3+0.5)/ROWS(codiciL1)) -> -6.75 | AL8: =IF(AND(ISNUMBER($F8),ISNUMBER($S8)),IF($F8=AL$4,$S8,NA()),NA()) -> #N/A | AM8: =IF(AND(ISNUMBER($F8),ISNUMBER($S8)),IF($F8=AM$4,$S8,NA()),NA()) -> #N/A | AN8: =IF(AND(ISNUMBER($F8),ISNUMBER($S8)),IF($F8=AN$4,$S8,NA()),NA()) -> #N/A | AO8: =IF(AND(ISNUMBER($F8),ISNUMBER($S8)),IF($F8=AO$4,$S8,NA()),NA()) -> #N/A | AP8: =IF(AND(ISNUMBER($F8),ISNUMBER($S8)),IF($F8=AP$4,$S8,NA()),NA()) -> #N/A | AQ8: =IF(AND(ISNUMBER($F8),ISNUMBER($S8)),IF($F8=AQ$4,$S8,NA()),NA()) -> #N/A | AR8: =IF(AND(ISNUMBER($F8),ISNUMBER($S8)),IF($F8=AR$4,$S8,NA()),NA()) -> #N/A | AS8: =IF(AND(ISNUMBER($F8),ISNUMBER($S8)),IF($F8=AS$4,$S8,NA()),NA()) -> -1.714597 | ... AY8: =IF(AND(ISNUMBER($F8),ISNUMBER($S8)),IF($F8=AY$4,$S8,NA()),NA()) -> #N/A
A9: =IF(Parametri!$H8="","",Parametri!$H8) -> NFR-05 | B9: =IF($A9="","",Parametri!$I8) -> Errori di processo nella migrazione del core banking | C9: =IF($A9="","",Parametri!$J8) -> L1-07 | D9: =IF($A9="",NA(),IF(COUNTIFS(RR_ID_Rischio,$A9,RR_Ciclo,cicloCorrente)=0,NA(),SUMIFS(RR_Severity,RR_ID_Rischio,$A9,RR_Ciclo,cicloCorrente))) -> 3 | E9: =IF($A9="",NA(),IF(COUNTIFS(RR_ID_Rischio,$A9,RR_Ciclo,cicloCorrente)=0,NA(),SUMIFS(RR_Probabilita,RR_ID_Rischio,$A9,RR_Ciclo,cicloCorrente))) -> 3 | F9: =IF(AND(ISNUMBER(D9),ISNUMBER(E9)),D9*E9,NA()) -> 9 | G9: =IF($A9="",NA(),IF(COUNTIFS(RR_ID_Rischio,$A9,RR_Ciclo,cicloCorrente)=0,NA(),SUMIFS(RR_Prossimita,RR_ID_Rischio,$A9,RR_Ciclo,cicloCorrente))) -> 3 | H9: =IF(ISNUMBER(G9),INDEX(anniProssimita,G9),NA()) -> 1.5 | I9: =IF($A9="",NA(),moscaX) -> 0.25 | J9: =IF($A9="",NA(),IF(COUNTIFS(AZ_ID_Rischio,$A9,AZ_Ciclo,cicloCorrente,AZ_Stato,"<>Respinta",AZ_Mesi_Orizzonte,">0")=0,moscaYDefault,_xlfn.MAXIFS(AZ_Mesi_Orizzonte,AZ_ID_Rischio,$A9,AZ_Ciclo,cicloCorrente,AZ_Stato,"<>Respinta")/12)) -> 0.25 | K9: =IF(AND(ISNUMBER(H9),ISNUMBER(J9)),H9-(I9+J9),NA()) -> 1 | L9: =IF(NOT(ISNUMBER(K9)),"",IF(K9<0,"AGIRE ORA: X+Y > Z",IF(K9<1,"Agire entro l'anno","Margine "&ROUND(K9,1)&IF(ROUND(K9,1)=1," anno"," anni")))) -> Margine 1 anno | M9: =IF($A9="",NA(),MATCH(C9,codiciL1,0)-1) -> 6 | N9: =IF($A9="",NA(),COUNTIF($C$4:C8,C9)) -> 0 | O9: =IF($A9="",NA(),COUNTIF(ANA_Event_Type,C9)) -> 2 | P9: =IF($A9="",NA(),2*PI()*(M9+(N9+0.5)/O9)/ROWS(codiciL1)) -> 5.6099869 | Q9: =IF(ISNUMBER(K9),MAX(0.6,MIN(6,K9+2)),NA()) -> 3 | R9: =IF(AND(ISNUMBER(Q9),ISNUMBER(P9)),Q9*SIN(P9),NA()) -> -1.8704694 | S9: =IF(AND(ISNUMBER(Q9),ISNUMBER(P9)),Q9*COS(P9),NA()) -> 2.3454944 | U9: =2*PI()*4/72 -> 0.34906585 | V9: =2*SIN($U9) -> 0.68404029 | W9: =2*COS($U9) -> 1.8793852 | X9: =3*SIN($U9) -> 1.0260604 | Y9: =3*COS($U9) -> 2.8190779 | Z9: =4*SIN($U9) -> 1.3680806 | AA9: =4*COS($U9) -> 3.7587705 | AB9: =5*SIN($U9) -> 1.7101007 | AC9: =5*COS($U9) -> 4.6984631 | AE9: 0 | AF9: 0 | AH9: L1-05 | AI9: =6.75*SIN(2*PI()*(4+0.5)/ROWS(codiciL1)) -> -5.2773625 | AJ9: =6.75*COS(2*PI()*(4+0.5)/ROWS(codiciL1)) -> -4.2085562 | AL9: =IF(AND(ISNUMBER($F9),ISNUMBER($S9)),IF($F9=AL$4,$S9,NA()),NA()) -> #N/A | AM9: =IF(AND(ISNUMBER($F9),ISNUMBER($S9)),IF($F9=AM$4,$S9,NA()),NA()) -> #N/A | AN9: =IF(AND(ISNUMBER($F9),ISNUMBER($S9)),IF($F9=AN$4,$S9,NA()),NA()) -> #N/A | AO9: =IF(AND(ISNUMBER($F9),ISNUMBER($S9)),IF($F9=AO$4,$S9,NA()),NA()) -> #N/A | AP9: =IF(AND(ISNUMBER($F9),ISNUMBER($S9)),IF($F9=AP$4,$S9,NA()),NA()) -> #N/A | AQ9: =IF(AND(ISNUMBER($F9),ISNUMBER($S9)),IF($F9=AQ$4,$S9,NA()),NA()) -> #N/A | AR9: =IF(AND(ISNUMBER($F9),ISNUMBER($S9)),IF($F9=AR$4,$S9,NA()),NA()) -> #N/A | AS9: =IF(AND(ISNUMBER($F9),ISNUMBER($S9)),IF($F9=AS$4,$S9,NA()),NA()) -> 2.3454944 | ... AY9: =IF(AND(ISNUMBER($F9),ISNUMBER($S9)),IF($F9=AY$4,$S9,NA()),NA()) -> #N/A
A10: =IF(Parametri!$H9="","",Parametri!$H9) -> NFR-06 | B10: =IF($A10="","",Parametri!$I9) -> Esfiltrazione di dati tramite strumenti di AI non autorizzati | C10: =IF($A10="","",Parametri!$J9) -> L1-01 | D10: =IF($A10="",NA(),IF(COUNTIFS(RR_ID_Rischio,$A10,RR_Ciclo,cicloCorrente)=0,NA(),SUMIFS(RR_Severity,RR_ID_Rischio,$A10,RR_Ciclo,cicloCorrente))) -> 3 | E10: =IF($A10="",NA(),IF(COUNTIFS(RR_ID_Rischio,$A10,RR_Ciclo,cicloCorrente)=0,NA(),SUMIFS(RR_Probabilita,RR_ID_Rischio,$A10,RR_Ciclo,cicloCorrente))) -> 3 | F10: =IF(AND(ISNUMBER(D10),ISNUMBER(E10)),D10*E10,NA()) -> 9 | G10: =IF($A10="",NA(),IF(COUNTIFS(RR_ID_Rischio,$A10,RR_Ciclo,cicloCorrente)=0,NA(),SUMIFS(RR_Prossimita,RR_ID_Rischio,$A10,RR_Ciclo,cicloCorrente))) -> 3 | H10: =IF(ISNUMBER(G10),INDEX(anniProssimita,G10),NA()) -> 1.5 | I10: =IF($A10="",NA(),moscaX) -> 0.25 | J10: =IF($A10="",NA(),IF(COUNTIFS(AZ_ID_Rischio,$A10,AZ_Ciclo,cicloCorrente,AZ_Stato,"<>Respinta",AZ_Mesi_Orizzonte,">0")=0,moscaYDefault,_xlfn.MAXIFS(AZ_Mesi_Orizzonte,AZ_ID_Rischio,$A10,AZ_Ciclo,cicloCorrente,AZ_Stato,"<>Respinta")/12)) -> 0.5 | K10: =IF(AND(ISNUMBER(H10),ISNUMBER(J10)),H10-(I10+J10),NA()) -> 0.75 | L10: =IF(NOT(ISNUMBER(K10)),"",IF(K10<0,"AGIRE ORA: X+Y > Z",IF(K10<1,"Agire entro l'anno","Margine "&ROUND(K10,1)&IF(ROUND(K10,1)=1," anno"," anni")))) -> Agire entro l'anno | M10: =IF($A10="",NA(),MATCH(C10,codiciL1,0)-1) -> 0 | N10: =IF($A10="",NA(),COUNTIF($C$4:C9,C10)) -> 0 | O10: =IF($A10="",NA(),COUNTIF(ANA_Event_Type,C10)) -> 2 | P10: =IF($A10="",NA(),2*PI()*(M10+(N10+0.5)/O10)/ROWS(codiciL1)) -> 0.22439948 | Q10: =IF(ISNUMBER(K10),MAX(0.6,MIN(6,K10+2)),NA()) -> 2.75 | R10: =IF(AND(ISNUMBER(Q10),ISNUMBER(P10)),Q10*SIN(P10),NA()) -> 0.61193257 | S10: =IF(AND(ISNUMBER(Q10),ISNUMBER(P10)),Q10*COS(P10),NA()) -> 2.6810518 | U10: =2*PI()*5/72 -> 0.43633231 | V10: =2*SIN($U10) -> 0.84523652 | W10: =2*COS($U10) -> 1.8126156 | X10: =3*SIN($U10) -> 1.2678548 | Y10: =3*COS($U10) -> 2.7189234 | Z10: =4*SIN($U10) -> 1.690473 | AA10: =4*COS($U10) -> 3.6252311 | AB10: =5*SIN($U10) -> 2.1130913 | AC10: =5*COS($U10) -> 4.5315389 | AE10: =6.3*SIN(2*PI()*2/ROWS(codiciL1)) -> 6.1420458 | AF10: =6.3*COS(2*PI()*2/ROWS(codiciL1)) -> -1.4018819 | AH10: L1-06 | AI10: =6.75*SIN(2*PI()*(5+0.5)/ROWS(codiciL1)) -> -6.5807634 | AJ10: =6.75*COS(2*PI()*(5+0.5)/ROWS(codiciL1)) -> 1.5020163 | AL10: =IF(AND(ISNUMBER($F10),ISNUMBER($S10)),IF($F10=AL$4,$S10,NA()),NA()) -> #N/A | AM10: =IF(AND(ISNUMBER($F10),ISNUMBER($S10)),IF($F10=AM$4,$S10,NA()),NA()) -> #N/A | AN10: =IF(AND(ISNUMBER($F10),ISNUMBER($S10)),IF($F10=AN$4,$S10,NA()),NA()) -> #N/A | AO10: =IF(AND(ISNUMBER($F10),ISNUMBER($S10)),IF($F10=AO$4,$S10,NA()),NA()) -> #N/A | AP10: =IF(AND(ISNUMBER($F10),ISNUMBER($S10)),IF($F10=AP$4,$S10,NA()),NA()) -> #N/A | AQ10: =IF(AND(ISNUMBER($F10),ISNUMBER($S10)),IF($F10=AQ$4,$S10,NA()),NA()) -> #N/A | AR10: =IF(AND(ISNUMBER($F10),ISNUMBER($S10)),IF($F10=AR$4,$S10,NA()),NA()) -> #N/A | AS10: =IF(AND(ISNUMBER($F10),ISNUMBER($S10)),IF($F10=AS$4,$S10,NA()),NA()) -> 2.6810518 | ... AY10: =IF(AND(ISNUMBER($F10),ISNUMBER($S10)),IF($F10=AY$4,$S10,NA()),NA()) -> #N/A
A11: =IF(Parametri!$H10="","",Parametri!$H10) -> NFR-07 | B11: =IF($A11="","",Parametri!$I10) -> Ransomware presso un fornitore di servizi di pagamento | C11: =IF($A11="","",Parametri!$J10) -> L1-06 | D11: =IF($A11="",NA(),IF(COUNTIFS(RR_ID_Rischio,$A11,RR_Ciclo,cicloCorrente)=0,NA(),SUMIFS(RR_Severity,RR_ID_Rischio,$A11,RR_Ciclo,cicloCorrente))) -> 4 | E11: =IF($A11="",NA(),IF(COUNTIFS(RR_ID_Rischio,$A11,RR_Ciclo,cicloCorrente)=0,NA(),SUMIFS(RR_Probabilita,RR_ID_Rischio,$A11,RR_Ciclo,cicloCorrente))) -> 3 | F11: =IF(AND(ISNUMBER(D11),ISNUMBER(E11)),D11*E11,NA()) -> 12 | G11: =IF($A11="",NA(),IF(COUNTIFS(RR_ID_Rischio,$A11,RR_Ciclo,cicloCorrente)=0,NA(),SUMIFS(RR_Prossimita,RR_ID_Rischio,$A11,RR_Ciclo,cicloCorrente))) -> 3 | H11: =IF(ISNUMBER(G11),INDEX(anniProssimita,G11),NA()) -> 1.5 | I11: =IF($A11="",NA(),moscaX) -> 0.25 | J11: =IF($A11="",NA(),IF(COUNTIFS(AZ_ID_Rischio,$A11,AZ_Ciclo,cicloCorrente,AZ_Stato,"<>Respinta",AZ_Mesi_Orizzonte,">0")=0,moscaYDefault,_xlfn.MAXIFS(AZ_Mesi_Orizzonte,AZ_ID_Rischio,$A11,AZ_Ciclo,cicloCorrente,AZ_Stato,"<>Respinta")/12)) -> 0.5 | K11: =IF(AND(ISNUMBER(H11),ISNUMBER(J11)),H11-(I11+J11),NA()) -> 0.75 | L11: =IF(NOT(ISNUMBER(K11)),"",IF(K11<0,"AGIRE ORA: X+Y > Z",IF(K11<1,"Agire entro l'anno","Margine "&ROUND(K11,1)&IF(ROUND(K11,1)=1," anno"," anni")))) -> Agire entro l'anno | M11: =IF($A11="",NA(),MATCH(C11,codiciL1,0)-1) -> 5 | N11: =IF($A11="",NA(),COUNTIF($C$4:C10,C11)) -> 1 | O11: =IF($A11="",NA(),COUNTIF(ANA_Event_Type,C11)) -> 3 | P11: =IF($A11="",NA(),2*PI()*(M11+(N11+0.5)/O11)/ROWS(codiciL1)) -> 4.9367885 | Q11: =IF(ISNUMBER(K11),MAX(0.6,MIN(6,K11+2)),NA()) -> 2.75 | R11: =IF(AND(ISNUMBER(Q11),ISNUMBER(P11)),Q11*SIN(P11),NA()) -> -2.6810518 | S11: =IF(AND(ISNUMBER(Q11),ISNUMBER(P11)),Q11*COS(P11),NA()) -> 0.61193257 | U11: =2*PI()*6/72 -> 0.52359878 | V11: =2*SIN($U11) -> 1 | W11: =2*COS($U11) -> 1.7320508 | X11: =3*SIN($U11) -> 1.5 | Y11: =3*COS($U11) -> 2.5980762 | Z11: =4*SIN($U11) -> 2 | AA11: =4*COS($U11) -> 3.4641016 | AB11: =5*SIN($U11) -> 2.5 | AC11: =5*COS($U11) -> 4.330127 | AE11: 0 | AF11: 0 | AH11: L1-07 | AI11: =6.75*SIN(2*PI()*(6+0.5)/ROWS(codiciL1)) -> -2.9287152 | AJ11: =6.75*COS(2*PI()*(6+0.5)/ROWS(codiciL1)) -> 6.0815399 | AL11: =IF(AND(ISNUMBER($F11),ISNUMBER($S11)),IF($F11=AL$4,$S11,NA()),NA()) -> #N/A | AM11: =IF(AND(ISNUMBER($F11),ISNUMBER($S11)),IF($F11=AM$4,$S11,NA()),NA()) -> #N/A | AN11: =IF(AND(ISNUMBER($F11),ISNUMBER($S11)),IF($F11=AN$4,$S11,NA()),NA()) -> #N/A | AO11: =IF(AND(ISNUMBER($F11),ISNUMBER($S11)),IF($F11=AO$4,$S11,NA()),NA()) -> #N/A | AP11: =IF(AND(ISNUMBER($F11),ISNUMBER($S11)),IF($F11=AP$4,$S11,NA()),NA()) -> #N/A | AQ11: =IF(AND(ISNUMBER($F11),ISNUMBER($S11)),IF($F11=AQ$4,$S11,NA()),NA()) -> #N/A | AR11: =IF(AND(ISNUMBER($F11),ISNUMBER($S11)),IF($F11=AR$4,$S11,NA()),NA()) -> #N/A | AS11: =IF(AND(ISNUMBER($F11),ISNUMBER($S11)),IF($F11=AS$4,$S11,NA()),NA()) -> #N/A | ... AY11: =IF(AND(ISNUMBER($F11),ISNUMBER($S11)),IF($F11=AY$4,$S11,NA()),NA()) -> #N/A
A12: =IF(Parametri!$H11="","",Parametri!$H11) -> NFR-08 | B12: =IF($A12="","",Parametri!$I11) -> Accessi impropri di dipendenti ai dati dei clienti | C12: =IF($A12="","",Parametri!$J11) -> L1-01 | D12: =IF($A12="",NA(),IF(COUNTIFS(RR_ID_Rischio,$A12,RR_Ciclo,cicloCorrente)=0,NA(),SUMIFS(RR_Severity,RR_ID_Rischio,$A12,RR_Ciclo,cicloCorrente))) -> 3 | E12: =IF($A12="",NA(),IF(COUNTIFS(RR_ID_Rischio,$A12,RR_Ciclo,cicloCorrente)=0,NA(),SUMIFS(RR_Probabilita,RR_ID_Rischio,$A12,RR_Ciclo,cicloCorrente))) -> 2 | F12: =IF(AND(ISNUMBER(D12),ISNUMBER(E12)),D12*E12,NA()) -> 6 | G12: =IF($A12="",NA(),IF(COUNTIFS(RR_ID_Rischio,$A12,RR_Ciclo,cicloCorrente)=0,NA(),SUMIFS(RR_Prossimita,RR_ID_Rischio,$A12,RR_Ciclo,cicloCorrente))) -> 3 | H12: =IF(ISNUMBER(G12),INDEX(anniProssimita,G12),NA()) -> 1.5 | I12: =IF($A12="",NA(),moscaX) -> 0.25 | J12: =IF($A12="",NA(),IF(COUNTIFS(AZ_ID_Rischio,$A12,AZ_Ciclo,cicloCorrente,AZ_Stato,"<>Respinta",AZ_Mesi_Orizzonte,">0")=0,moscaYDefault,_xlfn.MAXIFS(AZ_Mesi_Orizzonte,AZ_ID_Rischio,$A12,AZ_Ciclo,cicloCorrente,AZ_Stato,"<>Respinta")/12)) -> 0.25 | K12: =IF(AND(ISNUMBER(H12),ISNUMBER(J12)),H12-(I12+J12),NA()) -> 1 | L12: =IF(NOT(ISNUMBER(K12)),"",IF(K12<0,"AGIRE ORA: X+Y > Z",IF(K12<1,"Agire entro l'anno","Margine "&ROUND(K12,1)&IF(ROUND(K12,1)=1," anno"," anni")))) -> Margine 1 anno | M12: =IF($A12="",NA(),MATCH(C12,codiciL1,0)-1) -> 0 | N12: =IF($A12="",NA(),COUNTIF($C$4:C11,C12)) -> 1 | O12: =IF($A12="",NA(),COUNTIF(ANA_Event_Type,C12)) -> 2 | P12: =IF($A12="",NA(),2*PI()*(M12+(N12+0.5)/O12)/ROWS(codiciL1)) -> 0.67319843 | Q12: =IF(ISNUMBER(K12),MAX(0.6,MIN(6,K12+2)),NA()) -> 3 | R12: =IF(AND(ISNUMBER(Q12),ISNUMBER(P12)),Q12*SIN(P12),NA()) -> 1.8704694 | S12: =IF(AND(ISNUMBER(Q12),ISNUMBER(P12)),Q12*COS(P12),NA()) -> 2.3454944 | U12: =2*PI()*7/72 -> 0.61086524 | V12: =2*SIN($U12) -> 1.1471529 | W12: =2*COS($U12) -> 1.6383041 | X12: =3*SIN($U12) -> 1.7207293 | Y12: =3*COS($U12) -> 2.4574561 | Z12: =4*SIN($U12) -> 2.2943057 | AA12: =4*COS($U12) -> 3.2766082 | AB12: =5*SIN($U12) -> 2.8678822 | AC12: =5*COS($U12) -> 4.0957602 | AE12: =6.3*SIN(2*PI()*3/ROWS(codiciL1)) -> 2.7334676 | AF12: =6.3*COS(2*PI()*3/ROWS(codiciL1)) -> -5.6761039 | AL12: =IF(AND(ISNUMBER($F12),ISNUMBER($S12)),IF($F12=AL$4,$S12,NA()),NA()) -> #N/A | AM12: =IF(AND(ISNUMBER($F12),ISNUMBER($S12)),IF($F12=AM$4,$S12,NA()),NA()) -> #N/A | AN12: =IF(AND(ISNUMBER($F12),ISNUMBER($S12)),IF($F12=AN$4,$S12,NA()),NA()) -> #N/A | AO12: =IF(AND(ISNUMBER($F12),ISNUMBER($S12)),IF($F12=AO$4,$S12,NA()),NA()) -> #N/A | AP12: =IF(AND(ISNUMBER($F12),ISNUMBER($S12)),IF($F12=AP$4,$S12,NA()),NA()) -> #N/A | AQ12: =IF(AND(ISNUMBER($F12),ISNUMBER($S12)),IF($F12=AQ$4,$S12,NA()),NA()) -> 2.3454944 | AR12: =IF(AND(ISNUMBER($F12),ISNUMBER($S12)),IF($F12=AR$4,$S12,NA()),NA()) -> #N/A | AS12: =IF(AND(ISNUMBER($F12),ISNUMBER($S12)),IF($F12=AS$4,$S12,NA()),NA()) -> #N/A | ... AY12: =IF(AND(ISNUMBER($F12),ISNUMBER($S12)),IF($F12=AY$4,$S12,NA()),NA()) -> #N/A
A13: =IF(Parametri!$H12="","",Parametri!$H12) -> NFR-09 | B13: =IF($A13="","",Parametri!$I12) -> Violazione di sanzioni internazionali tramite triangolazioni | C13: =IF($A13="","",Parametri!$J12) -> L1-04 | D13: =IF($A13="",NA(),IF(COUNTIFS(RR_ID_Rischio,$A13,RR_Ciclo,cicloCorrente)=0,NA(),SUMIFS(RR_Severity,RR_ID_Rischio,$A13,RR_Ciclo,cicloCorrente))) -> 4 | E13: =IF($A13="",NA(),IF(COUNTIFS(RR_ID_Rischio,$A13,RR_Ciclo,cicloCorrente)=0,NA(),SUMIFS(RR_Probabilita,RR_ID_Rischio,$A13,RR_Ciclo,cicloCorrente))) -> 2 | F13: =IF(AND(ISNUMBER(D13),ISNUMBER(E13)),D13*E13,NA()) -> 8 | G13: =IF($A13="",NA(),IF(COUNTIFS(RR_ID_Rischio,$A13,RR_Ciclo,cicloCorrente)=0,NA(),SUMIFS(RR_Prossimita,RR_ID_Rischio,$A13,RR_Ciclo,cicloCorrente))) -> 2 | H13: =IF(ISNUMBER(G13),INDEX(anniProssimita,G13),NA()) -> 2.5 | I13: =IF($A13="",NA(),moscaX) -> 0.25 | J13: =IF($A13="",NA(),IF(COUNTIFS(AZ_ID_Rischio,$A13,AZ_Ciclo,cicloCorrente,AZ_Stato,"<>Respinta",AZ_Mesi_Orizzonte,">0")=0,moscaYDefault,_xlfn.MAXIFS(AZ_Mesi_Orizzonte,AZ_ID_Rischio,$A13,AZ_Ciclo,cicloCorrente,AZ_Stato,"<>Respinta")/12)) -> 1 | K13: =IF(AND(ISNUMBER(H13),ISNUMBER(J13)),H13-(I13+J13),NA()) -> 1.25 | L13: =IF(NOT(ISNUMBER(K13)),"",IF(K13<0,"AGIRE ORA: X+Y > Z",IF(K13<1,"Agire entro l'anno","Margine "&ROUND(K13,1)&IF(ROUND(K13,1)=1," anno"," anni")))) -> Margine 1,3 anni | M13: =IF($A13="",NA(),MATCH(C13,codiciL1,0)-1) -> 3 | N13: =IF($A13="",NA(),COUNTIF($C$4:C12,C13)) -> 1 | O13: =IF($A13="",NA(),COUNTIF(ANA_Event_Type,C13)) -> 3 | P13: =IF($A13="",NA(),2*PI()*(M13+(N13+0.5)/O13)/ROWS(codiciL1)) -> 3.1415927 | Q13: =IF(ISNUMBER(K13),MAX(0.6,MIN(6,K13+2)),NA()) -> 3.25 | R13: =IF(AND(ISNUMBER(Q13),ISNUMBER(P13)),Q13*SIN(P13),NA()) -> 3.9817325e-16 | S13: =IF(AND(ISNUMBER(Q13),ISNUMBER(P13)),Q13*COS(P13),NA()) -> -3.25 | U13: =2*PI()*8/72 -> 0.6981317 | V13: =2*SIN($U13) -> 1.2855752 | W13: =2*COS($U13) -> 1.5320889 | X13: =3*SIN($U13) -> 1.9283628 | Y13: =3*COS($U13) -> 2.2981333 | Z13: =4*SIN($U13) -> 2.5711504 | AA13: =4*COS($U13) -> 3.0641778 | AB13: =5*SIN($U13) -> 3.213938 | AC13: =5*COS($U13) -> 3.8302222 | AE13: 0 | AF13: 0 | AL13: =IF(AND(ISNUMBER($F13),ISNUMBER($S13)),IF($F13=AL$4,$S13,NA()),NA()) -> #N/A | AM13: =IF(AND(ISNUMBER($F13),ISNUMBER($S13)),IF($F13=AM$4,$S13,NA()),NA()) -> #N/A | AN13: =IF(AND(ISNUMBER($F13),ISNUMBER($S13)),IF($F13=AN$4,$S13,NA()),NA()) -> #N/A | AO13: =IF(AND(ISNUMBER($F13),ISNUMBER($S13)),IF($F13=AO$4,$S13,NA()),NA()) -> #N/A | AP13: =IF(AND(ISNUMBER($F13),ISNUMBER($S13)),IF($F13=AP$4,$S13,NA()),NA()) -> #N/A | AQ13: =IF(AND(ISNUMBER($F13),ISNUMBER($S13)),IF($F13=AQ$4,$S13,NA()),NA()) -> #N/A | AR13: =IF(AND(ISNUMBER($F13),ISNUMBER($S13)),IF($F13=AR$4,$S13,NA()),NA()) -> -3.25 | AS13: =IF(AND(ISNUMBER($F13),ISNUMBER($S13)),IF($F13=AS$4,$S13,NA()),NA()) -> #N/A | ... AY13: =IF(AND(ISNUMBER($F13),ISNUMBER($S13)),IF($F13=AY$4,$S13,NA()),NA()) -> #N/A
A14: =IF(Parametri!$H13="","",Parametri!$H13) -> NFR-10 | B14: =IF($A14="","",Parametri!$I13) -> Informazioni errate ai clienti da assistenti di AI generativa | C14: =IF($A14="","",Parametri!$J13) -> L1-04 | D14: =IF($A14="",NA(),IF(COUNTIFS(RR_ID_Rischio,$A14,RR_Ciclo,cicloCorrente)=0,NA(),SUMIFS(RR_Severity,RR_ID_Rischio,$A14,RR_Ciclo,cicloCorrente))) -> 3 | E14: =IF($A14="",NA(),IF(COUNTIFS(RR_ID_Rischio,$A14,RR_Ciclo,cicloCorrente)=0,NA(),SUMIFS(RR_Probabilita,RR_ID_Rischio,$A14,RR_Ciclo,cicloCorrente))) -> 3 | F14: =IF(AND(ISNUMBER(D14),ISNUMBER(E14)),D14*E14,NA()) -> 9 | G14: =IF($A14="",NA(),IF(COUNTIFS(RR_ID_Rischio,$A14,RR_Ciclo,cicloCorrente)=0,NA(),SUMIFS(RR_Prossimita,RR_ID_Rischio,$A14,RR_Ciclo,cicloCorrente))) -> 3 | H14: =IF(ISNUMBER(G14),INDEX(anniProssimita,G14),NA()) -> 1.5 | I14: =IF($A14="",NA(),moscaX) -> 0.25 | J14: =IF($A14="",NA(),IF(COUNTIFS(AZ_ID_Rischio,$A14,AZ_Ciclo,cicloCorrente,AZ_Stato,"<>Respinta",AZ_Mesi_Orizzonte,">0")=0,moscaYDefault,_xlfn.MAXIFS(AZ_Mesi_Orizzonte,AZ_ID_Rischio,$A14,AZ_Ciclo,cicloCorrente,AZ_Stato,"<>Respinta")/12)) -> 0.25 | K14: =IF(AND(ISNUMBER(H14),ISNUMBER(J14)),H14-(I14+J14),NA()) -> 1 | L14: =IF(NOT(ISNUMBER(K14)),"",IF(K14<0,"AGIRE ORA: X+Y > Z",IF(K14<1,"Agire entro l'anno","Margine "&ROUND(K14,1)&IF(ROUND(K14,1)=1," anno"," anni")))) -> Margine 1 anno | M14: =IF($A14="",NA(),MATCH(C14,codiciL1,0)-1) -> 3 | N14: =IF($A14="",NA(),COUNTIF($C$4:C13,C14)) -> 2 | O14: =IF($A14="",NA(),COUNTIF(ANA_Event_Type,C14)) -> 3 | P14: =IF($A14="",NA(),2*PI()*(M14+(N14+0.5)/O14)/ROWS(codiciL1)) -> 3.440792 | Q14: =IF(ISNUMBER(K14),MAX(0.6,MIN(6,K14+2)),NA()) -> 3 | R14: =IF(AND(ISNUMBER(Q14),ISNUMBER(P14)),Q14*SIN(P14),NA()) -> -0.88426552 | S14: =IF(AND(ISNUMBER(Q14),ISNUMBER(P14)),Q14*COS(P14),NA()) -> -2.8667184 | U14: =2*PI()*9/72 -> 0.78539816 | V14: =2*SIN($U14) -> 1.4142136 | W14: =2*COS($U14) -> 1.4142136 | X14: =3*SIN($U14) -> 2.1213203 | Y14: =3*COS($U14) -> 2.1213203 | Z14: =4*SIN($U14) -> 2.8284271 | AA14: =4*COS($U14) -> 2.8284271 | AB14: =5*SIN($U14) -> 3.5355339 | AC14: =5*COS($U14) -> 3.5355339 | AE14: =6.3*SIN(2*PI()*4/ROWS(codiciL1)) -> -2.7334676 | AF14: =6.3*COS(2*PI()*4/ROWS(codiciL1)) -> -5.6761039 | AL14: =IF(AND(ISNUMBER($F14),ISNUMBER($S14)),IF($F14=AL$4,$S14,NA()),NA()) -> #N/A | AM14: =IF(AND(ISNUMBER($F14),ISNUMBER($S14)),IF($F14=AM$4,$S14,NA()),NA()) -> #N/A | AN14: =IF(AND(ISNUMBER($F14),ISNUMBER($S14)),IF($F14=AN$4,$S14,NA()),NA()) -> #N/A | AO14: =IF(AND(ISNUMBER($F14),ISNUMBER($S14)),IF($F14=AO$4,$S14,NA()),NA()) -> #N/A | AP14: =IF(AND(ISNUMBER($F14),ISNUMBER($S14)),IF($F14=AP$4,$S14,NA()),NA()) -> #N/A | AQ14: =IF(AND(ISNUMBER($F14),ISNUMBER($S14)),IF($F14=AQ$4,$S14,NA()),NA()) -> #N/A | AR14: =IF(AND(ISNUMBER($F14),ISNUMBER($S14)),IF($F14=AR$4,$S14,NA()),NA()) -> #N/A | AS14: =IF(AND(ISNUMBER($F14),ISNUMBER($S14)),IF($F14=AS$4,$S14,NA()),NA()) -> -2.8667184 | ... AY14: =IF(AND(ISNUMBER($F14),ISNUMBER($S14)),IF($F14=AY$4,$S14,NA()),NA()) -> #N/A
