Workbook
Name ANA_Anni_Adeguamento: Parametri!$M$4:$M$18
Name ANA_Attenzione_Supervisore: Parametri!$N$4:$N$18
Name ANA_Driver: Parametri!$K$4:$K$18
Name ANA_Event_Type: Parametri!$J$4:$J$18
Name ANA_ID: Parametri!$H$4:$H$18
Name ANA_Nome: Parametri!$I$4:$I$18
Name ANA_Owner: Parametri!$L$4:$L$18
Name anagrafica: Parametri!$H$4:$N$18
Name anniProssimita: Parametri!$B$51:$B$55
Name AZ_Ciclo: Azioni!$A$6:$A$20015
Name AZ_Data_Decisione: Azioni!$K$6:$K$20015
Name AZ_Decisa_Da: Azioni!$L$6:$L$20015
Name AZ_Descrizione: Azioni!$D$6:$D$20015
Name AZ_Dimensione: Azioni!$F$6:$F$20015
Name AZ_ID_Azione: Azioni!$C$6:$C$20015
Name AZ_ID_Rischio: Azioni!$B$6:$B$20015
Name AZ_Mesi_Orizzonte: Azioni!$H$6:$H$20015
Name AZ_Orizzonte: Azioni!$G$6:$G$20015
Name AZ_Owner: Azioni!$E$6:$E$20015
Name AZ_Razionale: Azioni!$I$6:$I$20015
Name AZ_Stato: Azioni!$J$6:$J$20015
Name AZ_Validazione: Azioni!$M$6:$M$20015
Name capienzaElencoKRI: 150
Name capienzaKRICorrenti: 60
Name capienzaPianoAzioni: 150
Name cicliTrend: Parametri!$B$20:$B$27
Name cicloCorrente: Parametri!$B$15
Name cicloMeno2: Parametri!$B$17
Name cicloPrecedente: Parametri!$B$16
Name classificaAgire: OFFSET(Classifica!$V$5,0,0,MAX(1,COUNT(Classifica!$D$5:$D$19)),1)
Name classificaEntro: OFFSET(Classifica!$W$5,0,0,MAX(1,COUNT(Classifica!$D$5:$D$19)),1)
Name classificaEtichette: OFFSET(Classifica!$K$5,0,0,MAX(1,COUNT(Classifica!$D$5:$D$19)),1)
Name classificaID: OFFSET(Classifica!$B$5,0,0,MAX(1,COUNT(Classifica!$D$5:$D$19)),1)
Name classificaMargine: OFFSET(Classifica!$X$5,0,0,MAX(1,COUNT(Classifica!$D$5:$D$19)),1)
Name codiciL1: Parametri!$E$4:$E$10
Name coperturaAnagrafica: Registro!$D$5
Name coperturaValutati: Registro!$G$5
Name decisioniDaPrendere: Registro!$D$4
Name deltaEtichette: OFFSET(Delta!$AN$5,0,0,MAX(1,COUNT(Delta!$AK$5:$AK$19)),1)
Name deltaGiu: OFFSET(Delta!$AP$5,0,0,MAX(1,COUNT(Delta!$AK$5:$AK$19)),1)
Name deltaMotivi: Delta!$K$6:$Q$20
Name deltaSu: OFFSET(Delta!$AO$5,0,0,MAX(1,COUNT(Delta!$AK$5:$AK$19)),1)
Name deltaZero: OFFSET(Delta!$AQ$5,0,0,MAX(1,COUNT(Delta!$AK$5:$AK$19)),1)
Name elencoKRI: OFFSET(Indicatori!$AB$12,0,0,MAX(1,COUNTIF(Indicatori!$AB$12:$AB$161,"?*")),1)
Name etichettaCiclo: Parametri!$B$57
Name inizioFinestra4: Parametri!$B$31
Name KRI_Chiave: KRI!$R$6:$R$20037
Name KRI_Ciclo: KRI!$A$6:$A$20037
Name KRI_Ciclo_Aggiornamento: KRI!$P$6:$P$20037
Name KRI_Ciclo_Definizione: KRI!$O$6:$O$20037
Name KRI_Data_Rilevazione: KRI!$J$6:$J$20037
Name KRI_Fonte_Dati: KRI!$F$6:$F$20037
Name KRI_Fonte_Rilevazione: KRI!$K$6:$K$20037
Name KRI_ID_Rischio: KRI!$C$6:$C$20037
Name KRI_In_Vigore: KRI!$N$6:$N$20037
Name KRI_KRI_ID: KRI!$B$6:$B$20037
Name KRI_Nome: KRI!$D$6:$D$20037
Name KRI_Nota_Rilevazione: KRI!$L$6:$L$20037
Name KRI_Razionale: KRI!$Q$6:$Q$20037
Name KRI_Soglia_Allerta: KRI!$H$6:$H$20037

Sheet Guida
A1: ="Horizon Scan NFR — Guida: come si usa questo workbook · "&etichettaCiclo -> Horizon Scan NFR — Guida: come si usa questo workbook · Ciclo 2026Q3 · dati al 30/09/2026 · validato · Uso interno
A3: A COSA SERVE
A4: Horizon Scan NFR: registro dei rischi non finanziari emergenti della Banca. Ogni trimestre gli agenti valutano i rischi, lo script controlla e scrive qui, il validatore decide; i fogli da Quadro a Metodologia sono il report al comitato, le schede dei rischi un file a parte. Ogni foglio ha in testa (riga 2) chi lo aggiorna, cosa contiene e come si legge; il foglio Dizionario spiega ogni dato.
A6: CHI AGGIORNA COSA E QUANDO
A7: Foglio | B7: Settimanale · lunedi', A3 | C7: Trimestrale · A1, poi A5 | D7: Validatore · dopo il trimestre | E7: A che cosa serve
A8: REPORT AL COMITATO
A9: Quadro | C9: commento di A1, sintesi di A5, numeri | D9: stato della validazione; avviso rettifiche | E9: prima pagina: il quadro e il perche'
A10: Classifica | C10: score e urgenza | D10: valori validati | E10: rischi per score; lente di Mosca
A11: Radar_Mosca | C11: score, azioni (Y) | D11: anni di adeguamento, attenzione del supervisore | E11: quanto presto agire, quanto e' grande
A12: Matrice | C12: Probabilita e Severity | D12: valori validati | E12: gravita' dei rischi
A13: Delta | C13: confronto con il ciclo prima | E13: che cosa e' cambiato e perche'
A14: Metodologia | D14: pesi e parametri (Parametri) | E14: come si leggono i numeri
A15: LAVORO
A16: Registro | B16: segnali netti (colonna S) | C16: dimensioni, score, urgenza, KRI | D16: righe 4-5 | E16: il ciclo corrente, un rischio per riga
A17: Storico, Indicatori | C17: si aggiornano | E17: score negli ultimi cicli; KRI del ciclo e storia di uno
A18: Notizie | B18: si aggiorna | E18: pressione delle notizie, aree non presidiate
A19: Piano_azioni | C19: azioni proposte da A1 | D19: decisione; Stato In corso/Completata (foglio Azioni) | E19: tutte le azioni e la loro scadenza
A20: Validazione | B20: righe delle notizie | C20: righe di rischi, KRI, azioni | D20: DECISIONI, a mano | E20: unico foglio da compilare
A21: Parametri | B21: settimana corrente | C21: ciclo corrente; anagrafica H-K | D21: celle gialle | E21: pesi, soglie, urgenza, anagrafica
A22: Dizionario | E22: ogni dato: chi lo scrive, come si calcola
A23: DATI (solo lo script)
A24: RiskRegister | C24: valutazioni di A1 | D24: valori validati | E24: una riga per rischio per ciclo
A25: Azioni | C25: azioni proposte da A1 | D25: delibera; Stato In corso/Completata a mano | E25: una riga per azione
A26: KRI | C26: KRI e valori riletti da A1 | D26: rettifiche, KRI respinti | E26: storico, una riga per KRI per ciclo
A27: NewsLog | B27: notizie valutate da A3 | D27: rettifiche (facoltative) | E27: una riga per notizia
A28: Sintesi_Cicli | C28: commento di A1 e di A5 | E28: una riga per ciclo
A29: FILE A PARTE
A30: Schede_<ciclo>.xlsx | C30: testi di A6 dopo la validazione | D30: dati validati | E30: una scheda per rischio (comando schede)
A31: Giornaliero: la raccolta delle notizie riempie la cartella News_Inbox, non questo file. A4 (pareri su richiesta, in qualsiasi momento) non scrive qui: se un parere suggerisce di rivedere un rischio, la via e' il ciclo trimestrale successivo.
A33: QUANDO SI LANCIANO A5 E A6
A34: A5 (challenger): ogni trimestre, subito dopo A1 e prima del comando trimestrale, allegando SOLO l'output di A1 e Baseline_corrente.json. Senza l'esito di A5 lo script non scrive il ciclo. Di nuovo ogni volta che A1 viene rifatto: l'approvazione vale solo per l'output esaminato. Non si lancia per le settimane, per A4 ne' dopo la validazione.
A35: A6 (schede): dopo la validazione del trimestre. Il comando schede-input prepara i dati validati; A6 scrive i testi; il comando schede li controlla e produce Schede_<ciclo>.xlsx. Senza A6 il comando schede produce comunque le schede con i testi del registro.
A37: DOVE SI SCRIVE A MANO (solo qui)
A38: Validazione: le decisioni sulle proposte degli agenti (istruzioni e criteri in testa al foglio), poi il comando valida.
A39: Parametri, celle gialle: pesi, soglie, urgenza (decisione della funzione di rischio); nell'anagrafica Owner, anni di adeguamento e attenzione del supervisore (decisi dal validatore, restano da un ciclo all'altro).
A40: Azioni, colonna Stato: avanzamento di un'azione approvata (In corso, Completata); il Piano_azioni si aggiorna da solo.
A41: Indicatori, cella N4: il KRI di cui guardare la storia.
A42: Tutto il resto lo scrive lo script o e' una formula: non modificarlo.
A44: REGOLE
A45: 1. Score composito, urgenza e stato dei KRI li calcola il foglio. Nessun agente li fornisce.
...

Sheet Quadro
A1: ="Horizon Scan NFR — Quadro d'insieme · "&etichettaCiclo -> Horizon Scan NFR — Quadro d'insieme · Ciclo 2026Q3 · dati al 30/09/2026 · validato · Uso interno
A2: CICLO TRIMESTRALE — A1 valuta i rischi, A5 controlla la valutazione, il validatore la conferma o la rettifica. Come si legge: i cinque riquadri in alto dicono se il ciclo e' completo e validato; poi le priorita' per score, la gravita' (matrice) e l'urgenza (radar). A pagina 2 il commento di A1 (scritto prima della validazione: se dopo ci sono state rettifiche lo dice la riga "Dopo il commento" e valgono i numeri validati) e i rischi segnalati, con il perche' calcolato dal foglio. Metodo e scale: Metodologia; ogni dato: Dizionario.
BH3: Appoggio del grafico: non modificare | CM3: vigilanza | CN3: vigilanza | CO3: vigilanza | CP3: vigilanza | CQ3: vigilanza | CR3: vigilanza | CS3: vigilanza | CT3: vigilanza | CU3: vigilanza | CV3: vigilanza | CW3: vigilanza | CX3: vigilanza | CY3: vigilanza | CZ3: vigilanza
A4: Rischi valutati | D4: Da affrontare subito | G4: Variati · nuovi | J4: KRI in rosso | M4: Validazione | BY4: 1 | BZ4: 2 | CA4: 3 | CB4: 4 | CC4: 5 | CD4: 6 | CE4: 8 | CF4: 9 | CG4: 10 | CH4: 12 | CI4: 15 | CJ4: 16 | CK4: 20 | CL4: 25 | CM4: 1 | CN4: 2 | CO4: 3 | CP4: 4 | CQ4: 5 | CR4: 6 | CS4: 8 | CT4: 9 | CU4: 10 | CV4: 12 | CW4: 15 | CX4: 16 | CY4: 20 | CZ4: 25
A5: =coperturaValutati -> 12 | D5: =COUNTIF(Radar_Mosca!$L$5:$L$19,"AGIRE ORA*") -> 2 | G5: =COUNTIFS(RR_Ciclo,cicloCorrente,RR_Esito,"Variato")&" · "&COUNTIFS(RR_Ciclo,cicloCorrente,RR_Esito,"Nuovo") -> 3 · 0 | J5: =COUNTIFS(KRI_Ciclo,cicloCorrente,KRI_In_Vigore,"Sì",KRI_Stato,"Rosso") -> 0 | M5: =IF(decisioniDaPrendere>0,decisioniDaPrendere,"✓") -> ✓ | T5: =IF(LEFT(Radar_Mosca!$L$5,9)="AGIRE ORA",Radar_Mosca!$A$5,"") -> NFR-01 | BH5: =2*PI()*0/72 -> 0 | BI5: =2*SIN($BH5) -> 0 | BJ5: =2*COS($BH5) -> 2 | BK5: =3*SIN($BH5) -> 0 | BL5: =3*COS($BH5) -> 3 | BM5: =4*SIN($BH5) -> 0 | BN5: =4*COS($BH5) -> 4 | BO5: =5*SIN($BH5) -> 0 | BP5: =5*COS($BH5) -> 5 | BR5: 0 | BS5: 0 | BU5: L1-01 Frode interna | BV5: =6.95*SIN(2*PI()*(0+0.5)/ROWS(codiciL1)) -> 3.015492 | BW5: =6.95*COS(2*PI()*(0+0.5)/ROWS(codiciL1)) -> 6.2617336 | BY5: =IF(AND(ISNUMBER(Radar_Mosca!$F5),ISNUMBER(Radar_Mosca!$S5)),IF(AND(Radar_Mosca!$F5=BY$4,Radar_Mosca!$T5<>"Sì"),Radar_Mosca!$S5,NA()),NA()) -> #N/A | BZ5: =IF(AND(ISNUMBER(Radar_Mosca!$F5),ISNUMBER(Radar_Mosca!$S5)),IF(AND(Radar_Mosca!$F5=BZ$4,Radar_Mosca!$T5<>"Sì"),Radar_Mosca!$S5,NA()),NA()) -> #N/A | CA5: =IF(AND(ISNUMBER(Radar_Mosca!$F5),ISNUMBER(Radar_Mosca!$S5)),IF(AND(Radar_Mosca!$F5=CA$4,Radar_Mosca!$T5<>"Sì"),Radar_Mosca!$S5,NA()),NA()) -> #N/A | CB5: =IF(AND(ISNUMBER(Radar_Mosca!$F5),ISNUMBER(Radar_Mosca!$S5)),IF(AND(Radar_Mosca!$F5=CB$4,Radar_Mosca!$T5<>"Sì"),Radar_Mosca!$S5,NA()),NA()) -> #N/A | CC5: =IF(AND(ISNUMBER(Radar_Mosca!$F5),ISNUMBER(Radar_Mosca!$S5)),IF(AND(Radar_Mosca!$F5=CC$4,Radar_Mosca!$T5<>"Sì"),Radar_Mosca!$S5,NA()),NA()) -> #N/A | CD5: =IF(AND(ISNUMBER(Radar_Mosca!$F5),ISNUMBER(Radar_Mosca!$S5)),IF(AND(Radar_Mosca!$F5=CD$4,Radar_Mosca!$T5<>"Sì"),Radar_Mosca!$S5,NA()),NA()) -> #N/A | CE5: =IF(AND(ISNUMBER(Radar_Mosca!$F5),ISNUMBER(Radar_Mosca!$S5)),IF(AND(Radar_Mosca!$F5=CE$4,Radar_Mosca!$T5<>"Sì"),Radar_Mosca!$S5,NA()),NA()) -> #N/A | CF5: =IF(AND(ISNUMBER(Radar_Mosca!$F5),ISNUMBER(Radar_Mosca!$S5)),IF(AND(Radar_Mosca!$F5=CF$4,Radar_Mosca!$T5<>"Sì"),Radar_Mosca!$S5,NA()),NA()) -> #N/A | ... CL5: =IF(AND(ISNUMBER(Radar_Mosca!$F5),ISNUMBER(Radar_Mosca!$S5)),IF(AND(Radar_Mosca!$F5=CL$4,Radar_Mosca!$T5<>"Sì"),Radar_Mosca!$S5,NA()),NA()) -> #N/A | CM5: =IF(AND(ISNUMBER(Radar_Mosca!$F5),ISNUMBER(Radar_Mosca!$S5)),IF(AND(Radar_Mosca!$F5=CM$4,Radar_Mosca!$T5="Sì"),Radar_Mosca!$S5,NA()),NA()) -> #N/A | CN5: =IF(AND(ISNUMBER(Radar_Mosca!$F5),ISNUMBER(Radar_Mosca!$S5)),IF(AND(Radar_Mosca!$F5=CN$4,Radar_Mosca!$T5="Sì"),Radar_Mosca!$S5,NA()),NA()) -> #N/A | CO5: =IF(AND(ISNUMBER(Radar_Mosca!$F5),ISNUMBER(Radar_Mosca!$S5)),IF(AND(Radar_Mosca!$F5=CO$4,Radar_Mosca!$T5="Sì"),Radar_Mosca!$S5,NA()),NA()) -> #N/A | CP5: =IF(AND(ISNUMBER(Radar_Mosca!$F5),ISNUMBER(Radar_Mosca!$S5)),IF(AND(Radar_Mosca!$F5=CP$4,Radar_Mosca!$T5="Sì"),Radar_Mosca!$S5,NA()),NA()) -> #N/A | CQ5: =IF(AND(ISNUMBER(Radar_Mosca!$F5),ISNUMBER(Radar_Mosca!$S5)),IF(AND(Radar_Mosca!$F5=CQ$4,Radar_Mosca!$T5="Sì"),Radar_Mosca!$S5,NA()),NA()) -> #N/A | CR5: =IF(AND(ISNUMBER(Radar_Mosca!$F5),ISNUMBER(Radar_Mosca!$S5)),IF(AND(Radar_Mosca!$F5=CR$4,Radar_Mosca!$T5="Sì"),Radar_Mosca!$S5,NA()),NA()) -> #N/A | CS5: =IF(AND(ISNUMBER(Radar_Mosca!$F5),ISNUMBER(Radar_Mosca!$S5)),IF(AND(Radar_Mosca!$F5=CS$4,Radar_Mosca!$T5="Sì"),Radar_Mosca!$S5,NA()),NA()) -> #N/A | CT5: =IF(AND(ISNUMBER(Radar_Mosca!$F5),ISNUMBER(Radar_Mosca!$S5)),IF(AND(Radar_Mosca!$F5=CT$4,Radar_Mosca!$T5="Sì"),Radar_Mosca!$S5,NA()),NA()) -> #N/A | ... CZ5: =IF(AND(ISNUMBER(Radar_Mosca!$F5),ISNUMBER(Radar_Mosca!$S5)),IF(AND(Radar_Mosca!$F5=CZ$4,Radar_Mosca!$T5="Sì"),Radar_Mosca!$S5,NA()),NA()) -> #N/A | DA5: =IF(ISNUMBER(Radar_Mosca!$R5),Radar_Mosca!$R5,NA()) -> 1.7061238 | DB5: =IF(Radar_Mosca!$A5="","",MID(Radar_Mosca!$A5,5,3)) -> 01 | DC5: =IF(ISNUMBER(Radar_Mosca!$S5),Radar_Mosca!$S5,NA()) -> 0.38941163 | DD5: attenzione supervisore | DE5: -6.9 | DF5: -6.35
A6: ="su "&coperturaAnagrafica&" in anagrafica · "&IF(coperturaValutati=coperturaAnagrafica,"completo","INCOMPLETO") -> su 12 in anagrafica · completo | D6: =IF(D5=0,"nessun rischio con X + Y > Z","X + Y > Z: "&_xlfn.TEXTJOIN(", ",TRUE,$T$5:$T$19)) -> X + Y > Z: NFR-01, NFR-11 | G6: ="rispetto al "&cicloPrecedente -> rispetto al 2026Q2 | J6: ="su "&COUNTIFS(KRI_Ciclo,cicloCorrente,KRI_In_Vigore,"Sì")&" in vigore" -> su 36 in vigore | M6: =IF(decisioniDaPrendere>0,"decisioni da prendere: ciclo non validato","ciclo validato") -> ciclo validato | T6: =IF(LEFT(Radar_Mosca!$L$6,9)="AGIRE ORA",Radar_Mosca!$A$6,"") | BH6: =2*PI()*1/72 -> 0.087266463 | BI6: =2*SIN($BH6) -> 0.17431149 | BJ6: =2*COS($BH6) -> 1.9923894 | BK6: =3*SIN($BH6) -> 0.26146723 | BL6: =3*COS($BH6) -> 2.9885841 | BM6: =4*SIN($BH6) -> 0.34862297 | BN6: =4*COS($BH6) -> 3.9847788 | BO6: =5*SIN($BH6) -> 0.43577871 | BP6: =5*COS($BH6) -> 4.9809735 | BR6: =6.3*SIN(2*PI()*0/ROWS(codiciL1)) -> 0 | BS6: =6.3*COS(2*PI()*0/ROWS(codiciL1)) -> 6.3 | BU6: L1-02 Frode esterna | BV6: =6.95*SIN(2*PI()*(1+0.5)/ROWS(codiciL1)) -> 6.775749 | BW6: =6.95*COS(2*PI()*(1+0.5)/ROWS(codiciL1)) -> 1.5465205 | BY6: =IF(AND(ISNUMBER(Radar_Mosca!$F6),ISNUMBER(Radar_Mosca!$S6)),IF(AND(Radar_Mosca!$F6=BY$4,Radar_Mosca!$T6<>"Sì"),Radar_Mosca!$S6,NA()),NA()) -> #N/A | BZ6: =IF(AND(ISNUMBER(Radar_Mosca!$F6),ISNUMBER(Radar_Mosca!$S6)),IF(AND(Radar_Mosca!$F6=BZ$4,Radar_Mosca!$T6<>"Sì"),Radar_Mosca!$S6,NA()),NA()) -> #N/A | CA6: =IF(AND(ISNUMBER(Radar_Mosca!$F6),ISNUMBER(Radar_Mosca!$S6)),IF(AND(Radar_Mosca!$F6=CA$4,Radar_Mosca!$T6<>"Sì"),Radar_Mosca!$S6,NA()),NA()) -> #N/A | CB6: =IF(AND(ISNUMBER(Radar_Mosca!$F6),ISNUMBER(Radar_Mosca!$S6)),IF(AND(Radar_Mosca!$F6=CB$4,Radar_Mosca!$T6<>"Sì"),Radar_Mosca!$S6,NA()),NA()) -> #N/A | CC6: =IF(AND(ISNUMBER(Radar_Mosca!$F6),ISNUMBER(Radar_Mosca!$S6)),IF(AND(Radar_Mosca!$F6=CC$4,Radar_Mosca!$T6<>"Sì"),Radar_Mosca!$S6,NA()),NA()) -> #N/A | CD6: =IF(AND(ISNUMBER(Radar_Mosca!$F6),ISNUMBER(Radar_Mosca!$S6)),IF(AND(Radar_Mosca!$F6=CD$4,Radar_Mosca!$T6<>"Sì"),Radar_Mosca!$S6,NA()),NA()) -> #N/A | CE6: =IF(AND(ISNUMBER(Radar_Mosca!$F6),ISNUMBER(Radar_Mosca!$S6)),IF(AND(Radar_Mosca!$F6=CE$4,Radar_Mosca!$T6<>"Sì"),Radar_Mosca!$S6,NA()),NA()) -> #N/A | CF6: =IF(AND(ISNUMBER(Radar_Mosca!$F6),ISNUMBER(Radar_Mosca!$S6)),IF(AND(Radar_Mosca!$F6=CF$4,Radar_Mosca!$T6<>"Sì"),Radar_Mosca!$S6,NA()),NA()) -> #N/A | ... CL6: =IF(AND(ISNUMBER(Radar_Mosca!$F6),ISNUMBER(Radar_Mosca!$S6)),IF(AND(Radar_Mosca!$F6=CL$4,Radar_Mosca!$T6<>"Sì"),Radar_Mosca!$S6,NA()),NA()) -> #N/A | CM6: =IF(AND(ISNUMBER(Radar_Mosca!$F6),ISNUMBER(Radar_Mosca!$S6)),IF(AND(Radar_Mosca!$F6=CM$4,Radar_Mosca!$T6="Sì"),Radar_Mosca!$S6,NA()),NA()) -> #N/A | CN6: =IF(AND(ISNUMBER(Radar_Mosca!$F6),ISNUMBER(Radar_Mosca!$S6)),IF(AND(Radar_Mosca!$F6=CN$4,Radar_Mosca!$T6="Sì"),Radar_Mosca!$S6,NA()),NA()) -> #N/A | CO6: =IF(AND(ISNUMBER(Radar_Mosca!$F6),ISNUMBER(Radar_Mosca!$S6)),IF(AND(Radar_Mosca!$F6=CO$4,Radar_Mosca!$T6="Sì"),Radar_Mosca!$S6,NA()),NA()) -> #N/A | CP6: =IF(AND(ISNUMBER(Radar_Mosca!$F6),ISNUMBER(Radar_Mosca!$S6)),IF(AND(Radar_Mosca!$F6=CP$4,Radar_Mosca!$T6="Sì"),Radar_Mosca!$S6,NA()),NA()) -> #N/A | CQ6: =IF(AND(ISNUMBER(Radar_Mosca!$F6),ISNUMBER(Radar_Mosca!$S6)),IF(AND(Radar_Mosca!$F6=CQ$4,Radar_Mosca!$T6="Sì"),Radar_Mosca!$S6,NA()),NA()) -> #N/A | CR6: =IF(AND(ISNUMBER(Radar_Mosca!$F6),ISNUMBER(Radar_Mosca!$S6)),IF(AND(Radar_Mosca!$F6=CR$4,Radar_Mosca!$T6="Sì"),Radar_Mosca!$S6,NA()),NA()) -> #N/A | CS6: =IF(AND(ISNUMBER(Radar_Mosca!$F6),ISNUMBER(Radar_Mosca!$S6)),IF(AND(Radar_Mosca!$F6=CS$4,Radar_Mosca!$T6="Sì"),Radar_Mosca!$S6,NA()),NA()) -> -0.16814271 | CT6: =IF(AND(ISNUMBER(Radar_Mosca!$F6),ISNUMBER(Radar_Mosca!$S6)),IF(AND(Radar_Mosca!$F6=CT$4,Radar_Mosca!$T6="Sì"),Radar_Mosca!$S6,NA()),NA()) -> #N/A | ... CZ6: =IF(AND(ISNUMBER(Radar_Mosca!$F6),ISNUMBER(Radar_Mosca!$S6)),IF(AND(Radar_Mosca!$F6=CZ$4,Radar_Mosca!$T6="Sì"),Radar_Mosca!$S6,NA()),NA()) -> #N/A | DA6: =IF(ISNUMBER(Radar_Mosca!$R6),Radar_Mosca!$R6,NA()) -> -2.2437085 | DB6: =IF(Radar_Mosca!$A6="","",MID(Radar_Mosca!$A6,5,3)) -> 02 | DC6: =IF(ISNUMBER(Radar_Mosca!$S6),Radar_Mosca!$S6,NA()) -> -0.16814271 | DD6: AGIRE ORA: X + Y > Z | DE6: -7.35 | DF6: -7.35
T7: =IF(LEFT(Radar_Mosca!$L$7,9)="AGIRE ORA",Radar_Mosca!$A$7,"") | BH7: =2*PI()*2/72 -> 0.17453293 | BI7: =2*SIN($BH7) -> 0.34729636 | BJ7: =2*COS($BH7) -> 1.9696155 | BK7: =3*SIN($BH7) -> 0.52094453 | BL7: =3*COS($BH7) -> 2.9544233 | BM7: =4*SIN($BH7) -> 0.69459271 | BN7: =4*COS($BH7) -> 3.939231 | BO7: =5*SIN($BH7) -> 0.86824089 | BP7: =5*COS($BH7) -> 4.9240388 | BR7: 0 | BS7: 0 | BU7: L1-03 Impiego e sicurezza | BV7: =6.95*SIN(2*PI()*(2+0.5)/ROWS(codiciL1)) -> 5.4337288 | BW7: =6.95*COS(2*PI()*(2+0.5)/ROWS(codiciL1)) -> -4.3332541 | BY7: =IF(AND(ISNUMBER(Radar_Mosca!$F7),ISNUMBER(Radar_Mosca!$S7)),IF(AND(Radar_Mosca!$F7=BY$4,Radar_Mosca!$T7<>"Sì"),Radar_Mosca!$S7,NA()),NA()) -> #N/A | BZ7: =IF(AND(ISNUMBER(Radar_Mosca!$F7),ISNUMBER(Radar_Mosca!$S7)),IF(AND(Radar_Mosca!$F7=BZ$4,Radar_Mosca!$T7<>"Sì"),Radar_Mosca!$S7,NA()),NA()) -> #N/A | CA7: =IF(AND(ISNUMBER(Radar_Mosca!$F7),ISNUMBER(Radar_Mosca!$S7)),IF(AND(Radar_Mosca!$F7=CA$4,Radar_Mosca!$T7<>"Sì"),Radar_Mosca!$S7,NA()),NA()) -> #N/A | CB7: =IF(AND(ISNUMBER(Radar_Mosca!$F7),ISNUMBER(Radar_Mosca!$S7)),IF(AND(Radar_Mosca!$F7=CB$4,Radar_Mosca!$T7<>"Sì"),Radar_Mosca!$S7,NA()),NA()) -> #N/A | CC7: =IF(AND(ISNUMBER(Radar_Mosca!$F7),ISNUMBER(Radar_Mosca!$S7)),IF(AND(Radar_Mosca!$F7=CC$4,Radar_Mosca!$T7<>"Sì"),Radar_Mosca!$S7,NA()),NA()) -> #N/A | CD7: =IF(AND(ISNUMBER(Radar_Mosca!$F7),ISNUMBER(Radar_Mosca!$S7)),IF(AND(Radar_Mosca!$F7=CD$4,Radar_Mosca!$T7<>"Sì"),Radar_Mosca!$S7,NA()),NA()) -> #N/A | CE7: =IF(AND(ISNUMBER(Radar_Mosca!$F7),ISNUMBER(Radar_Mosca!$S7)),IF(AND(Radar_Mosca!$F7=CE$4,Radar_Mosca!$T7<>"Sì"),Radar_Mosca!$S7,NA()),NA()) -> #N/A | CF7: =IF(AND(ISNUMBER(Radar_Mosca!$F7),ISNUMBER(Radar_Mosca!$S7)),IF(AND(Radar_Mosca!$F7=CF$4,Radar_Mosca!$T7<>"Sì"),Radar_Mosca!$S7,NA()),NA()) -> -1.9111456 | ... CL7: =IF(AND(ISNUMBER(Radar_Mosca!$F7),ISNUMBER(Radar_Mosca!$S7)),IF(AND(Radar_Mosca!$F7=CL$4,Radar_Mosca!$T7<>"Sì"),Radar_Mosca!$S7,NA()),NA()) -> #N/A | CM7: =IF(AND(ISNUMBER(Radar_Mosca!$F7),ISNUMBER(Radar_Mosca!$S7)),IF(AND(Radar_Mosca!$F7=CM$4,Radar_Mosca!$T7="Sì"),Radar_Mosca!$S7,NA()),NA()) -> #N/A | CN7: =IF(AND(ISNUMBER(Radar_Mosca!$F7),ISNUMBER(Radar_Mosca!$S7)),IF(AND(Radar_Mosca!$F7=CN$4,Radar_Mosca!$T7="Sì"),Radar_Mosca!$S7,NA()),NA()) -> #N/A | CO7: =IF(AND(ISNUMBER(Radar_Mosca!$F7),ISNUMBER(Radar_Mosca!$S7)),IF(AND(Radar_Mosca!$F7=CO$4,Radar_Mosca!$T7="Sì"),Radar_Mosca!$S7,NA()),NA()) -> #N/A | CP7: =IF(AND(ISNUMBER(Radar_Mosca!$F7),ISNUMBER(Radar_Mosca!$S7)),IF(AND(Radar_Mosca!$F7=CP$4,Radar_Mosca!$T7="Sì"),Radar_Mosca!$S7,NA()),NA()) -> #N/A | CQ7: =IF(AND(ISNUMBER(Radar_Mosca!$F7),ISNUMBER(Radar_Mosca!$S7)),IF(AND(Radar_Mosca!$F7=CQ$4,Radar_Mosca!$T7="Sì"),Radar_Mosca!$S7,NA()),NA()) -> #N/A | CR7: =IF(AND(ISNUMBER(Radar_Mosca!$F7),ISNUMBER(Radar_Mosca!$S7)),IF(AND(Radar_Mosca!$F7=CR$4,Radar_Mosca!$T7="Sì"),Radar_Mosca!$S7,NA()),NA()) -> #N/A | CS7: =IF(AND(ISNUMBER(Radar_Mosca!$F7),ISNUMBER(Radar_Mosca!$S7)),IF(AND(Radar_Mosca!$F7=CS$4,Radar_Mosca!$T7="Sì"),Radar_Mosca!$S7,NA()),NA()) -> #N/A | CT7: =IF(AND(ISNUMBER(Radar_Mosca!$F7),ISNUMBER(Radar_Mosca!$S7)),IF(AND(Radar_Mosca!$F7=CT$4,Radar_Mosca!$T7="Sì"),Radar_Mosca!$S7,NA()),NA()) -> #N/A | ... CZ7: =IF(AND(ISNUMBER(Radar_Mosca!$F7),ISNUMBER(Radar_Mosca!$S7)),IF(AND(Radar_Mosca!$F7=CZ$4,Radar_Mosca!$T7="Sì"),Radar_Mosca!$S7,NA()),NA()) -> #N/A | DA7: =IF(ISNUMBER(Radar_Mosca!$R7),Radar_Mosca!$R7,NA()) -> 0.58951035 | DB7: =IF(Radar_Mosca!$A7="","",MID(Radar_Mosca!$A7,5,3)) -> 03 | DC7: =IF(ISNUMBER(Radar_Mosca!$S7),Radar_Mosca!$S7,NA()) -> -1.9111456 | DE7: -6.45 | DF7: -7.35
A8: Priorita' — primi cinque per score composito | J8: Gravita': Probabilita x Severity | T8: =IF(LEFT(Radar_Mosca!$L$8,9)="AGIRE ORA",Radar_Mosca!$A$8,"") | BH8: =2*PI()*3/72 -> 0.26179939 | BI8: =2*SIN($BH8) -> 0.51763809 | BJ8: =2*COS($BH8) -> 1.9318517 | BK8: =3*SIN($BH8) -> 0.77645714 | BL8: =3*COS($BH8) -> 2.8977775 | BM8: =4*SIN($BH8) -> 1.0352762 | BN8: =4*COS($BH8) -> 3.8637033 | BO8: =5*SIN($BH8) -> 1.2940952 | BP8: =5*COS($BH8) -> 4.8296291 | BR8: =6.3*SIN(2*PI()*1/ROWS(codiciL1)) -> 4.9255383 | BS8: =6.3*COS(2*PI()*1/ROWS(codiciL1)) -> 3.9279858 | BU8: L1-04 Clientela e prodotti | BV8: =6.95*SIN(2*PI()*(3+0.5)/ROWS(codiciL1)) -> 8.5147818e-16 | BW8: =6.95*COS(2*PI()*(3+0.5)/ROWS(codiciL1)) -> -6.95 | BY8: =IF(AND(ISNUMBER(Radar_Mosca!$F8),ISNUMBER(Radar_Mosca!$S8)),IF(AND(Radar_Mosca!$F8=BY$4,Radar_Mosca!$T8<>"Sì"),Radar_Mosca!$S8,NA()),NA()) -> #N/A | BZ8: =IF(AND(ISNUMBER(Radar_Mosca!$F8),ISNUMBER(Radar_Mosca!$S8)),IF(AND(Radar_Mosca!$F8=BZ$4,Radar_Mosca!$T8<>"Sì"),Radar_Mosca!$S8,NA()),NA()) -> #N/A | CA8: =IF(AND(ISNUMBER(Radar_Mosca!$F8),ISNUMBER(Radar_Mosca!$S8)),IF(AND(Radar_Mosca!$F8=CA$4,Radar_Mosca!$T8<>"Sì"),Radar_Mosca!$S8,NA()),NA()) -> #N/A | CB8: =IF(AND(ISNUMBER(Radar_Mosca!$F8),ISNUMBER(Radar_Mosca!$S8)),IF(AND(Radar_Mosca!$F8=CB$4,Radar_Mosca!$T8<>"Sì"),Radar_Mosca!$S8,NA()),NA()) -> #N/A | CC8: =IF(AND(ISNUMBER(Radar_Mosca!$F8),ISNUMBER(Radar_Mosca!$S8)),IF(AND(Radar_Mosca!$F8=CC$4,Radar_Mosca!$T8<>"Sì"),Radar_Mosca!$S8,NA()),NA()) -> #N/A | CD8: =IF(AND(ISNUMBER(Radar_Mosca!$F8),ISNUMBER(Radar_Mosca!$S8)),IF(AND(Radar_Mosca!$F8=CD$4,Radar_Mosca!$T8<>"Sì"),Radar_Mosca!$S8,NA()),NA()) -> #N/A | CE8: =IF(AND(ISNUMBER(Radar_Mosca!$F8),ISNUMBER(Radar_Mosca!$S8)),IF(AND(Radar_Mosca!$F8=CE$4,Radar_Mosca!$T8<>"Sì"),Radar_Mosca!$S8,NA()),NA()) -> #N/A | CF8: =IF(AND(ISNUMBER(Radar_Mosca!$F8),ISNUMBER(Radar_Mosca!$S8)),IF(AND(Radar_Mosca!$F8=CF$4,Radar_Mosca!$T8<>"Sì"),Radar_Mosca!$S8,NA()),NA()) -> -1.714597 | ... CL8: =IF(AND(ISNUMBER(Radar_Mosca!$F8),ISNUMBER(Radar_Mosca!$S8)),IF(AND(Radar_Mosca!$F8=CL$4,Radar_Mosca!$T8<>"Sì"),Radar_Mosca!$S8,NA()),NA()) -> #N/A | CM8: =IF(AND(ISNUMBER(Radar_Mosca!$F8),ISNUMBER(Radar_Mosca!$S8)),IF(AND(Radar_Mosca!$F8=CM$4,Radar_Mosca!$T8="Sì"),Radar_Mosca!$S8,NA()),NA()) -> #N/A | CN8: =IF(AND(ISNUMBER(Radar_Mosca!$F8),ISNUMBER(Radar_Mosca!$S8)),IF(AND(Radar_Mosca!$F8=CN$4,Radar_Mosca!$T8="Sì"),Radar_Mosca!$S8,NA()),NA()) -> #N/A | CO8: =IF(AND(ISNUMBER(Radar_Mosca!$F8),ISNUMBER(Radar_Mosca!$S8)),IF(AND(Radar_Mosca!$F8=CO$4,Radar_Mosca!$T8="Sì"),Radar_Mosca!$S8,NA()),NA()) -> #N/A | CP8: =IF(AND(ISNUMBER(Radar_Mosca!$F8),ISNUMBER(Radar_Mosca!$S8)),IF(AND(Radar_Mosca!$F8=CP$4,Radar_Mosca!$T8="Sì"),Radar_Mosca!$S8,NA()),NA()) -> #N/A | CQ8: =IF(AND(ISNUMBER(Radar_Mosca!$F8),ISNUMBER(Radar_Mosca!$S8)),IF(AND(Radar_Mosca!$F8=CQ$4,Radar_Mosca!$T8="Sì"),Radar_Mosca!$S8,NA()),NA()) -> #N/A | CR8: =IF(AND(ISNUMBER(Radar_Mosca!$F8),ISNUMBER(Radar_Mosca!$S8)),IF(AND(Radar_Mosca!$F8=CR$4,Radar_Mosca!$T8="Sì"),Radar_Mosca!$S8,NA()),NA()) -> #N/A | CS8: =IF(AND(ISNUMBER(Radar_Mosca!$F8),ISNUMBER(Radar_Mosca!$S8)),IF(AND(Radar_Mosca!$F8=CS$4,Radar_Mosca!$T8="Sì"),Radar_Mosca!$S8,NA()),NA()) -> #N/A | CT8: =IF(AND(ISNUMBER(Radar_Mosca!$F8),ISNUMBER(Radar_Mosca!$S8)),IF(AND(Radar_Mosca!$F8=CT$4,Radar_Mosca!$T8="Sì"),Radar_Mosca!$S8,NA()),NA()) -> #N/A | ... CZ8: =IF(AND(ISNUMBER(Radar_Mosca!$F8),ISNUMBER(Radar_Mosca!$S8)),IF(AND(Radar_Mosca!$F8=CZ$4,Radar_Mosca!$T8="Sì"),Radar_Mosca!$S8,NA()),NA()) -> #N/A | DA8: =IF(ISNUMBER(Radar_Mosca!$R8),Radar_Mosca!$R8,NA()) -> -2.1500366 | DB8: =IF(Radar_Mosca!$A8="","",MID(Radar_Mosca!$A8,5,3)) -> 04 | DC8: =IF(ISNUMBER(Radar_Mosca!$S8),Radar_Mosca!$S8,NA()) -> -1.714597 | DD8: Area del cerchio = P x I | DE8: 4.4 | DF8: -5.6
A9: # | B9: Rischio | F9: Score | G9: Variazione | H9: Urgenza | J9: P \ S | K9: 1 | L9: 2 | M9: 3 | N9: 4 | O9: 5 | T9: =IF(LEFT(Radar_Mosca!$L$9,9)="AGIRE ORA",Radar_Mosca!$A$9,"") | BH9: =2*PI()*4/72 -> 0.34906585 | BI9: =2*SIN($BH9) -> 0.68404029 | BJ9: =2*COS($BH9) -> 1.8793852 | BK9: =3*SIN($BH9) -> 1.0260604 | BL9: =3*COS($BH9) -> 2.8190779 | BM9: =4*SIN($BH9) -> 1.3680806 | BN9: =4*COS($BH9) -> 3.7587705 | BO9: =5*SIN($BH9) -> 1.7101007 | BP9: =5*COS($BH9) -> 4.6984631 | BR9: 0 | BS9: 0 | BU9: L1-05 Danni a beni materiali | BV9: =6.95*SIN(2*PI()*(4+0.5)/ROWS(codiciL1)) -> -5.4337288 | BW9: =6.95*COS(2*PI()*(4+0.5)/ROWS(codiciL1)) -> -4.3332541 | BY9: =IF(AND(ISNUMBER(Radar_Mosca!$F9),ISNUMBER(Radar_Mosca!$S9)),IF(AND(Radar_Mosca!$F9=BY$4,Radar_Mosca!$T9<>"Sì"),Radar_Mosca!$S9,NA()),NA()) -> #N/A | BZ9: =IF(AND(ISNUMBER(Radar_Mosca!$F9),ISNUMBER(Radar_Mosca!$S9)),IF(AND(Radar_Mosca!$F9=BZ$4,Radar_Mosca!$T9<>"Sì"),Radar_Mosca!$S9,NA()),NA()) -> #N/A | CA9: =IF(AND(ISNUMBER(Radar_Mosca!$F9),ISNUMBER(Radar_Mosca!$S9)),IF(AND(Radar_Mosca!$F9=CA$4,Radar_Mosca!$T9<>"Sì"),Radar_Mosca!$S9,NA()),NA()) -> #N/A | CB9: =IF(AND(ISNUMBER(Radar_Mosca!$F9),ISNUMBER(Radar_Mosca!$S9)),IF(AND(Radar_Mosca!$F9=CB$4,Radar_Mosca!$T9<>"Sì"),Radar_Mosca!$S9,NA()),NA()) -> #N/A | CC9: =IF(AND(ISNUMBER(Radar_Mosca!$F9),ISNUMBER(Radar_Mosca!$S9)),IF(AND(Radar_Mosca!$F9=CC$4,Radar_Mosca!$T9<>"Sì"),Radar_Mosca!$S9,NA()),NA()) -> #N/A | CD9: =IF(AND(ISNUMBER(Radar_Mosca!$F9),ISNUMBER(Radar_Mosca!$S9)),IF(AND(Radar_Mosca!$F9=CD$4,Radar_Mosca!$T9<>"Sì"),Radar_Mosca!$S9,NA()),NA()) -> #N/A | CE9: =IF(AND(ISNUMBER(Radar_Mosca!$F9),ISNUMBER(Radar_Mosca!$S9)),IF(AND(Radar_Mosca!$F9=CE$4,Radar_Mosca!$T9<>"Sì"),Radar_Mosca!$S9,NA()),NA()) -> #N/A | CF9: =IF(AND(ISNUMBER(Radar_Mosca!$F9),ISNUMBER(Radar_Mosca!$S9)),IF(AND(Radar_Mosca!$F9=CF$4,Radar_Mosca!$T9<>"Sì"),Radar_Mosca!$S9,NA()),NA()) -> 2.3454944 | ... CL9: =IF(AND(ISNUMBER(Radar_Mosca!$F9),ISNUMBER(Radar_Mosca!$S9)),IF(AND(Radar_Mosca!$F9=CL$4,Radar_Mosca!$T9<>"Sì"),Radar_Mosca!$S9,NA()),NA()) -> #N/A | CM9: =IF(AND(ISNUMBER(Radar_Mosca!$F9),ISNUMBER(Radar_Mosca!$S9)),IF(AND(Radar_Mosca!$F9=CM$4,Radar_Mosca!$T9="Sì"),Radar_Mosca!$S9,NA()),NA()) -> #N/A | CN9: =IF(AND(ISNUMBER(Radar_Mosca!$F9),ISNUMBER(Radar_Mosca!$S9)),IF(AND(Radar_Mosca!$F9=CN$4,Radar_Mosca!$T9="Sì"),Radar_Mosca!$S9,NA()),NA()) -> #N/A | CO9: =IF(AND(ISNUMBER(Radar_Mosca!$F9),ISNUMBER(Radar_Mosca!$S9)),IF(AND(Radar_Mosca!$F9=CO$4,Radar_Mosca!$T9="Sì"),Radar_Mosca!$S9,NA()),NA()) -> #N/A | CP9: =IF(AND(ISNUMBER(Radar_Mosca!$F9),ISNUMBER(Radar_Mosca!$S9)),IF(AND(Radar_Mosca!$F9=CP$4,Radar_Mosca!$T9="Sì"),Radar_Mosca!$S9,NA()),NA()) -> #N/A | CQ9: =IF(AND(ISNUMBER(Radar_Mosca!$F9),ISNUMBER(Radar_Mosca!$S9)),IF(AND(Radar_Mosca!$F9=CQ$4,Radar_Mosca!$T9="Sì"),Radar_Mosca!$S9,NA()),NA()) -> #N/A | CR9: =IF(AND(ISNUMBER(Radar_Mosca!$F9),ISNUMBER(Radar_Mosca!$S9)),IF(AND(Radar_Mosca!$F9=CR$4,Radar_Mosca!$T9="Sì"),Radar_Mosca!$S9,NA()),NA()) -> #N/A | CS9: =IF(AND(ISNUMBER(Radar_Mosca!$F9),ISNUMBER(Radar_Mosca!$S9)),IF(AND(Radar_Mosca!$F9=CS$4,Radar_Mosca!$T9="Sì"),Radar_Mosca!$S9,NA()),NA()) -> #N/A | CT9: =IF(AND(ISNUMBER(Radar_Mosca!$F9),ISNUMBER(Radar_Mosca!$S9)),IF(AND(Radar_Mosca!$F9=CT$4,Radar_Mosca!$T9="Sì"),Radar_Mosca!$S9,NA()),NA()) -> #N/A | ... CZ9: =IF(AND(ISNUMBER(Radar_Mosca!$F9),ISNUMBER(Radar_Mosca!$S9)),IF(AND(Radar_Mosca!$F9=CZ$4,Radar_Mosca!$T9="Sì"),Radar_Mosca!$S9,NA()),NA()) -> #N/A | DA9: =IF(ISNUMBER(Radar_Mosca!$R9),Radar_Mosca!$R9,NA()) -> -1.8704694 | DB9: =IF(Radar_Mosca!$A9="","",MID(Radar_Mosca!$A9,5,3)) -> 05 | DC9: =IF(ISNUMBER(Radar_Mosca!$S9),Radar_Mosca!$S9,NA()) -> 2.3454944 | DD9: 4 | DE9: 3.5 | DF9: -6.6
A10: =Classifica!$A$5 -> 1 | B10: =IF(Classifica!$B$5="","",Classifica!$B$5&" "&Classifica!$C$5&IFERROR(IF(INDEX(ANA_Attenzione_Supervisore,Classifica!$U$5)="Sì"," ◆",""),"")) -> NFR-01 Frodi su pagamenti istantanei abilitate da AI generativa ◆ | F10: =IF(Classifica!$B$5="","",Classifica!$D$5) -> 3.8 | G10: =IF(Classifica!$B$5="","",IF(ISNUMBER(Classifica!$F$5),Classifica!$F$5,"nuovo")) -> 0 | H10: =IF(Classifica!$B$5="","",IF(LEFT(Classifica!$H$5,9)="AGIRE ORA","AGIRE ORA",IF(LEFT(Classifica!$H$5,11)="Agire entro","Entro l'anno",Classifica!$H$5))) -> AGIRE ORA | J10: 5 | K10: =SUBSTITUTE(SUBSTITUTE(Matrice!C5," ◆",""),"NFR-","") | L10: =SUBSTITUTE(SUBSTITUTE(Matrice!D5," ◆",""),"NFR-","") | M10: =SUBSTITUTE(SUBSTITUTE(Matrice!E5," ◆",""),"NFR-","") | N10: =SUBSTITUTE(SUBSTITUTE(Matrice!F5," ◆",""),"NFR-","") | O10: =SUBSTITUTE(SUBSTITUTE(Matrice!G5," ◆",""),"NFR-","") | T10: =IF(LEFT(Radar_Mosca!$L$10,9)="AGIRE ORA",Radar_Mosca!$A$10,"") | BH10: =2*PI()*5/72 -> 0.43633231 | BI10: =2*SIN($BH10) -> 0.84523652 | BJ10: =2*COS($BH10) -> 1.8126156 | BK10: =3*SIN($BH10) -> 1.2678548 | BL10: =3*COS($BH10) -> 2.7189234 | BM10: =4*SIN($BH10) -> 1.690473 | BN10: =4*COS($BH10) -> 3.6252311 | BO10: =5*SIN($BH10) -> 2.1130913 | BP10: =5*COS($BH10) -> 4.5315389 | BR10: =6.3*SIN(2*PI()*2/ROWS(codiciL1)) -> 6.1420458 | BS10: =6.3*COS(2*PI()*2/ROWS(codiciL1)) -> -1.4018819 | BU10: L1-06 Interruzione e sistemi | BV10: =6.95*SIN(2*PI()*(5+0.5)/ROWS(codiciL1)) -> -6.775749 | BW10: =6.95*COS(2*PI()*(5+0.5)/ROWS(codiciL1)) -> 1.5465205 | BY10: =IF(AND(ISNUMBER(Radar_Mosca!$F10),ISNUMBER(Radar_Mosca!$S10)),IF(AND(Radar_Mosca!$F10=BY$4,Radar_Mosca!$T10<>"Sì"),Radar_Mosca!$S10,NA()),NA()) -> #N/A | BZ10: =IF(AND(ISNUMBER(Radar_Mosca!$F10),ISNUMBER(Radar_Mosca!$S10)),IF(AND(Radar_Mosca!$F10=BZ$4,Radar_Mosca!$T10<>"Sì"),Radar_Mosca!$S10,NA()),NA()) -> #N/A | CA10: =IF(AND(ISNUMBER(Radar_Mosca!$F10),ISNUMBER(Radar_Mosca!$S10)),IF(AND(Radar_Mosca!$F10=CA$4,Radar_Mosca!$T10<>"Sì"),Radar_Mosca!$S10,NA()),NA()) -> #N/A | CB10: =IF(AND(ISNUMBER(Radar_Mosca!$F10),ISNUMBER(Radar_Mosca!$S10)),IF(AND(Radar_Mosca!$F10=CB$4,Radar_Mosca!$T10<>"Sì"),Radar_Mosca!$S10,NA()),NA()) -> #N/A | CC10: =IF(AND(ISNUMBER(Radar_Mosca!$F10),ISNUMBER(Radar_Mosca!$S10)),IF(AND(Radar_Mosca!$F10=CC$4,Radar_Mosca!$T10<>"Sì"),Radar_Mosca!$S10,NA()),NA()) -> #N/A | CD10: =IF(AND(ISNUMBER(Radar_Mosca!$F10),ISNUMBER(Radar_Mosca!$S10)),IF(AND(Radar_Mosca!$F10=CD$4,Radar_Mosca!$T10<>"Sì"),Radar_Mosca!$S10,NA()),NA()) -> #N/A | CE10: =IF(AND(ISNUMBER(Radar_Mosca!$F10),ISNUMBER(Radar_Mosca!$S10)),IF(AND(Radar_Mosca!$F10=CE$4,Radar_Mosca!$T10<>"Sì"),Radar_Mosca!$S10,NA()),NA()) -> #N/A | CF10: =IF(AND(ISNUMBER(Radar_Mosca!$F10),ISNUMBER(Radar_Mosca!$S10)),IF(AND(Radar_Mosca!$F10=CF$4,Radar_Mosca!$T10<>"Sì"),Radar_Mosca!$S10,NA()),NA()) -> 2.6810518 | ... CL10: =IF(AND(ISNUMBER(Radar_Mosca!$F10),ISNUMBER(Radar_Mosca!$S10)),IF(AND(Radar_Mosca!$F10=CL$4,Radar_Mosca!$T10<>"Sì"),Radar_Mosca!$S10,NA()),NA()) -> #N/A | CM10: =IF(AND(ISNUMBER(Radar_Mosca!$F10),ISNUMBER(Radar_Mosca!$S10)),IF(AND(Radar_Mosca!$F10=CM$4,Radar_Mosca!$T10="Sì"),Radar_Mosca!$S10,NA()),NA()) -> #N/A | CN10: =IF(AND(ISNUMBER(Radar_Mosca!$F10),ISNUMBER(Radar_Mosca!$S10)),IF(AND(Radar_Mosca!$F10=CN$4,Radar_Mosca!$T10="Sì"),Radar_Mosca!$S10,NA()),NA()) -> #N/A | CO10: =IF(AND(ISNUMBER(Radar_Mosca!$F10),ISNUMBER(Radar_Mosca!$S10)),IF(AND(Radar_Mosca!$F10=CO$4,Radar_Mosca!$T10="Sì"),Radar_Mosca!$S10,NA()),NA()) -> #N/A | CP10: =IF(AND(ISNUMBER(Radar_Mosca!$F10),ISNUMBER(Radar_Mosca!$S10)),IF(AND(Radar_Mosca!$F10=CP$4,Radar_Mosca!$T10="Sì"),Radar_Mosca!$S10,NA()),NA()) -> #N/A | CQ10: =IF(AND(ISNUMBER(Radar_Mosca!$F10),ISNUMBER(Radar_Mosca!$S10)),IF(AND(Radar_Mosca!$F10=CQ$4,Radar_Mosca!$T10="Sì"),Radar_Mosca!$S10,NA()),NA()) -> #N/A | CR10: =IF(AND(ISNUMBER(Radar_Mosca!$F10),ISNUMBER(Radar_Mosca!$S10)),IF(AND(Radar_Mosca!$F10=CR$4,Radar_Mosca!$T10="Sì"),Radar_Mosca!$S10,NA()),NA()) -> #N/A | CS10: =IF(AND(ISNUMBER(Radar_Mosca!$F10),ISNUMBER(Radar_Mosca!$S10)),IF(AND(Radar_Mosca!$F10=CS$4,Radar_Mosca!$T10="Sì"),Radar_Mosca!$S10,NA()),NA()) -> #N/A | CT10: =IF(AND(ISNUMBER(Radar_Mosca!$F10),ISNUMBER(Radar_Mosca!$S10)),IF(AND(Radar_Mosca!$F10=CT$4,Radar_Mosca!$T10="Sì"),Radar_Mosca!$S10,NA()),NA()) -> #N/A | ... CZ10: =IF(AND(ISNUMBER(Radar_Mosca!$F10),ISNUMBER(Radar_Mosca!$S10)),IF(AND(Radar_Mosca!$F10=CZ$4,Radar_Mosca!$T10="Sì"),Radar_Mosca!$S10,NA()),NA()) -> #N/A | DA10: =IF(ISNUMBER(Radar_Mosca!$R10),Radar_Mosca!$R10,NA()) -> 0.61193257 | DB10: =IF(Radar_Mosca!$A10="","",MID(Radar_Mosca!$A10,5,3)) -> 06 | DC10: =IF(ISNUMBER(Radar_Mosca!$S10),Radar_Mosca!$S10,NA()) -> 2.6810518 | DD10: 12 | DE10: 4.8 | DF10: -6.6
A11: =Classifica!$A$6 -> 2 | B11: =IF(Classifica!$B$6="","",Classifica!$B$6&" "&Classifica!$C$6&IFERROR(IF(INDEX(ANA_Attenzione_Supervisore,Classifica!$U$6)="Sì"," ◆",""),"")) -> NFR-07 Ransomware presso un fornitore di servizi di pagamento ◆ | F11: =IF(Classifica!$B$6="","",Classifica!$D$6) -> 3.6 | G11: =IF(Classifica!$B$6="","",IF(ISNUMBER(Classifica!$F$6),Classifica!$F$6,"nuovo")) -> 0 | H11: =IF(Classifica!$B$6="","",IF(LEFT(Classifica!$H$6,9)="AGIRE ORA","AGIRE ORA",IF(LEFT(Classifica!$H$6,11)="Agire entro","Entro l'anno",Classifica!$H$6))) -> Entro l'anno | J11: 4 | K11: =SUBSTITUTE(SUBSTITUTE(Matrice!C6," ◆",""),"NFR-","") | L11: =SUBSTITUTE(SUBSTITUTE(Matrice!D6," ◆",""),"NFR-","") | M11: =SUBSTITUTE(SUBSTITUTE(Matrice!E6," ◆",""),"NFR-","") -> 12 | N11: =SUBSTITUTE(SUBSTITUTE(Matrice!F6," ◆",""),"NFR-","") -> 01 | O11: =SUBSTITUTE(SUBSTITUTE(Matrice!G6," ◆",""),"NFR-","") | T11: =IF(LEFT(Radar_Mosca!$L$11,9)="AGIRE ORA",Radar_Mosca!$A$11,"") | BH11: =2*PI()*6/72 -> 0.52359878 | BI11: =2*SIN($BH11) -> 1 | BJ11: =2*COS($BH11) -> 1.7320508 | BK11: =3*SIN($BH11) -> 1.5 | BL11: =3*COS($BH11) -> 2.5980762 | BM11: =4*SIN($BH11) -> 2 | BN11: =4*COS($BH11) -> 3.4641016 | BO11: =5*SIN($BH11) -> 2.5 | BP11: =5*COS($BH11) -> 4.330127 | BR11: 0 | BS11: 0 | BU11: L1-07 Processi | BV11: =6.95*SIN(2*PI()*(6+0.5)/ROWS(codiciL1)) -> -3.015492 | BW11: =6.95*COS(2*PI()*(6+0.5)/ROWS(codiciL1)) -> 6.2617336 | BY11: =IF(AND(ISNUMBER(Radar_Mosca!$F11),ISNUMBER(Radar_Mosca!$S11)),IF(AND(Radar_Mosca!$F11=BY$4,Radar_Mosca!$T11<>"Sì"),Radar_Mosca!$S11,NA()),NA()) -> #N/A | BZ11: =IF(AND(ISNUMBER(Radar_Mosca!$F11),ISNUMBER(Radar_Mosca!$S11)),IF(AND(Radar_Mosca!$F11=BZ$4,Radar_Mosca!$T11<>"Sì"),Radar_Mosca!$S11,NA()),NA()) -> #N/A | CA11: =IF(AND(ISNUMBER(Radar_Mosca!$F11),ISNUMBER(Radar_Mosca!$S11)),IF(AND(Radar_Mosca!$F11=CA$4,Radar_Mosca!$T11<>"Sì"),Radar_Mosca!$S11,NA()),NA()) -> #N/A | CB11: =IF(AND(ISNUMBER(Radar_Mosca!$F11),ISNUMBER(Radar_Mosca!$S11)),IF(AND(Radar_Mosca!$F11=CB$4,Radar_Mosca!$T11<>"Sì"),Radar_Mosca!$S11,NA()),NA()) -> #N/A | CC11: =IF(AND(ISNUMBER(Radar_Mosca!$F11),ISNUMBER(Radar_Mosca!$S11)),IF(AND(Radar_Mosca!$F11=CC$4,Radar_Mosca!$T11<>"Sì"),Radar_Mosca!$S11,NA()),NA()) -> #N/A | CD11: =IF(AND(ISNUMBER(Radar_Mosca!$F11),ISNUMBER(Radar_Mosca!$S11)),IF(AND(Radar_Mosca!$F11=CD$4,Radar_Mosca!$T11<>"Sì"),Radar_Mosca!$S11,NA()),NA()) -> #N/A | CE11: =IF(AND(ISNUMBER(Radar_Mosca!$F11),ISNUMBER(Radar_Mosca!$S11)),IF(AND(Radar_Mosca!$F11=CE$4,Radar_Mosca!$T11<>"Sì"),Radar_Mosca!$S11,NA()),NA()) -> #N/A | CF11: =IF(AND(ISNUMBER(Radar_Mosca!$F11),ISNUMBER(Radar_Mosca!$S11)),IF(AND(Radar_Mosca!$F11=CF$4,Radar_Mosca!$T11<>"Sì"),Radar_Mosca!$S11,NA()),NA()) -> #N/A | ... CL11: =IF(AND(ISNUMBER(Radar_Mosca!$F11),ISNUMBER(Radar_Mosca!$S11)),IF(AND(Radar_Mosca!$F11=CL$4,Radar_Mosca!$T11<>"Sì"),Radar_Mosca!$S11,NA()),NA()) -> #N/A | CM11: =IF(AND(ISNUMBER(Radar_Mosca!$F11),ISNUMBER(Radar_Mosca!$S11)),IF(AND(Radar_Mosca!$F11=CM$4,Radar_Mosca!$T11="Sì"),Radar_Mosca!$S11,NA()),NA()) -> #N/A | CN11: =IF(AND(ISNUMBER(Radar_Mosca!$F11),ISNUMBER(Radar_Mosca!$S11)),IF(AND(Radar_Mosca!$F11=CN$4,Radar_Mosca!$T11="Sì"),Radar_Mosca!$S11,NA()),NA()) -> #N/A | CO11: =IF(AND(ISNUMBER(Radar_Mosca!$F11),ISNUMBER(Radar_Mosca!$S11)),IF(AND(Radar_Mosca!$F11=CO$4,Radar_Mosca!$T11="Sì"),Radar_Mosca!$S11,NA()),NA()) -> #N/A | CP11: =IF(AND(ISNUMBER(Radar_Mosca!$F11),ISNUMBER(Radar_Mosca!$S11)),IF(AND(Radar_Mosca!$F11=CP$4,Radar_Mosca!$T11="Sì"),Radar_Mosca!$S11,NA()),NA()) -> #N/A | CQ11: =IF(AND(ISNUMBER(Radar_Mosca!$F11),ISNUMBER(Radar_Mosca!$S11)),IF(AND(Radar_Mosca!$F11=CQ$4,Radar_Mosca!$T11="Sì"),Radar_Mosca!$S11,NA()),NA()) -> #N/A | CR11: =IF(AND(ISNUMBER(Radar_Mosca!$F11),ISNUMBER(Radar_Mosca!$S11)),IF(AND(Radar_Mosca!$F11=CR$4,Radar_Mosca!$T11="Sì"),Radar_Mosca!$S11,NA()),NA()) -> #N/A | CS11: =IF(AND(ISNUMBER(Radar_Mosca!$F11),ISNUMBER(Radar_Mosca!$S11)),IF(AND(Radar_Mosca!$F11=CS$4,Radar_Mosca!$T11="Sì"),Radar_Mosca!$S11,NA()),NA()) -> #N/A | CT11: =IF(AND(ISNUMBER(Radar_Mosca!$F11),ISNUMBER(Radar_Mosca!$S11)),IF(AND(Radar_Mosca!$F11=CT$4,Radar_Mosca!$T11="Sì"),Radar_Mosca!$S11,NA()),NA()) -> #N/A | ... CZ11: =IF(AND(ISNUMBER(Radar_Mosca!$F11),ISNUMBER(Radar_Mosca!$S11)),IF(AND(Radar_Mosca!$F11=CZ$4,Radar_Mosca!$T11="Sì"),Radar_Mosca!$S11,NA()),NA()) -> #N/A | DA11: =IF(ISNUMBER(Radar_Mosca!$R11),Radar_Mosca!$R11,NA()) -> -2.6810518 | DB11: =IF(Radar_Mosca!$A11="","",MID(Radar_Mosca!$A11,5,3)) -> 07 | DC11: =IF(ISNUMBER(Radar_Mosca!$S11),Radar_Mosca!$S11,NA()) -> 0.61193257 | DD11: 25 | DE11: 6.5 | DF11: -6.6
A12: =Classifica!$A$7 -> 3 | B12: =IF(Classifica!$B$7="","",Classifica!$B$7&" "&Classifica!$C$7&IFERROR(IF(INDEX(ANA_Attenzione_Supervisore,Classifica!$U$7)="Sì"," ◆",""),"")) -> NFR-12 Errori operativi nei pagamenti istantanei obbligatori | F12: =IF(Classifica!$B$7="","",Classifica!$D$7) -> 3.5 | G12: =IF(Classifica!$B$7="","",IF(ISNUMBER(Classifica!$F$7),Classifica!$F$7,"nuovo")) -> 0 | H12: =IF(Classifica!$B$7="","",IF(LEFT(Classifica!$H$7,9)="AGIRE ORA","AGIRE ORA",IF(LEFT(Classifica!$H$7,11)="Agire entro","Entro l'anno",Classifica!$H$7))) -> Entro l'anno | J12: 3 | K12: =SUBSTITUTE(SUBSTITUTE(Matrice!C7," ◆",""),"NFR-","") | L12: =SUBSTITUTE(SUBSTITUTE(Matrice!D7," ◆",""),"NFR-","") | M12: =SUBSTITUTE(SUBSTITUTE(Matrice!E7," ◆",""),"NFR-","") -> 03 04 05 06 10 11 | N12: =SUBSTITUTE(SUBSTITUTE(Matrice!F7," ◆",""),"NFR-","") -> 07 | O12: =SUBSTITUTE(SUBSTITUTE(Matrice!G7," ◆",""),"NFR-","") | T12: =IF(LEFT(Radar_Mosca!$L$12,9)="AGIRE ORA",Radar_Mosca!$A$12,"") | BH12: =2*PI()*7/72 -> 0.61086524 | BI12: =2*SIN($BH12) -> 1.1471529 | BJ12: =2*COS($BH12) -> 1.6383041 | BK12: =3*SIN($BH12) -> 1.7207293 | BL12: =3*COS($BH12) -> 2.4574561 | BM12: =4*SIN($BH12) -> 2.2943057 | BN12: =4*COS($BH12) -> 3.2766082 | BO12: =5*SIN($BH12) -> 2.8678822 | BP12: =5*COS($BH12) -> 4.0957602 | BR12: =6.3*SIN(2*PI()*3/ROWS(codiciL1)) -> 2.7334676 | BS12: =6.3*COS(2*PI()*3/ROWS(codiciL1)) -> -5.6761039 | BY12: =IF(AND(ISNUMBER(Radar_Mosca!$F12),ISNUMBER(Radar_Mosca!$S12)),IF(AND(Radar_Mosca!$F12=BY$4,Radar_Mosca!$T12<>"Sì"),Radar_Mosca!$S12,NA()),NA()) -> #N/A | BZ12: =IF(AND(ISNUMBER(Radar_Mosca!$F12),ISNUMBER(Radar_Mosca!$S12)),IF(AND(Radar_Mosca!$F12=BZ$4,Radar_Mosca!$T12<>"Sì"),Radar_Mosca!$S12,NA()),NA()) -> #N/A | CA12: =IF(AND(ISNUMBER(Radar_Mosca!$F12),ISNUMBER(Radar_Mosca!$S12)),IF(AND(Radar_Mosca!$F12=CA$4,Radar_Mosca!$T12<>"Sì"),Radar_Mosca!$S12,NA()),NA()) -> #N/A | CB12: =IF(AND(ISNUMBER(Radar_Mosca!$F12),ISNUMBER(Radar_Mosca!$S12)),IF(AND(Radar_Mosca!$F12=CB$4,Radar_Mosca!$T12<>"Sì"),Radar_Mosca!$S12,NA()),NA()) -> #N/A | CC12: =IF(AND(ISNUMBER(Radar_Mosca!$F12),ISNUMBER(Radar_Mosca!$S12)),IF(AND(Radar_Mosca!$F12=CC$4,Radar_Mosca!$T12<>"Sì"),Radar_Mosca!$S12,NA()),NA()) -> #N/A | CD12: =IF(AND(ISNUMBER(Radar_Mosca!$F12),ISNUMBER(Radar_Mosca!$S12)),IF(AND(Radar_Mosca!$F12=CD$4,Radar_Mosca!$T12<>"Sì"),Radar_Mosca!$S12,NA()),NA()) -> 1.7591208 | CE12: =IF(AND(ISNUMBER(Radar_Mosca!$F12),ISNUMBER(Radar_Mosca!$S12)),IF(AND(Radar_Mosca!$F12=CE$4,Radar_Mosca!$T12<>"Sì"),Radar_Mosca!$S12,NA()),NA()) -> #N/A | CF12: =IF(AND(ISNUMBER(Radar_Mosca!$F12),ISNUMBER(Radar_Mosca!$S12)),IF(AND(Radar_Mosca!$F12=CF$4,Radar_Mosca!$T12<>"Sì"),Radar_Mosca!$S12,NA()),NA()) -> #N/A | ... CL12: =IF(AND(ISNUMBER(Radar_Mosca!$F12),ISNUMBER(Radar_Mosca!$S12)),IF(AND(Radar_Mosca!$F12=CL$4,Radar_Mosca!$T12<>"Sì"),Radar_Mosca!$S12,NA()),NA()) -> #N/A | CM12: =IF(AND(ISNUMBER(Radar_Mosca!$F12),ISNUMBER(Radar_Mosca!$S12)),IF(AND(Radar_Mosca!$F12=CM$4,Radar_Mosca!$T12="Sì"),Radar_Mosca!$S12,NA()),NA()) -> #N/A | CN12: =IF(AND(ISNUMBER(Radar_Mosca!$F12),ISNUMBER(Radar_Mosca!$S12)),IF(AND(Radar_Mosca!$F12=CN$4,Radar_Mosca!$T12="Sì"),Radar_Mosca!$S12,NA()),NA()) -> #N/A | CO12: =IF(AND(ISNUMBER(Radar_Mosca!$F12),ISNUMBER(Radar_Mosca!$S12)),IF(AND(Radar_Mosca!$F12=CO$4,Radar_Mosca!$T12="Sì"),Radar_Mosca!$S12,NA()),NA()) -> #N/A | CP12: =IF(AND(ISNUMBER(Radar_Mosca!$F12),ISNUMBER(Radar_Mosca!$S12)),IF(AND(Radar_Mosca!$F12=CP$4,Radar_Mosca!$T12="Sì"),Radar_Mosca!$S12,NA()),NA()) -> #N/A | CQ12: =IF(AND(ISNUMBER(Radar_Mosca!$F12),ISNUMBER(Radar_Mosca!$S12)),IF(AND(Radar_Mosca!$F12=CQ$4,Radar_Mosca!$T12="Sì"),Radar_Mosca!$S12,NA()),NA()) -> #N/A | CR12: =IF(AND(ISNUMBER(Radar_Mosca!$F12),ISNUMBER(Radar_Mosca!$S12)),IF(AND(Radar_Mosca!$F12=CR$4,Radar_Mosca!$T12="Sì"),Radar_Mosca!$S12,NA()),NA()) -> #N/A | CS12: =IF(AND(ISNUMBER(Radar_Mosca!$F12),ISNUMBER(Radar_Mosca!$S12)),IF(AND(Radar_Mosca!$F12=CS$4,Radar_Mosca!$T12="Sì"),Radar_Mosca!$S12,NA()),NA()) -> #N/A | CT12: =IF(AND(ISNUMBER(Radar_Mosca!$F12),ISNUMBER(Radar_Mosca!$S12)),IF(AND(Radar_Mosca!$F12=CT$4,Radar_Mosca!$T12="Sì"),Radar_Mosca!$S12,NA()),NA()) -> #N/A | ... CZ12: =IF(AND(ISNUMBER(Radar_Mosca!$F12),ISNUMBER(Radar_Mosca!$S12)),IF(AND(Radar_Mosca!$F12=CZ$4,Radar_Mosca!$T12="Sì"),Radar_Mosca!$S12,NA()),NA()) -> #N/A | DA12: =IF(ISNUMBER(Radar_Mosca!$R12),Radar_Mosca!$R12,NA()) -> 1.4028521 | DB12: =IF(Radar_Mosca!$A12="","",MID(Radar_Mosca!$A12,5,3)) -> 08 | DC12: =IF(ISNUMBER(Radar_Mosca!$S12),Radar_Mosca!$S12,NA()) -> 1.7591208
A13: =Classifica!$A$8 -> 4 | B13: =IF(Classifica!$B$8="","",Classifica!$B$8&" "&Classifica!$C$8&IFERROR(IF(INDEX(ANA_Attenzione_Supervisore,Classifica!$U$8)="Sì"," ◆",""),"")) -> NFR-02 Concentrazione su un fornitore cloud critico ◆ | F13: =IF(Classifica!$B$8="","",Classifica!$D$8) -> 3.25 | G13: =IF(Classifica!$B$8="","",IF(ISNUMBER(Classifica!$F$8),Classifica!$F$8,"nuovo")) -> -0.2 | H13: =IF(Classifica!$B$8="","",IF(LEFT(Classifica!$H$8,9)="AGIRE ORA","AGIRE ORA",IF(LEFT(Classifica!$H$8,11)="Agire entro","Entro l'anno",Classifica!$H$8))) -> Entro l'anno | J13: 2 | K13: =SUBSTITUTE(SUBSTITUTE(Matrice!C8," ◆",""),"NFR-","") | L13: =SUBSTITUTE(SUBSTITUTE(Matrice!D8," ◆",""),"NFR-","") | M13: =SUBSTITUTE(SUBSTITUTE(Matrice!E8," ◆",""),"NFR-","") -> 08 | N13: =SUBSTITUTE(SUBSTITUTE(Matrice!F8," ◆",""),"NFR-","") -> 02 09 | O13: =SUBSTITUTE(SUBSTITUTE(Matrice!G8," ◆",""),"NFR-","") | T13: =IF(LEFT(Radar_Mosca!$L$13,9)="AGIRE ORA",Radar_Mosca!$A$13,"") | BH13: =2*PI()*8/72 -> 0.6981317 | BI13: =2*SIN($BH13) -> 1.2855752 | BJ13: =2*COS($BH13) -> 1.5320889 | BK13: =3*SIN($BH13) -> 1.9283628 | BL13: =3*COS($BH13) -> 2.2981333 | BM13: =4*SIN($BH13) -> 2.5711504 | BN13: =4*COS($BH13) -> 3.0641778 | BO13: =5*SIN($BH13) -> 3.213938 | BP13: =5*COS($BH13) -> 3.8302222 | BR13: 0 | BS13: 0 | BY13: =IF(AND(ISNUMBER(Radar_Mosca!$F13),ISNUMBER(Radar_Mosca!$S13)),IF(AND(Radar_Mosca!$F13=BY$4,Radar_Mosca!$T13<>"Sì"),Radar_Mosca!$S13,NA()),NA()) -> #N/A | BZ13: =IF(AND(ISNUMBER(Radar_Mosca!$F13),ISNUMBER(Radar_Mosca!$S13)),IF(AND(Radar_Mosca!$F13=BZ$4,Radar_Mosca!$T13<>"Sì"),Radar_Mosca!$S13,NA()),NA()) -> #N/A | CA13: =IF(AND(ISNUMBER(Radar_Mosca!$F13),ISNUMBER(Radar_Mosca!$S13)),IF(AND(Radar_Mosca!$F13=CA$4,Radar_Mosca!$T13<>"Sì"),Radar_Mosca!$S13,NA()),NA()) -> #N/A | CB13: =IF(AND(ISNUMBER(Radar_Mosca!$F13),ISNUMBER(Radar_Mosca!$S13)),IF(AND(Radar_Mosca!$F13=CB$4,Radar_Mosca!$T13<>"Sì"),Radar_Mosca!$S13,NA()),NA()) -> #N/A | CC13: =IF(AND(ISNUMBER(Radar_Mosca!$F13),ISNUMBER(Radar_Mosca!$S13)),IF(AND(Radar_Mosca!$F13=CC$4,Radar_Mosca!$T13<>"Sì"),Radar_Mosca!$S13,NA()),NA()) -> #N/A | CD13: =IF(AND(ISNUMBER(Radar_Mosca!$F13),ISNUMBER(Radar_Mosca!$S13)),IF(AND(Radar_Mosca!$F13=CD$4,Radar_Mosca!$T13<>"Sì"),Radar_Mosca!$S13,NA()),NA()) -> #N/A | CE13: =IF(AND(ISNUMBER(Radar_Mosca!$F13),ISNUMBER(Radar_Mosca!$S13)),IF(AND(Radar_Mosca!$F13=CE$4,Radar_Mosca!$T13<>"Sì"),Radar_Mosca!$S13,NA()),NA()) -> #N/A | CF13: =IF(AND(ISNUMBER(Radar_Mosca!$F13),ISNUMBER(Radar_Mosca!$S13)),IF(AND(Radar_Mosca!$F13=CF$4,Radar_Mosca!$T13<>"Sì"),Radar_Mosca!$S13,NA()),NA()) -> #N/A | ... CL13: =IF(AND(ISNUMBER(Radar_Mosca!$F13),ISNUMBER(Radar_Mosca!$S13)),IF(AND(Radar_Mosca!$F13=CL$4,Radar_Mosca!$T13<>"Sì"),Radar_Mosca!$S13,NA()),NA()) -> #N/A | CM13: =IF(AND(ISNUMBER(Radar_Mosca!$F13),ISNUMBER(Radar_Mosca!$S13)),IF(AND(Radar_Mosca!$F13=CM$4,Radar_Mosca!$T13="Sì"),Radar_Mosca!$S13,NA()),NA()) -> #N/A | CN13: =IF(AND(ISNUMBER(Radar_Mosca!$F13),ISNUMBER(Radar_Mosca!$S13)),IF(AND(Radar_Mosca!$F13=CN$4,Radar_Mosca!$T13="Sì"),Radar_Mosca!$S13,NA()),NA()) -> #N/A | CO13: =IF(AND(ISNUMBER(Radar_Mosca!$F13),ISNUMBER(Radar_Mosca!$S13)),IF(AND(Radar_Mosca!$F13=CO$4,Radar_Mosca!$T13="Sì"),Radar_Mosca!$S13,NA()),NA()) -> #N/A | CP13: =IF(AND(ISNUMBER(Radar_Mosca!$F13),ISNUMBER(Radar_Mosca!$S13)),IF(AND(Radar_Mosca!$F13=CP$4,Radar_Mosca!$T13="Sì"),Radar_Mosca!$S13,NA()),NA()) -> #N/A | CQ13: =IF(AND(ISNUMBER(Radar_Mosca!$F13),ISNUMBER(Radar_Mosca!$S13)),IF(AND(Radar_Mosca!$F13=CQ$4,Radar_Mosca!$T13="Sì"),Radar_Mosca!$S13,NA()),NA()) -> #N/A | CR13: =IF(AND(ISNUMBER(Radar_Mosca!$F13),ISNUMBER(Radar_Mosca!$S13)),IF(AND(Radar_Mosca!$F13=CR$4,Radar_Mosca!$T13="Sì"),Radar_Mosca!$S13,NA()),NA()) -> #N/A | CS13: =IF(AND(ISNUMBER(Radar_Mosca!$F13),ISNUMBER(Radar_Mosca!$S13)),IF(AND(Radar_Mosca!$F13=CS$4,Radar_Mosca!$T13="Sì"),Radar_Mosca!$S13,NA()),NA()) -> -3.25 | CT13: =IF(AND(ISNUMBER(Radar_Mosca!$F13),ISNUMBER(Radar_Mosca!$S13)),IF(AND(Radar_Mosca!$F13=CT$4,Radar_Mosca!$T13="Sì"),Radar_Mosca!$S13,NA()),NA()) -> #N/A | ... CZ13: =IF(AND(ISNUMBER(Radar_Mosca!$F13),ISNUMBER(Radar_Mosca!$S13)),IF(AND(Radar_Mosca!$F13=CZ$4,Radar_Mosca!$T13="Sì"),Radar_Mosca!$S13,NA()),NA()) -> #N/A | DA13: =IF(ISNUMBER(Radar_Mosca!$R13),Radar_Mosca!$R13,NA()) -> 3.9817325e-16 | DB13: =IF(Radar_Mosca!$A13="","",MID(Radar_Mosca!$A13,5,3)) -> 09 | DC13: =IF(ISNUMBER(Radar_Mosca!$S13),Radar_Mosca!$S13,NA()) -> -3.25
A14: =Classifica!$A$9 -> 5 | B14: =IF(Classifica!$B$9="","",Classifica!$B$9&" "&Classifica!$C$9&IFERROR(IF(INDEX(ANA_Attenzione_Supervisore,Classifica!$U$9)="Sì"," ◆",""),"")) -> NFR-10 Informazioni errate ai clienti da assistenti di AI generativa | F14: =IF(Classifica!$B$9="","",Classifica!$D$9) -> 3.2 | G14: =IF(Classifica!$B$9="","",IF(ISNUMBER(Classifica!$F$9),Classifica!$F$9,"nuovo")) -> 0 | H14: =IF(Classifica!$B$9="","",IF(LEFT(Classifica!$H$9,9)="AGIRE ORA","AGIRE ORA",IF(LEFT(Classifica!$H$9,11)="Agire entro","Entro l'anno",Classifica!$H$9))) -> Margine 1 anno | J14: 1 | K14: =SUBSTITUTE(SUBSTITUTE(Matrice!C9," ◆",""),"NFR-","") | L14: =SUBSTITUTE(SUBSTITUTE(Matrice!D9," ◆",""),"NFR-","") | M14: =SUBSTITUTE(SUBSTITUTE(Matrice!E9," ◆",""),"NFR-","") | N14: =SUBSTITUTE(SUBSTITUTE(Matrice!F9," ◆",""),"NFR-","") | O14: =SUBSTITUTE(SUBSTITUTE(Matrice!G9," ◆",""),"NFR-","") | T14: =IF(LEFT(Radar_Mosca!$L$14,9)="AGIRE ORA",Radar_Mosca!$A$14,"") | BH14: =2*PI()*9/72 -> 0.78539816 | BI14: =2*SIN($BH14) -> 1.4142136 | BJ14: =2*COS($BH14) -> 1.4142136 | BK14: =3*SIN($BH14) -> 2.1213203 | BL14: =3*COS($BH14) -> 2.1213203 | BM14: =4*SIN($BH14) -> 2.8284271 | BN14: =4*COS($BH14) -> 2.8284271 | BO14: =5*SIN($BH14) -> 3.5355339 | BP14: =5*COS($BH14) -> 3.5355339 | BR14: =6.3*SIN(2*PI()*4/ROWS(codiciL1)) -> -2.7334676 | BS14: =6.3*COS(2*PI()*4/ROWS(codiciL1)) -> -5.6761039 | BY14: =IF(AND(ISNUMBER(Radar_Mosca!$F14),ISNUMBER(Radar_Mosca!$S14)),IF(AND(Radar_Mosca!$F14=BY$4,Radar_Mosca!$T14<>"Sì"),Radar_Mosca!$S14,NA()),NA()) -> #N/A | BZ14: =IF(AND(ISNUMBER(Radar_Mosca!$F14),ISNUMBER(Radar_Mosca!$S14)),IF(AND(Radar_Mosca!$F14=BZ$4,Radar_Mosca!$T14<>"Sì"),Radar_Mosca!$S14,NA()),NA()) -> #N/A | CA14: =IF(AND(ISNUMBER(Radar_Mosca!$F14),ISNUMBER(Radar_Mosca!$S14)),IF(AND(Radar_Mosca!$F14=CA$4,Radar_Mosca!$T14<>"Sì"),Radar_Mosca!$S14,NA()),NA()) -> #N/A | CB14: =IF(AND(ISNUMBER(Radar_Mosca!$F14),ISNUMBER(Radar_Mosca!$S14)),IF(AND(Radar_Mosca!$F14=CB$4,Radar_Mosca!$T14<>"Sì"),Radar_Mosca!$S14,NA()),NA()) -> #N/A | CC14: =IF(AND(ISNUMBER(Radar_Mosca!$F14),ISNUMBER(Radar_Mosca!$S14)),IF(AND(Radar_Mosca!$F14=CC$4,Radar_Mosca!$T14<>"Sì"),Radar_Mosca!$S14,NA()),NA()) -> #N/A | CD14: =IF(AND(ISNUMBER(Radar_Mosca!$F14),ISNUMBER(Radar_Mosca!$S14)),IF(AND(Radar_Mosca!$F14=CD$4,Radar_Mosca!$T14<>"Sì"),Radar_Mosca!$S14,NA()),NA()) -> #N/A | CE14: =IF(AND(ISNUMBER(Radar_Mosca!$F14),ISNUMBER(Radar_Mosca!$S14)),IF(AND(Radar_Mosca!$F14=CE$4,Radar_Mosca!$T14<>"Sì"),Radar_Mosca!$S14,NA()),NA()) -> #N/A | CF14: =IF(AND(ISNUMBER(Radar_Mosca!$F14),ISNUMBER(Radar_Mosca!$S14)),IF(AND(Radar_Mosca!$F14=CF$4,Radar_Mosca!$T14<>"Sì"),Radar_Mosca!$S14,NA()),NA()) -> -2.8667184 | ... CL14: =IF(AND(ISNUMBER(Radar_Mosca!$F14),ISNUMBER(Radar_Mosca!$S14)),IF(AND(Radar_Mosca!$F14=CL$4,Radar_Mosca!$T14<>"Sì"),Radar_Mosca!$S14,NA()),NA()) -> #N/A | CM14: =IF(AND(ISNUMBER(Radar_Mosca!$F14),ISNUMBER(Radar_Mosca!$S14)),IF(AND(Radar_Mosca!$F14=CM$4,Radar_Mosca!$T14="Sì"),Radar_Mosca!$S14,NA()),NA()) -> #N/A | CN14: =IF(AND(ISNUMBER(Radar_Mosca!$F14),ISNUMBER(Radar_Mosca!$S14)),IF(AND(Radar_Mosca!$F14=CN$4,Radar_Mosca!$T14="Sì"),Radar_Mosca!$S14,NA()),NA()) -> #N/A | CO14: =IF(AND(ISNUMBER(Radar_Mosca!$F14),ISNUMBER(Radar_Mosca!$S14)),IF(AND(Radar_Mosca!$F14=CO$4,Radar_Mosca!$T14="Sì"),Radar_Mosca!$S14,NA()),NA()) -> #N/A | CP14: =IF(AND(ISNUMBER(Radar_Mosca!$F14),ISNUMBER(Radar_Mosca!$S14)),IF(AND(Radar_Mosca!$F14=CP$4,Radar_Mosca!$T14="Sì"),Radar_Mosca!$S14,NA()),NA()) -> #N/A | CQ14: =IF(AND(ISNUMBER(Radar_Mosca!$F14),ISNUMBER(Radar_Mosca!$S14)),IF(AND(Radar_Mosca!$F14=CQ$4,Radar_Mosca!$T14="Sì"),Radar_Mosca!$S14,NA()),NA()) -> #N/A | CR14: =IF(AND(ISNUMBER(Radar_Mosca!$F14),ISNUMBER(Radar_Mosca!$S14)),IF(AND(Radar_Mosca!$F14=CR$4,Radar_Mosca!$T14="Sì"),Radar_Mosca!$S14,NA()),NA()) -> #N/A | CS14: =IF(AND(ISNUMBER(Radar_Mosca!$F14),ISNUMBER(Radar_Mosca!$S14)),IF(AND(Radar_Mosca!$F14=CS$4,Radar_Mosca!$T14="Sì"),Radar_Mosca!$S14,NA()),NA()) -> #N/A | CT14: =IF(AND(ISNUMBER(Radar_Mosca!$F14),ISNUMBER(Radar_Mosca!$S14)),IF(AND(Radar_Mosca!$F14=CT$4,Radar_Mosca!$T14="Sì"),Radar_Mosca!$S14,NA()),NA()) -> #N/A | ... CZ14: =IF(AND(ISNUMBER(Radar_Mosca!$F14),ISNUMBER(Radar_Mosca!$S14)),IF(AND(Radar_Mosca!$F14=CZ$4,Radar_Mosca!$T14="Sì"),Radar_Mosca!$S14,NA()),NA()) -> #N/A | DA14: =IF(ISNUMBER(Radar_Mosca!$R14),Radar_Mosca!$R14,NA()) -> -0.88426552 | DB14: =IF(Radar_Mosca!$A14="","",MID(Radar_Mosca!$A14,5,3)) -> 10 | DC14: =IF(ISNUMBER(Radar_Mosca!$S14),Radar_Mosca!$S14,NA()) -> -2.8667184
A15: Score 1-5, 5 = peggiore; barra su scala fissa 0-5. Variazione sul ciclo precedente. | J15: Numeri = NFR-nn. Verde P x I fino a 6, ambra 8-12, rosso da 15. | T15: =IF(LEFT(Radar_Mosca!$L$15,9)="AGIRE ORA",Radar_Mosca!$A$15,"") -> NFR-11 | BH15: =2*PI()*10/72 -> 0.87266463 | BI15: =2*SIN($BH15) -> 1.5320889 | BJ15: =2*COS($BH15) -> 1.2855752 | BK15: =3*SIN($BH15) -> 2.2981333 | BL15: =3*COS($BH15) -> 1.9283628 | BM15: =4*SIN($BH15) -> 3.0641778 | BN15: =4*COS($BH15) -> 2.5711504 | BO15: =5*SIN($BH15) -> 3.8302222 | BP15: =5*COS($BH15) -> 3.213938 | BR15: 0 | BS15: 0 | BY15: =IF(AND(ISNUMBER(Radar_Mosca!$F15),ISNUMBER(Radar_Mosca!$S15)),IF(AND(Radar_Mosca!$F15=BY$4,Radar_Mosca!$T15<>"Sì"),Radar_Mosca!$S15,NA()),NA()) -> #N/A | BZ15: =IF(AND(ISNUMBER(Radar_Mosca!$F15),ISNUMBER(Radar_Mosca!$S15)),IF(AND(Radar_Mosca!$F15=BZ$4,Radar_Mosca!$T15<>"Sì"),Radar_Mosca!$S15,NA()),NA()) -> #N/A | CA15: =IF(AND(ISNUMBER(Radar_Mosca!$F15),ISNUMBER(Radar_Mosca!$S15)),IF(AND(Radar_Mosca!$F15=CA$4,Radar_Mosca!$T15<>"Sì"),Radar_Mosca!$S15,NA()),NA()) -> #N/A | CB15: =IF(AND(ISNUMBER(Radar_Mosca!$F15),ISNUMBER(Radar_Mosca!$S15)),IF(AND(Radar_Mosca!$F15=CB$4,Radar_Mosca!$T15<>"Sì"),Radar_Mosca!$S15,NA()),NA()) -> #N/A | CC15: =IF(AND(ISNUMBER(Radar_Mosca!$F15),ISNUMBER(Radar_Mosca!$S15)),IF(AND(Radar_Mosca!$F15=CC$4,Radar_Mosca!$T15<>"Sì"),Radar_Mosca!$S15,NA()),NA()) -> #N/A | CD15: =IF(AND(ISNUMBER(Radar_Mosca!$F15),ISNUMBER(Radar_Mosca!$S15)),IF(AND(Radar_Mosca!$F15=CD$4,Radar_Mosca!$T15<>"Sì"),Radar_Mosca!$S15,NA()),NA()) -> #N/A | CE15: =IF(AND(ISNUMBER(Radar_Mosca!$F15),ISNUMBER(Radar_Mosca!$S15)),IF(AND(Radar_Mosca!$F15=CE$4,Radar_Mosca!$T15<>"Sì"),Radar_Mosca!$S15,NA()),NA()) -> #N/A | CF15: =IF(AND(ISNUMBER(Radar_Mosca!$F15),ISNUMBER(Radar_Mosca!$S15)),IF(AND(Radar_Mosca!$F15=CF$4,Radar_Mosca!$T15<>"Sì"),Radar_Mosca!$S15,NA()),NA()) -> 0.3 | ... CL15: =IF(AND(ISNUMBER(Radar_Mosca!$F15),ISNUMBER(Radar_Mosca!$S15)),IF(AND(Radar_Mosca!$F15=CL$4,Radar_Mosca!$T15<>"Sì"),Radar_Mosca!$S15,NA()),NA()) -> #N/A | CM15: =IF(AND(ISNUMBER(Radar_Mosca!$F15),ISNUMBER(Radar_Mosca!$S15)),IF(AND(Radar_Mosca!$F15=CM$4,Radar_Mosca!$T15="Sì"),Radar_Mosca!$S15,NA()),NA()) -> #N/A | CN15: =IF(AND(ISNUMBER(Radar_Mosca!$F15),ISNUMBER(Radar_Mosca!$S15)),IF(AND(Radar_Mosca!$F15=CN$4,Radar_Mosca!$T15="Sì"),Radar_Mosca!$S15,NA()),NA()) -> #N/A | CO15: =IF(AND(ISNUMBER(Radar_Mosca!$F15),ISNUMBER(Radar_Mosca!$S15)),IF(AND(Radar_Mosca!$F15=CO$4,Radar_Mosca!$T15="Sì"),Radar_Mosca!$S15,NA()),NA()) -> #N/A | CP15: =IF(AND(ISNUMBER(Radar_Mosca!$F15),ISNUMBER(Radar_Mosca!$S15)),IF(AND(Radar_Mosca!$F15=CP$4,Radar_Mosca!$T15="Sì"),Radar_Mosca!$S15,NA()),NA()) -> #N/A | CQ15: =IF(AND(ISNUMBER(Radar_Mosca!$F15),ISNUMBER(Radar_Mosca!$S15)),IF(AND(Radar_Mosca!$F15=CQ$4,Radar_Mosca!$T15="Sì"),Radar_Mosca!$S15,NA()),NA()) -> #N/A | CR15: =IF(AND(ISNUMBER(Radar_Mosca!$F15),ISNUMBER(Radar_Mosca!$S15)),IF(AND(Radar_Mosca!$F15=CR$4,Radar_Mosca!$T15="Sì"),Radar_Mosca!$S15,NA()),NA()) -> #N/A | CS15: =IF(AND(ISNUMBER(Radar_Mosca!$F15),ISNUMBER(Radar_Mosca!$S15)),IF(AND(Radar_Mosca!$F15=CS$4,Radar_Mosca!$T15="Sì"),Radar_Mosca!$S15,NA()),NA()) -> #N/A | CT15: =IF(AND(ISNUMBER(Radar_Mosca!$F15),ISNUMBER(Radar_Mosca!$S15)),IF(AND(Radar_Mosca!$F15=CT$4,Radar_Mosca!$T15="Sì"),Radar_Mosca!$S15,NA()),NA()) -> #N/A | ... CZ15: =IF(AND(ISNUMBER(Radar_Mosca!$F15),ISNUMBER(Radar_Mosca!$S15)),IF(AND(Radar_Mosca!$F15=CZ$4,Radar_Mosca!$T15="Sì"),Radar_Mosca!$S15,NA()),NA()) -> #N/A | DA15: =IF(ISNUMBER(Radar_Mosca!$R15),Radar_Mosca!$R15,NA()) -> -0.51961524 | DB15: =IF(Radar_Mosca!$A15="","",MID(Radar_Mosca!$A15,5,3)) -> 11 | DC15: =IF(ISNUMBER(Radar_Mosca!$S15),Radar_Mosca!$S15,NA()) -> 0.3
T16: =IF(LEFT(Radar_Mosca!$L$16,9)="AGIRE ORA",Radar_Mosca!$A$16,"") | BH16: =2*PI()*11/72 -> 0.95993109 | BI16: =2*SIN($BH16) -> 1.6383041 | BJ16: =2*COS($BH16) -> 1.1471529 | BK16: =3*SIN($BH16) -> 2.4574561 | BL16: =3*COS($BH16) -> 1.7207293 | BM16: =4*SIN($BH16) -> 3.2766082 | BN16: =4*COS($BH16) -> 2.2943057 | BO16: =5*SIN($BH16) -> 4.0957602 | BP16: =5*COS($BH16) -> 2.8678822 | BR16: =6.3*SIN(2*PI()*5/ROWS(codiciL1)) -> -6.1420458 | BS16: =6.3*COS(2*PI()*5/ROWS(codiciL1)) -> -1.4018819 | BY16: =IF(AND(ISNUMBER(Radar_Mosca!$F16),ISNUMBER(Radar_Mosca!$S16)),IF(AND(Radar_Mosca!$F16=BY$4,Radar_Mosca!$T16<>"Sì"),Radar_Mosca!$S16,NA()),NA()) -> #N/A | BZ16: =IF(AND(ISNUMBER(Radar_Mosca!$F16),ISNUMBER(Radar_Mosca!$S16)),IF(AND(Radar_Mosca!$F16=BZ$4,Radar_Mosca!$T16<>"Sì"),Radar_Mosca!$S16,NA()),NA()) -> #N/A | CA16: =IF(AND(ISNUMBER(Radar_Mosca!$F16),ISNUMBER(Radar_Mosca!$S16)),IF(AND(Radar_Mosca!$F16=CA$4,Radar_Mosca!$T16<>"Sì"),Radar_Mosca!$S16,NA()),NA()) -> #N/A | CB16: =IF(AND(ISNUMBER(Radar_Mosca!$F16),ISNUMBER(Radar_Mosca!$S16)),IF(AND(Radar_Mosca!$F16=CB$4,Radar_Mosca!$T16<>"Sì"),Radar_Mosca!$S16,NA()),NA()) -> #N/A | CC16: =IF(AND(ISNUMBER(Radar_Mosca!$F16),ISNUMBER(Radar_Mosca!$S16)),IF(AND(Radar_Mosca!$F16=CC$4,Radar_Mosca!$T16<>"Sì"),Radar_Mosca!$S16,NA()),NA()) -> #N/A | CD16: =IF(AND(ISNUMBER(Radar_Mosca!$F16),ISNUMBER(Radar_Mosca!$S16)),IF(AND(Radar_Mosca!$F16=CD$4,Radar_Mosca!$T16<>"Sì"),Radar_Mosca!$S16,NA()),NA()) -> #N/A | CE16: =IF(AND(ISNUMBER(Radar_Mosca!$F16),ISNUMBER(Radar_Mosca!$S16)),IF(AND(Radar_Mosca!$F16=CE$4,Radar_Mosca!$T16<>"Sì"),Radar_Mosca!$S16,NA()),NA()) -> #N/A | CF16: =IF(AND(ISNUMBER(Radar_Mosca!$F16),ISNUMBER(Radar_Mosca!$S16)),IF(AND(Radar_Mosca!$F16=CF$4,Radar_Mosca!$T16<>"Sì"),Radar_Mosca!$S16,NA()),NA()) -> #N/A | ... CL16: =IF(AND(ISNUMBER(Radar_Mosca!$F16),ISNUMBER(Radar_Mosca!$S16)),IF(AND(Radar_Mosca!$F16=CL$4,Radar_Mosca!$T16<>"Sì"),Radar_Mosca!$S16,NA()),NA()) -> #N/A | CM16: =IF(AND(ISNUMBER(Radar_Mosca!$F16),ISNUMBER(Radar_Mosca!$S16)),IF(AND(Radar_Mosca!$F16=CM$4,Radar_Mosca!$T16="Sì"),Radar_Mosca!$S16,NA()),NA()) -> #N/A | CN16: =IF(AND(ISNUMBER(Radar_Mosca!$F16),ISNUMBER(Radar_Mosca!$S16)),IF(AND(Radar_Mosca!$F16=CN$4,Radar_Mosca!$T16="Sì"),Radar_Mosca!$S16,NA()),NA()) -> #N/A | CO16: =IF(AND(ISNUMBER(Radar_Mosca!$F16),ISNUMBER(Radar_Mosca!$S16)),IF(AND(Radar_Mosca!$F16=CO$4,Radar_Mosca!$T16="Sì"),Radar_Mosca!$S16,NA()),NA()) -> #N/A | CP16: =IF(AND(ISNUMBER(Radar_Mosca!$F16),ISNUMBER(Radar_Mosca!$S16)),IF(AND(Radar_Mosca!$F16=CP$4,Radar_Mosca!$T16="Sì"),Radar_Mosca!$S16,NA()),NA()) -> #N/A | CQ16: =IF(AND(ISNUMBER(Radar_Mosca!$F16),ISNUMBER(Radar_Mosca!$S16)),IF(AND(Radar_Mosca!$F16=CQ$4,Radar_Mosca!$T16="Sì"),Radar_Mosca!$S16,NA()),NA()) -> #N/A | CR16: =IF(AND(ISNUMBER(Radar_Mosca!$F16),ISNUMBER(Radar_Mosca!$S16)),IF(AND(Radar_Mosca!$F16=CR$4,Radar_Mosca!$T16="Sì"),Radar_Mosca!$S16,NA()),NA()) -> #N/A | CS16: =IF(AND(ISNUMBER(Radar_Mosca!$F16),ISNUMBER(Radar_Mosca!$S16)),IF(AND(Radar_Mosca!$F16=CS$4,Radar_Mosca!$T16="Sì"),Radar_Mosca!$S16,NA()),NA()) -> #N/A | CT16: =IF(AND(ISNUMBER(Radar_Mosca!$F16),ISNUMBER(Radar_Mosca!$S16)),IF(AND(Radar_Mosca!$F16=CT$4,Radar_Mosca!$T16="Sì"),Radar_Mosca!$S16,NA()),NA()) -> #N/A | ... CZ16: =IF(AND(ISNUMBER(Radar_Mosca!$F16),ISNUMBER(Radar_Mosca!$S16)),IF(AND(Radar_Mosca!$F16=CZ$4,Radar_Mosca!$T16="Sì"),Radar_Mosca!$S16,NA()),NA()) -> #N/A | DA16: =IF(ISNUMBER(Radar_Mosca!$R16),Radar_Mosca!$R16,NA()) -> -0.44504187 | DB16: =IF(Radar_Mosca!$A16="","",MID(Radar_Mosca!$A16,5,3)) -> 12 | DC16: =IF(ISNUMBER(Radar_Mosca!$S16),Radar_Mosca!$S16,NA()) -> 1.9498558
